Workbook

Sheet Sheet4
A2: U Of M | B2: (All)
A3: Macro / Micro | B3: GAL
A4: Document Date | B4: (All)
A5: Year | B5: (Multiple Items)
A7: Sum of QTY | B7: Column Labels
A8: Row Labels | B8: 1 | C8: 2 | D8: 3 | E8: 4 | F8: 5 | G8: 6 | H8: 7 | I8: 8 | J8: 9 | K8: 10 | L8: 11 | M8: 12 | N8: Grand Total
A9: Thrive 8-21-6 | B9: 58920 | C9: 43530 | D9: 51280 | E9: 11130 | H9: 7420 | N9: 172280
A10: FLO821602 | B10: 14400 | C10: 32400 | D10: 21600 | N10: 68400
A11: FLO8216250 | B11: 44520 | C11: 11130 | D11: 29680 | E11: 11130 | H11: 7420 | N11: 103880
A12: Top Side Liquid Boron | D12: 15830 | E12: 53840 | F12: 24500 | G12: 20000 | H12: 39880 | N12: 154050
A13: TRITOPS02 | D13: 10080 | E13: 33840 | H13: 11880 | N13: 55800
A14: TRITOPS250 | D14: 5750 | E14: 20000 | F14: 24500 | G14: 20000 | H14: 28000 | N14: 98250
A15: Petro-Canada Spray Oil 13 | C15: 28183 | D15: 7143 | E15: 35001 | F15: 34954 | G15: 20197 | H15: 20994 | J15: 6957 | N15: 153429
A16: PETRO1300 | C16: 28183 | D16: 7143 | E16: 35001 | F16: 34954 | G16: 20197 | H16: 20994 | J16: 6957 | N16: 153429
A17: Citra Guard XP | B17: 4250 | C17: 15186 | D17: 19674.13 | E17: 24443.7 | F17: 18786.045 | G17: 9029 | H17: 15476.05 | I17: 8277 | J17: 8216.46 | K17: 2319.73 | L17: 9672.59 | M17: 3784.75 | N17: 139115.46
A18: GRO13116190.5 | J18: 8 | N18: 8
A19: GRO131161901 | J19: 15 | N19: 15
A20: GRO131161902 | C20: 95 | J20: 25 | K20: 65 | N20: 185
A21: GRO1311619250 | B21: 4250 | C21: 6050 | D21: 5300 | E21: 8000 | F21: 6750 | G21: 3500 | H21: 4560 | I21: 3250 | J21: 750 | K21: 250 | L21: 2750 | M21: 750 | N21: 46160
A22: GRO131161900 | C22: 9041 | D22: 14374.13 | E22: 16443.7 | F22: 12036.045 | G22: 5529 | H22: 10916.05 | I22: 5027 | J22: 7418.46 | K22: 2004.73 | L22: 6922.59 | M22: 3034.75 | N22: 92747.455
A23: Soar Bloom Spray | B23: 13372.5 | C23: 26736 | D23: 17930 | E23: 13095 | F23: 3332.5 | G23: 11145 | H23: 3387.5 | I23: -1237.5 | J23: 2230 | K23: 2345 | L23: 2480 | M23: 4355 | N23: 99171
A24: SOARBLM55 | H24: 55 | N24: 55
A25: SOARBLM00 | C25: 2631 | N25: 2631
A26: SOARBLM250 | B26: 4500 | C26: 14000 | D26: 7250 | E26: 2780 | F26: 1500 | G26: 7500 | H26: 2250 | I26: -1000 | M26: 250 | N26: 39030
A27: SOARBLM02 | B27: 8872.5 | C27: 10105 | D27: 10680 | E27: 10315 | F27: 1832.5 | G27: 3645 | H27: 1082.5 | I27: -237.5 | J27: 2230 | K27: 2345 | L27: 2480 | M27: 4105 | N27: 57455
A28: Soar Citrus Mix | B28: 210 | C28: 1905 | D28: 8120 | E28: 11340 | F28: 12540 | G28: 10820 | H28: 14035 | I28: 3385 | J28: 1720 | K28: 180 | N28: 64255
A29: SOARCIT00 | J29: 800 | N29: 800
A30: SOARCIT250 | C30: 1500 | D30: 3500 | E30: 4500 | F30: 4750 | G30: 2000 | H30: 5750 | I30: 500 | J30: 500 | N30: 23000
A31: SOARCIT02 | B31: 210 | C31: 405 | D31: 4620 | E31: 6840 | F31: 7790 | G31: 8820 | H31: 8285 | I31: 2885 | J31: 420 | K31: 180 | N31: 40455
A32: Dyna Cal 10.25% | B32: 9255 | C32: 5250 | D32: 2955 | E32: 3050 | F32: 535 | G32: 335 | H32: 55 | J32: 8305 | K32: 3055 | L32: 9250 | M32: 5250 | N32: 47295
A33: SORCA30 | F33: 30 | G33: 30 | N33: 60
A34: SORCA02 | B34: 5 | D34: 210 | E34: 50 | F34: 5 | N34: 270
A35: SORCA55 | D35: 495 | G35: 55 | H35: 55 | J35: 55 | K35: 55 | N35: 715
A36: SORCA250 | B36: 9250 | C36: 5250 | D36: 2250 | E36: 3000 | F36: 500 | G36: 250 | J36: 8250 | K36: 3000 | L36: 9250 | M36: 5250 | N36: 46250
A37: Dyna Gold Calcium 8.25% | B37: 4985 | C37: 11960 | D37: 5847.5 | E37: 4650 | F37: 1540 | G37: 1107.5 | H37: 430 | I37: 712.5 | J37: 835 | K37: 1605 | L37: 950 | M37: 4707.5 | N37: 39330
A38: GOLDCA55 | D38: 55 | F38: 165 | G38: 110 | I38: 165 | J38: 55 | K38: 55 | N38: 605
A39: GOLDCA250 | B39: 750 | C39: 750 | D39: 1250 | E39: 750 | F39: 250 | G39: 250 | H39: 250 | M39: 1250 | N39: 5500
A40: GOLDCA02 | B40: 4235 | C40: 11210 | D40: 4542.5 | E40: 3900 | F40: 1125 | G40: 747.5 | H40: 180 | I40: 547.5 | J40: 780 | K40: 1550 | L40: 950 | M40: 3457.5 | N40: 33225
A41: Copper Count N | B41: 4919 | C41: 4805.3 | D41: 2208 | E41: 2335.3 | F41: 5427 | G41: 5587.7 | H41: 190 | I41: 3270 | J41: 3578 | K41: 1040 | L41: 2580 | M41: 1430 | N41: 37370.3
A42: MRCCCN02 | B42: 660 | C42: 1380 | D42: 900 | E42: 1020 | F42: 240 | G42: 180 | H42: 190 | I42: 180 | J42: 30 | K42: 540 | L42: 380 | M42: 880 | N42: 6580
...

Sheet Sheet1
B2: Salesperson ID | C2: Sales Territory | D2: Customer Number | E2: Primary ShipTo | F2: Document Date | G2: Month | H2: Year | I2: SOP Type | J2: SOP Number | K2: Item Number | L2: Item Description | M2: U Of M | N2: Macro / Micro | O2: QTY
B3: HAP | C3: 01 | D3: GREENWAY | E3: WINDSOR POLO | F3: =DATE(2022,10,4) -> 44838 | G3: =+MONTH(F3) -> 10 | H3: =+YEAR(F3) -> 2022 | I3: Invoice | J3: 95927 | K3: USCMANPLX+55 | L3: Vented Manga Plex Plus | M3: GAL11.90 | N3: =+LEFT(M3,3) -> GAL | O3: 55 | Q3: =K3 -> USCMANPLX+55 | R3: =L3 -> Vented Manga Plex Plus | S3: =SUMIF($R$3:$R$885,$R3,$O$3:$O$885) -> 1060 | U3: Vented Manga Plex Plus | V3: 1060
B4: HAP | C4: 01 | D4: GREENWAY | E4: LAWN HARMONY | F4: =DATE(2022,10,5) -> 44839 | G4: =+MONTH(F4) -> 10 | H4: =+YEAR(F4) -> 2022 | I4: Invoice | J4: 95929 | K4: FLO1200655 | L4: Green Master 12-0-0 | M4: GAL11.80 | N4: =+LEFT(M4,3) -> GAL | O4: 110 | Q4: =K4 -> FLO1200655 | R4: =L4 -> Green Master 12-0-0 | S4: =SUMIF($R$3:$R$885, $R4, $O$3:$O$885) -> 440 | U4: Green Master 12-0-0 | V4: 440
B5: HAP | C5: 01 | D5: GREENWAY | E5: COUNTRY CLUB | F5: =DATE(2022,10,5) -> 44839 | G5: =+MONTH(F5) -> 10 | H5: =+YEAR(F5) -> 2022 | I5: Invoice | J5: 95930 | K5: USCMANPLX+02 | L5: Vented Manga Plex Plus | M5: GAL11.90 | N5: =+LEFT(M5,3) -> GAL | O5: 30 | Q5: =K5 -> USCMANPLX+02 | R5: =L5 -> Vented Manga Plex Plus | S5: =SUMIF($R$3:$R$885, $R5, $O$3:$O$885) -> 1060 | U5: Vented Manga Plex Plus | V5: 1060
B6: HAP | C6: 01 | D6: GREENWAY | E6: THECLUBSHOUSTON | F6: =DATE(2022,10,5) -> 44839 | G6: =+MONTH(F6) -> 10 | H6: =+YEAR(F6) -> 2022 | I6: Invoice | J6: 95931 | K6: FLOKTS02 | L6: Excel 0-0-25 | M6: GAL12.24 | N6: =+LEFT(M6,3) -> GAL | O6: 40 | Q6: =K6 -> FLOKTS02 | R6: =L6 -> Excel 0-0-25 | S6: =SUMIF($R$3:$R$885, $R6, $O$3:$O$885) -> 690 | U6: Excel 0-0-25 | V6: 690
B7: HAP | C7: 01 | D7: GREENWAY | E7: THECLUBSHOUSTON | F7: =DATE(2022,10,5) -> 44839 | G7: =+MONTH(F7) -> 10 | H7: =+YEAR(F7) -> 2022 | I7: Invoice | J7: 95931 | K7: GPHUMIC02 | L7: Humic Soil Rebuilder | M7: GAL09.65 | N7: =+LEFT(M7,3) -> GAL | O7: 40 | Q7: =K7 -> GPHUMIC02 | R7: =L7 -> Humic Soil Rebuilder | S7: =SUMIF($R$3:$R$885, $R7, $O$3:$O$885) -> 180 | U7: Humic Soil Rebuilder | V7: 180
B8: HAP | C8: 01 | D8: GREENWAY | E8: THECLUBSHOUSTON | F8: =DATE(2022,10,5) -> 44839 | G8: =+MONTH(F8) -> 10 | H8: =+YEAR(F8) -> 2022 | I8: Invoice | J8: 95931 | K8: GOLDCA02 | L8: Neutra Soil | M8: GAL11.60 | N8: =+LEFT(M8,3) -> GAL | O8: 40 | Q8: =K8 -> GOLDCA02 | R8: =L8 -> Neutra Soil | S8: =SUMIF($R$3:$R$885, $R8, $O$3:$O$885) -> 470 | U8: Neutra Soil | V8: 470
B9: HAP | C9: 01 | D9: GREENWAY | E9: THECLUBSHOUSTON | F9: =DATE(2022,10,5) -> 44839 | G9: =+MONTH(F9) -> 10 | H9: =+YEAR(F9) -> 2022 | I9: Invoice | J9: 95931 | K9: USCBIOPX02 | L9: Vented Bio Plex | M9: GAL09.70 | N9: =+LEFT(M9,3) -> GAL | O9: 40 | Q9: =K9 -> USCBIOPX02 | R9: =L9 -> Vented Bio Plex | S9: =SUMIF($R$3:$R$885, $R9, $O$3:$O$885) -> 510 | U9: Vented Bio Plex | V9: 510
B10: HAP | C10: 01 | D10: GREENWAY | E10: THECLUBSHOUSTON | F10: =DATE(2022,10,5) -> 44839 | G10: =+MONTH(F10) -> 10 | H10: =+YEAR(F10) -> 2022 | I10: Invoice | J10: 95931 | K10: USCMANPLX+02 | L10: Vented Manga Plex Plus | M10: GAL11.90 | N10: =+LEFT(M10,3) -> GAL | O10: 40 | Q10: =K10 -> USCMANPLX+02 | R10: =L10 -> Vented Manga Plex Plus | S10: =SUMIF($R$3:$R$885, $R10, $O$3:$O$885) -> 1060 | U10: Vented Manga Plex Plus | V10: 1060
B11: HAP | C11: 01 | D11: GREENWAY | E11: INDIAN RIVER CL | F11: =DATE(2022,10,6) -> 44840 | G11: =+MONTH(F11) -> 10 | H11: =+YEAR(F11) -> 2022 | I11: Invoice | J11: 95939 | K11: ZON1501002 | L11: Ever-Green 15-0-10 | M11: GAL10.95 | N11: =+LEFT(M11,3) -> GAL | O11: 20 | Q11: =K11 -> ZON1501002 | R11: =L11 -> Ever-Green 15-0-10 | S11: =SUMIF($R$3:$R$885, $R11, $O$3:$O$885) -> 140 | U11: Ever-Green 15-0-10 | V11: 140
B12: HAP | C12: 01 | D12: GREENWAY | E12: INDIAN RIVER CL | F12: =DATE(2022,10,6) -> 44840 | G12: =+MONTH(F12) -> 10 | H12: =+YEAR(F12) -> 2022 | I12: Invoice | J12: 95939 | K12: FLOKTS02 | L12: Excel 0-0-25 | M12: GAL12.24 | N12: =+LEFT(M12,3) -> GAL | O12: 20 | Q12: =K12 -> FLOKTS02 | R12: =L12 -> Excel 0-0-25 | S12: =SUMIF($R$3:$R$885, $R12, $O$3:$O$885) -> 690 | U12: Excel 0-0-25 | V12: 690
B13: HAP | C13: 01 | D13: GREENWAY | E13: INDIAN RIVER CL | F13: =DATE(2022,10,6) -> 44840 | G13: =+MONTH(F13) -> 10 | H13: =+YEAR(F13) -> 2022 | I13: Invoice | J13: 95939 | K13: GPHUMIC02 | L13: Humic Soil Rebuilder | M13: GAL09.65 | N13: =+LEFT(M13,3) -> GAL | O13: 20 | Q13: =K13 -> GPHUMIC02 | R13: =L13 -> Humic Soil Rebuilder | S13: =SUMIF($R$3:$R$885, $R13, $O$3:$O$885) -> 180 | U13: Humic Soil Rebuilder | V13: 180
B14: HAP | C14: 01 | D14: GREENWAY | E14: INDIAN RIVER CL | F14: =DATE(2022,10,6) -> 44840 | G14: =+MONTH(F14) -> 10 | H14: =+YEAR(F14) -> 2022 | I14: Invoice | J14: 95939 | K14: FLO3181802 | L14: Mega Feed 3-18-18 | M14: GAL11.72 | N14: =+LEFT(M14,3) -> GAL | O14: 20 | Q14: =K14 -> FLO3181802 | R14: =L14 -> Mega Feed 3-18-18 | S14: =SUMIF($R$3:$R$885, $R14, $O$3:$O$885) -> 260 | U14: Mega Feed 3-18-18 | V14: 260
B15: HAP | C15: 01 | D15: GREENWAY | E15: INDIAN RIVER CL | F15: =DATE(2022,10,6) -> 44840 | G15: =+MONTH(F15) -> 10 | H15: =+YEAR(F15) -> 2022 | I15: Invoice | J15: 95939 | K15: FLOU3202 | L15: Quick Green | M15: GAL11.05 | N15: =+LEFT(M15,3) -> GAL | O15: 10 | Q15: =K15 -> FLOU3202 | R15: =L15 -> Quick Green | S15: =SUMIF($R$3:$R$885, $R15, $O$3:$O$885) -> 10 | U15: Quick Green | V15: 10
B16: HAP | C16: 01 | D16: GREENWAY | E16: INDIAN RIVER CL | F16: =DATE(2022,10,6) -> 44840 | G16: =+MONTH(F16) -> 10 | H16: =+YEAR(F16) -> 2022 | I16: Invoice | J16: 95939 | K16: USCBIOPX02 | L16: Vented Bio Plex | M16: GAL09.70 | N16: =+LEFT(M16,3) -> GAL | O16: 20 | Q16: =K16 -> USCBIOPX02 | R16: =L16 -> Vented Bio Plex | S16: =SUMIF($R$3:$R$885, $R16, $O$3:$O$885) -> 510 | U16: Vented Bio Plex | V16: 510
B17: HAP | C17: 01 | D17: GREENWAY | E17: INDIAN RIVER CL | F17: =DATE(2022,10,6) -> 44840 | G17: =+MONTH(F17) -> 10 | H17: =+YEAR(F17) -> 2022 | I17: Invoice | J17: 95939 | K17: USCMANPLX+02 | L17: Vented Manga Plex Plus | M17: GAL11.90 | N17: =+LEFT(M17,3) -> GAL | O17: 15 | Q17: =K17 -> USCMANPLX+02 | R17: =L17 -> Vented Manga Plex Plus | S17: =SUMIF($R$3:$R$885, $R17, $O$3:$O$885) -> 1060 | U17: Vented Manga Plex Plus | V17: 1060
B18: HAP | C18: 01 | D18: GREENWAY | E18: MAILING-WPBCH | F18: =DATE(2022,10,6) -> 44840 | G18: =+MONTH(F18) -> 10 | H18: =+YEAR(F18) -> 2022 | I18: Invoice | J18: 95940 | K18: FLOKTS02 | L18: Excel 0-0-25 | M18: GAL12.24 | N18: =+LEFT(M18,3) -> GAL | O18: 120 | Q18: =K18 -> FLOKTS02 | R18: =L18 -> Excel 0-0-25 | S18: =SUMIF($R$3:$R$885, $R18, $O$3:$O$885) -> 690 | U18: Excel 0-0-25 | V18: 690
B19: HAP | C19: 01 | D19: GREENWAY | E19: MAILING-WPBCH | F19: =DATE(2022,10,6) -> 44840 | G19: =+MONTH(F19) -> 10 | H19: =+YEAR(F19) -> 2022 | I19: Invoice | J19: 95940 | K19: FLO3181802 | L19: Mega Feed 3-18-18 | M19: GAL11.72 | N19: =+LEFT(M19,3) -> GAL | O19: 60 | Q19: =K19 -> FLO3181802 | R19: =L19 -> Mega Feed 3-18-18 | S19: =SUMIF($R$3:$R$885, $R19, $O$3:$O$885) -> 260 | U19: Mega Feed 3-18-18 | V19: 260
B20: HAP | C20: 01 | D20: GREENWAY | E20: MAILING-WPBCH | F20: =DATE(2022,10,6) -> 44840 | G20: =+MONTH(F20) -> 10 | H20: =+YEAR(F20) -> 2022 | I20: Invoice | J20: 95940 | K20: FLO824802 | L20: Mega Green Starter | M20: GAL11.70 | N20: =+LEFT(M20,3) -> GAL | O20: 30 | Q20: =K20 -> FLO824802 | R20: =L20 -> Mega Green Starter | S20: =SUMIF($R$3:$R$885, $R20, $O$3:$O$885) -> 60 | U20: Mega Green Starter | V20: 60
B21: HAP | C21: 01 | D21: GREENWAY | E21: MAILING-WPBCH | F21: =DATE(2022,10,6) -> 44840 | G21: =+MONTH(F21) -> 10 | H21: =+YEAR(F21) -> 2022 | I21: Invoice | J21: 95940 | K21: GROMG602 | L21: Mega Mix Mg | M21: GAL11.24 | N21: =+LEFT(M21,3) -> GAL | O21: 30 | Q21: =K21 -> GROMG602 | R21: =L21 -> Mega Mix Mg | S21: =SUMIF($R$3:$R$885, $R21, $O$3:$O$885) -> 150 | U21: Mega Mix Mg | V21: 150
B22: HAP | C22: 01 | D22: GREENWAY | E22: MAILING-WPBCH | F22: =DATE(2022,10,6) -> 44840 | G22: =+MONTH(F22) -> 10 | H22: =+YEAR(F22) -> 2022 | I22: Invoice | J22: 95940 | K22: ZONN2802 | L22: Ultra Green 28-0-0 | M22: GAL10.63 | N22: =+LEFT(M22,3) -> GAL | O22: 120 | Q22: =K22 -> ZONN2802 | R22: =L22 -> Ultra Green 28-0-0 | S22: =SUMIF($R$3:$R$885, $R22, $O$3:$O$885) -> 180 | U22: Ultra Green 28-0-0 | V22: 180
B23: HAP | C23: 01 | D23: GREENWAY | E23: MAILING-WPBCH | F23: =DATE(2022,10,6) -> 44840 | G23: =+MONTH(F23) -> 10 | H23: =+YEAR(F23) -> 2022 | I23: Invoice | J23: 95940 | K23: USCMANPLX+02 | L23: Vented Manga Plex Plus | M23: GAL11.90 | N23: =+LEFT(M23,3) -> GAL | O23: 120 | Q23: =K23 -> USCMANPLX+02 | R23: =L23 -> Vented Manga Plex Plus | S23: =SUMIF($R$3:$R$885, $R23, $O$3:$O$885) -> 1060 | U23: Vented Manga Plex Plus | V23: 1060
B24: HAP | C24: 01 | D24: GREENWAY | E24: LOXAHATCHEE CLB | F24: =DATE(2022,10,10) -> 44844 | G24: =+MONTH(F24) -> 10 | H24: =+YEAR(F24) -> 2022 | I24: Invoice | J24: 95953 | K24: FLO1200655 | L24: Green Master 12-0-0 | M24: GAL11.80 | N24: =+LEFT(M24,3) -> GAL | O24: 55 | Q24: =K24 -> FLO1200655 | R24: =L24 -> Green Master 12-0-0 | S24: =SUMIF($R$3:$R$885, $R24, $O$3:$O$885) -> 440 | U24: Green Master 12-0-0 | V24: 440
B25: HAP | C25: 01 | D25: ALMARCH | E25: THONOTOSASSA | F25: =DATE(2022,10,14) -> 44848 | G25: =+MONTH(F25) -> 10 | H25: =+YEAR(F25) -> 2022 | I25: Invoice | J25: 95978 | K25: ALMBGNOFE55 | L25: Beauti Green without Iron | M25: GAL09.42 | N25: =+LEFT(M25,3) -> GAL | O25: 165 | Q25: =K25 -> ALMBGNOFE55 | R25: =L25 -> Beauti Green without Iron | S25: =SUMIF($R$3:$R$885, $R25, $O$3:$O$885) -> 165 | U25: Beauti Green without Iron | V25: 165
B26: HAP | C26: 01 | D26: GREENWAY | E26: MIZNER C. CLUB | F26: =DATE(2022,10,14) -> 44848 | G26: =+MONTH(F26) -> 10 | H26: =+YEAR(F26) -> 2022 | I26: Invoice | J26: 95984 | K26: FLOKTS02 | L26: Excel 0-0-25 | M26: GAL12.24 | N26: =+LEFT(M26,3) -> GAL | O26: 35 | Q26: =K26 -> FLOKTS02 | R26: =L26 -> Excel 0-0-25 | S26: =SUMIF($R$3:$R$885, $R26, $O$3:$O$885) -> 690 | U26: Excel 0-0-25 | V26: 690
B27: HAP | C27: 01 | D27: GREENWAY | E27: MIZNER C. CLUB | F27: =DATE(2022,10,14) -> 44848 | G27: =+MONTH(F27) -> 10 | H27: =+YEAR(F27) -> 2022 | I27: Invoice | J27: 95984 | K27: GOLDCA02 | L27: Neutra Soil | M27: GAL11.60 | N27: =+LEFT(M27,3) -> GAL | O27: 70 | Q27: =K27 -> GOLDCA02 | R27: =L27 -> Neutra Soil | S27: =SUMIF($R$3:$R$885, $R27, $O$3:$O$885) -> 470 | U27: Neutra Soil | V27: 470
B28: HAP | C28: 01 | D28: GREENWAY | E28: MIZNER C. CLUB | F28: =DATE(2022,10,14) -> 44848 | G28: =+MONTH(F28) -> 10 | H28: =+YEAR(F28) -> 2022 | I28: Invoice | J28: 95984 | K28: USCBIOPX02 | L28: Vented Bio Plex | M28: GAL09.70 | N28: =+LEFT(M28,3) -> GAL | O28: 35 | Q28: =K28 -> USCBIOPX02 | R28: =L28 -> Vented Bio Plex | S28: =SUMIF($R$3:$R$885, $R28, $O$3:$O$885) -> 510 | U28: Vented Bio Plex | V28: 510
B29: HAP | C29: 01 | D29: GREENWAY | E29: MIZNER C. CLUB | F29: =DATE(2022,10,14) -> 44848 | G29: =+MONTH(F29) -> 10 | H29: =+YEAR(F29) -> 2022 | I29: Invoice | J29: 95984 | K29: USCMANPLX+02 | L29: Vented Manga Plex Plus | M29: GAL11.90 | N29: =+LEFT(M29,3) -> GAL | O29: 70 | Q29: =K29 -> USCMANPLX+02 | R29: =L29 -> Vented Manga Plex Plus | S29: =SUMIF($R$3:$R$885, $R29, $O$3:$O$885) -> 1060 | U29: Vented Manga Plex Plus | V29: 1060
B30: HAP | C30: 01 | D30: GREENWAY | E30: EMERALDHILLS | F30: =DATE(2022,10,18) -> 44852 | G30: =+MONTH(F30) -> 10 | H30: =+YEAR(F30) -> 2022 | I30: Invoice | J30: 96002 | K30: USC8FE30 | L30: 8 Iron | M30: GAL11.30 | N30: =+LEFT(M30,3) -> GAL | O30: 30 | Q30: =K30 -> USC8FE30 | R30: =L30 -> 8 Iron | S30: =SUMIF($R$3:$R$885, $R30, $O$3:$O$885) -> 185 | U30: 8 Iron | V30: 185
B31: HAP | C31: 01 | D31: GREENWAY | E31: EMERALDHILLS | F31: =DATE(2022,10,18) -> 44852 | G31: =+MONTH(F31) -> 10 | H31: =+YEAR(F31) -> 2022 | I31: Invoice | J31: 96002 | K31: ZON1501030 | L31: Ever-Green 15-0-10 | M31: GAL10.95 | N31: =+LEFT(M31,3) -> GAL | O31: 30 | Q31: =K31 -> ZON1501030 | R31: =L31 -> Ever-Green 15-0-10 | S31: =SUMIF($R$3:$R$885, $R31, $O$3:$O$885) -> 140 | U31: Ever-Green 15-0-10 | V31: 140
B32: HAP | C32: 01 | D32: GREENWAY | E32: EMERALDHILLS | F32: =DATE(2022,10,18) -> 44852 | G32: =+MONTH(F32) -> 10 | H32: =+YEAR(F32) -> 2022 | I32: Invoice | J32: 96002 | K32: FLOKTS30 | L32: Excel 0-0-25 | M32: GAL12.24 | N32: =+LEFT(M32,3) -> GAL | O32: 30 | Q32: =K32 -> FLOKTS30 | R32: =L32 -> Excel 0-0-25 | S32: =SUMIF($R$3:$R$885, $R32, $O$3:$O$885) -> 690 | U32: Excel 0-0-25 | V32: 690
B33: HAP | C33: 01 | D33: GREENWAY | E33: EMERALDHILLS | F33: =DATE(2022,10,18) -> 44852 | G33: =+MONTH(F33) -> 10 | H33: =+YEAR(F33) -> 2022 | I33: Invoice | J33: 96002 | K33: GROMG630 | L33: Mega Mix Mg | M33: GAL11.24 | N33: =+LEFT(M33,3) -> GAL | O33: 30 | Q33: =K33 -> GROMG630 | R33: =L33 -> Mega Mix Mg | S33: =SUMIF($R$3:$R$885, $R33, $O$3:$O$885) -> 150 | U33: Mega Mix Mg | V33: 150
B34: HAP | C34: 01 | D34: GREENWAY | E34: EMERALDHILLS | F34: =DATE(2022,10,18) -> 44852 | G34: =+MONTH(F34) -> 10 | H34: =+YEAR(F34) -> 2022 | I34: Invoice | J34: 96002 | K34: GROMN30 | L34: Mega Mix Mn | M34: GAL13.12 | N34: =+LEFT(M34,3) -> GAL | O34: 30 | Q34: =K34 -> GROMN30 | R34: =L34 -> Mega Mix Mn | S34: =SUMIF($R$3:$R$885, $R34, $O$3:$O$885) -> 110 | U34: Mega Mix Mn | V34: 110
B35: HAP | C35: 01 | D35: GREENWAY | E35: EMERALDHILLS | F35: =DATE(2022,10,18) -> 44852 | G35: =+MONTH(F35) -> 10 | H35: =+YEAR(F35) -> 2022 | I35: Invoice | J35: 96002 | K35: USCMICRO+30 | L35: Micro Plus | M35: GAL09.40 | N35: =+LEFT(M35,3) -> GAL | O35: 30 | Q35: =K35 -> USCMICRO+30 | R35: =L35 -> Micro Plus | S35: =SUMIF($R$3:$R$885, $R35, $O$3:$O$885) -> 70 | U35: Micro Plus | V35: 70
B36: HAP | C36: 01 | D36: GREENWAY | E36: EMERALDHILLS | F36: =DATE(2022,10,18) -> 44852 | G36: =+MONTH(F36) -> 10 | H36: =+YEAR(F36) -> 2022 | I36: Invoice | J36: 96002 | K36: USCMANPLX+30 | L36: Vented Manga Plex Plus | M36: GAL11.90 | N36: =+LEFT(M36,3) -> GAL | O36: 30 | Q36: =K36 -> USCMANPLX+30 | R36: =L36 -> Vented Manga Plex Plus | S36: =SUMIF($R$3:$R$885, $R36, $O$3:$O$885) -> 1060 | U36: Vented Manga Plex Plus | V36: 1060
B37: HAP | C37: 01 | D37: GREENWAY | E37: W.PALM BCH MAIN | F37: =DATE(2022,10,20) -> 44854 | G37: =+MONTH(F37) -> 10 | H37: =+YEAR(F37) -> 2022 | I37: Invoice | J37: 96019 | K37: GPHUMIC02 | L37: Humic Soil Rebuilder | M37: GAL09.65 | N37: =+LEFT(M37,3) -> GAL | O37: 60 | Q37: =K37 -> GPHUMIC02 | R37: =L37 -> Humic Soil Rebuilder | S37: =SUMIF($R$3:$R$885, $R37, $O$3:$O$885) -> 180 | U37: Humic Soil Rebuilder | V37: 180
B38: HAP | C38: 01 | D38: GREENWAY | E38: W.PALM BCH MAIN | F38: =DATE(2022,10,20) -> 44854 | G38: =+MONTH(F38) -> 10 | H38: =+YEAR(F38) -> 2022 | I38: Invoice | J38: 96019 | K38: USCMICMIX02 | L38: Micro Mix with Humic | M38: GAL10.35 | N38: =+LEFT(M38,3) -> GAL | O38: 60 | Q38: =K38 -> USCMICMIX02 | R38: =L38 -> Micro Mix with Humic | S38: =SUMIF($R$3:$R$885, $R38, $O$3:$O$885) -> 180 | U38: Micro Mix with Humic | V38: 180
B39: HAP | C39: 01 | D39: GREENWAY | E39: W.PALM BCH MAIN | F39: =DATE(2022,10,20) -> 44854 | G39: =+MONTH(F39) -> 10 | H39: =+YEAR(F39) -> 2022 | I39: Invoice | J39: 96019 | K39: GOLDCA02 | L39: Neutra Soil | M39: GAL11.60 | N39: =+LEFT(M39,3) -> GAL | O39: 120 | Q39: =K39 -> GOLDCA02 | R39: =L39 -> Neutra Soil | S39: =SUMIF($R$3:$R$885, $R39, $O$3:$O$885) -> 470 | U39: Neutra Soil | V39: 470
B40: HAP | C40: 01 | D40: GREENWAY | E40: W.PALM BCH MAIN | F40: =DATE(2022,10,20) -> 44854 | G40: =+MONTH(F40) -> 10 | H40: =+YEAR(F40) -> 2022 | I40: Invoice | J40: 96019 | K40: ZON183602 | L40: Pro Long | M40: GAL10.65 | N40: =+LEFT(M40,3) -> GAL | O40: 120 | Q40: =K40 -> ZON183602 | R40: =L40 -> Pro Long | S40: =SUMIF($R$3:$R$885, $R40, $O$3:$O$885) -> 180 | U40: Pro Long | V40: 180
B41: HAP | C41: 01 | D41: GREENWAY | E41: W.PALM BCH MAIN | F41: =DATE(2022,10,20) -> 44854 | G41: =+MONTH(F41) -> 10 | H41: =+YEAR(F41) -> 2022 | I41: Invoice | J41: 96019 | K41: USCBIOPX02 | L41: Vented Bio Plex | M41: GAL09.70 | N41: =+LEFT(M41,3) -> GAL | O41: 120 | Q41: =K41 -> USCBIOPX02 | R41: =L41 -> Vented Bio Plex | S41: =SUMIF($R$3:$R$885, $R41, $O$3:$O$885) -> 510 | U41: Vented Bio Plex | V41: 510
...

Sheet Sheet3
D2: OCT | E2: Nov | F2: Dec | G2: Jan | H2: Feb | I2: March | J2: April | K2: May | L2: June | M2: July | N2: Aug | O2: Sep
D3: 10 | E3: 11 | F3: 12 | G3: 1 | H3: =G3+1 -> 2 | I3: =H3+1 -> 3 | J3: =I3+1 -> 4 | K3: =J3+1 -> 5 | L3: =K3+1 -> 6 | M3: =L3+1 -> 7 | N3: =M3+1 -> 8 | O3: =N3+1 -> 9
C4: Thrive 8-21-6
C5: FLO821602 | D5: =SUMIFS(Sheet1!$O3:$O8885,Sheet1!$K3:$K8885,Sheet3!$C5,Sheet1!$G3:$G8885,Sheet3!D$3)/3/2/IF(RIGHT(TRIM(Sheet3!$C5),3)="250",250, IF(RIGHT(TRIM(Sheet3!$C5),2)="02",180,1)) -> 0 | E5: =SUMIFS(Sheet1!$O3:$O8885,Sheet1!$K3:$K8885,Sheet3!$C5,Sheet1!$G3:$G8885,Sheet3!E$3)/3/2/IF(RIGHT(TRIM(Sheet3!$C5),3)="250",250, IF(RIGHT(TRIM(Sheet3!$C5),2)="02",180,1)) -> 0 | F5: =SUMIFS(Sheet1!$O3:$O8885,Sheet1!$K3:$K8885,Sheet3!$C5,Sheet1!$G3:$G8885,Sheet3!F$3)/3/2/IF(RIGHT(TRIM(Sheet3!$C5),3)="250",250, IF(RIGHT(TRIM(Sheet3!$C5),2)="02",180,1)) -> 3.4351852 | G5: =SUMIFS(Sheet1!$O3:$O8885,Sheet1!$K3:$K8885,Sheet3!$C5,Sheet1!$G3:$G8885,Sheet3!G$3)/3/2/IF(RIGHT(TRIM(Sheet3!$C5),3)="250",250, IF(RIGHT(TRIM(Sheet3!$C5),2)="02",180,1)) -> 13.333333 | H5: =SUMIFS(Sheet1!$O3:$O8885,Sheet1!$K3:$K8885,Sheet3!$C5,Sheet1!$G3:$G8885,Sheet3!H$3)/3/2/IF(RIGHT(TRIM(Sheet3!$C5),3)="250",250, IF(RIGHT(TRIM(Sheet3!$C5),2)="02",180,1)) -> 30 | I5: =SUMIFS(Sheet1!$O3:$O8885,Sheet1!$K3:$K8885,Sheet3!$C5,Sheet1!$G3:$G8885,Sheet3!I$3)/3/2/IF(RIGHT(TRIM(Sheet3!$C5),3)="250",250, IF(RIGHT(TRIM(Sheet3!$C5),2)="02",180,1)) -> 20 | J5: =SUMIFS(Sheet1!$O3:$O8885,Sheet1!$K3:$K8885,Sheet3!$C5,Sheet1!$G3:$G8885,Sheet3!J$3)/3/2/IF(RIGHT(TRIM(Sheet3!$C5),3)="250",250, IF(RIGHT(TRIM(Sheet3!$C5),2)="02",180,1)) -> 0 | K5: =SUMIFS(Sheet1!$O3:$O8885,Sheet1!$K3:$K8885,Sheet3!$C5,Sheet1!$G3:$G8885,Sheet3!K$3)/3/2/IF(RIGHT(TRIM(Sheet3!$C5),3)="250",250, IF(RIGHT(TRIM(Sheet3!$C5),2)="02",180,1)) -> 0 | ... O5: =SUMIFS(Sheet1!$O3:$O8885,Sheet1!$K3:$K8885,Sheet3!$C5,Sheet1!$G3:$G8885,Sheet3!O$3)/3/2/IF(RIGHT(TRIM(Sheet3!$C5),3)="250",250, IF(RIGHT(TRIM(Sheet3!$C5),2)="02",180,1)) -> 0
C6: FLO8216250 | D6: =SUMIFS(Sheet1!$O4:$O8886,Sheet1!$K4:$K8886,Sheet3!$C6,Sheet1!$G4:$G8886,Sheet3!D$3)/3/2/IF(RIGHT(TRIM(Sheet3!$C6),3)="250",250, IF(RIGHT(TRIM(Sheet3!$C6),2)="02",180,1)) -> 0 | E6: =SUMIFS(Sheet1!$O4:$O8886,Sheet1!$K4:$K8886,Sheet3!$C6,Sheet1!$G4:$G8886,Sheet3!E$3)/3/2/IF(RIGHT(TRIM(Sheet3!$C6),3)="250",250, IF(RIGHT(TRIM(Sheet3!$C6),2)="02",180,1)) -> 4.9466667 | F6: =SUMIFS(Sheet1!$O4:$O8886,Sheet1!$K4:$K8886,Sheet3!$C6,Sheet1!$G4:$G8886,Sheet3!F$3)/3/2/IF(RIGHT(TRIM(Sheet3!$C6),3)="250",250, IF(RIGHT(TRIM(Sheet3!$C6),2)="02",180,1)) -> 19.786667 | G6: =SUMIFS(Sheet1!$O4:$O8886,Sheet1!$K4:$K8886,Sheet3!$C6,Sheet1!$G4:$G8886,Sheet3!G$3)/3/2/IF(RIGHT(TRIM(Sheet3!$C6),3)="250",250, IF(RIGHT(TRIM(Sheet3!$C6),2)="02",180,1)) -> 29.68 | H6: =SUMIFS(Sheet1!$O4:$O8886,Sheet1!$K4:$K8886,Sheet3!$C6,Sheet1!$G4:$G8886,Sheet3!H$3)/3/2/IF(RIGHT(TRIM(Sheet3!$C6),3)="250",250, IF(RIGHT(TRIM(Sheet3!$C6),2)="02",180,1)) -> 7.42 | I6: =SUMIFS(Sheet1!$O4:$O8886,Sheet1!$K4:$K8886,Sheet3!$C6,Sheet1!$G4:$G8886,Sheet3!I$3)/3/2/IF(RIGHT(TRIM(Sheet3!$C6),3)="250",250, IF(RIGHT(TRIM(Sheet3!$C6),2)="02",180,1)) -> 19.786667 | J6: =SUMIFS(Sheet1!$O4:$O8886,Sheet1!$K4:$K8886,Sheet3!$C6,Sheet1!$G4:$G8886,Sheet3!J$3)/3/2/IF(RIGHT(TRIM(Sheet3!$C6),3)="250",250, IF(RIGHT(TRIM(Sheet3!$C6),2)="02",180,1)) -> 7.42 | K6: =SUMIFS(Sheet1!$O4:$O8886,Sheet1!$K4:$K8886,Sheet3!$C6,Sheet1!$G4:$G8886,Sheet3!K$3)/3/2/IF(RIGHT(TRIM(Sheet3!$C6),3)="250",250, IF(RIGHT(TRIM(Sheet3!$C6),2)="02",180,1)) -> 0 | ... O6: =SUMIFS(Sheet1!$O4:$O8886,Sheet1!$K4:$K8886,Sheet3!$C6,Sheet1!$G4:$G8886,Sheet3!O$3)/3/2/IF(RIGHT(TRIM(Sheet3!$C6),3)="250",250, IF(RIGHT(TRIM(Sheet3!$C6),2)="02",180,1)) -> 0
C7: Top Side Liquid Boron
C8: TRITOPS02 | D8: =SUMIFS(Sheet1!$O6:$O8888,Sheet1!$K6:$K8888,Sheet3!$C8,Sheet1!$G6:$G8888,Sheet3!D$3)/3/2/IF(RIGHT(TRIM(Sheet3!$C8),3)="250",250, IF(RIGHT(TRIM(Sheet3!$C8),2)="02",180,1)) -> 0 | E8: =SUMIFS(Sheet1!$O6:$O8888,Sheet1!$K6:$K8888,Sheet3!$C8,Sheet1!$G6:$G8888,Sheet3!E$3)/3/2/IF(RIGHT(TRIM(Sheet3!$C8),3)="250",250, IF(RIGHT(TRIM(Sheet3!$C8),2)="02",180,1)) -> 0 | F8: =SUMIFS(Sheet1!$O6:$O8888,Sheet1!$K6:$K8888,Sheet3!$C8,Sheet1!$G6:$G8888,Sheet3!F$3)/3/2/IF(RIGHT(TRIM(Sheet3!$C8),3)="250",250, IF(RIGHT(TRIM(Sheet3!$C8),2)="02",180,1)) -> 0 | G8: =SUMIFS(Sheet1!$O6:$O8888,Sheet1!$K6:$K8888,Sheet3!$C8,Sheet1!$G6:$G8888,Sheet3!G$3)/3/2/IF(RIGHT(TRIM(Sheet3!$C8),3)="250",250, IF(RIGHT(TRIM(Sheet3!$C8),2)="02",180,1)) -> 0 | H8: =SUMIFS(Sheet1!$O6:$O8888,Sheet1!$K6:$K8888,Sheet3!$C8,Sheet1!$G6:$G8888,Sheet3!H$3)/3/2/IF(RIGHT(TRIM(Sheet3!$C8),3)="250",250, IF(RIGHT(TRIM(Sheet3!$C8),2)="02",180,1)) -> 0 | I8: =SUMIFS(Sheet1!$O6:$O8888,Sheet1!$K6:$K8888,Sheet3!$C8,Sheet1!$G6:$G8888,Sheet3!I$3)/3/2/IF(RIGHT(TRIM(Sheet3!$C8),3)="250",250, IF(RIGHT(TRIM(Sheet3!$C8),2)="02",180,1)) -> 9.3333333 | J8: =SUMIFS(Sheet1!$O6:$O8888,Sheet1!$K6:$K8888,Sheet3!$C8,Sheet1!$G6:$G8888,Sheet3!J$3)/3/2/IF(RIGHT(TRIM(Sheet3!$C8),3)="250",250, IF(RIGHT(TRIM(Sheet3!$C8),2)="02",180,1)) -> 31.333333 | K8: =SUMIFS(Sheet1!$O6:$O8888,Sheet1!$K6:$K8888,Sheet3!$C8,Sheet1!$G6:$G8888,Sheet3!K$3)/3/2/IF(RIGHT(TRIM(Sheet3!$C8),3)="250",250, IF(RIGHT(TRIM(Sheet3!$C8),2)="02",180,1)) -> 0 | ... O8: =SUMIFS(Sheet1!$O6:$O8888,Sheet1!$K6:$K8888,Sheet3!$C8,Sheet1!$G6:$G8888,Sheet3!O$3)/3/2/IF(RIGHT(TRIM(Sheet3!$C8),3)="250",250, IF(RIGHT(TRIM(Sheet3!$C8),2)="02",180,1)) -> 0
C9: TRITOPS250 | D9: =SUMIFS(Sheet1!$O7:$O8889,Sheet1!$K7:$K8889,Sheet3!$C9,Sheet1!$G7:$G8889,Sheet3!D$3)/3/2/IF(RIGHT(TRIM(Sheet3!$C9),3)="250",250, IF(RIGHT(TRIM(Sheet3!$C9),2)="02",180,1)) -> 0 | E9: =SUMIFS(Sheet1!$O7:$O8889,Sheet1!$K7:$K8889,Sheet3!$C9,Sheet1!$G7:$G8889,Sheet3!E$3)/3/2/IF(RIGHT(TRIM(Sheet3!$C9),3)="250",250, IF(RIGHT(TRIM(Sheet3!$C9),2)="02",180,1)) -> 0 | F9: =SUMIFS(Sheet1!$O7:$O8889,Sheet1!$K7:$K8889,Sheet3!$C9,Sheet1!$G7:$G8889,Sheet3!F$3)/3/2/IF(RIGHT(TRIM(Sheet3!$C9),3)="250",250, IF(RIGHT(TRIM(Sheet3!$C9),2)="02",180,1)) -> 0 | G9: =SUMIFS(Sheet1!$O7:$O8889,Sheet1!$K7:$K8889,Sheet3!$C9,Sheet1!$G7:$G8889,Sheet3!G$3)/3/2/IF(RIGHT(TRIM(Sheet3!$C9),3)="250",250, IF(RIGHT(TRIM(Sheet3!$C9),2)="02",180,1)) -> 0 | H9: =SUMIFS(Sheet1!$O7:$O8889,Sheet1!$K7:$K8889,Sheet3!$C9,Sheet1!$G7:$G8889,Sheet3!H$3)/3/2/IF(RIGHT(TRIM(Sheet3!$C9),3)="250",250, IF(RIGHT(TRIM(Sheet3!$C9),2)="02",180,1)) -> 0 | I9: =SUMIFS(Sheet1!$O7:$O8889,Sheet1!$K7:$K8889,Sheet3!$C9,Sheet1!$G7:$G8889,Sheet3!I$3)/3/2/IF(RIGHT(TRIM(Sheet3!$C9),3)="250",250, IF(RIGHT(TRIM(Sheet3!$C9),2)="02",180,1)) -> 3.8333333 | J9: =SUMIFS(Sheet1!$O7:$O8889,Sheet1!$K7:$K8889,Sheet3!$C9,Sheet1!$G7:$G8889,Sheet3!J$3)/3/2/IF(RIGHT(TRIM(Sheet3!$C9),3)="250",250, IF(RIGHT(TRIM(Sheet3!$C9),2)="02",180,1)) -> 13.333333 | K9: =SUMIFS(Sheet1!$O7:$O8889,Sheet1!$K7:$K8889,Sheet3!$C9,Sheet1!$G7:$G8889,Sheet3!K$3)/3/2/IF(RIGHT(TRIM(Sheet3!$C9),3)="250",250, IF(RIGHT(TRIM(Sheet3!$C9),2)="02",180,1)) -> 16.333333 | ... O9: =SUMIFS(Sheet1!$O7:$O8889,Sheet1!$K7:$K8889,Sheet3!$C9,Sheet1!$G7:$G8889,Sheet3!O$3)/3/2/IF(RIGHT(TRIM(Sheet3!$C9),3)="250",250, IF(RIGHT(TRIM(Sheet3!$C9),2)="02",180,1)) -> 0
C10: Citra Guard XP
C11: GRO131161902 | D11: =SUMIFS(Sheet1!$O9:$O8891,Sheet1!$K9:$K8891,Sheet3!$C11,Sheet1!$G9:$G8891,Sheet3!D$3)/3/2/IF(RIGHT(TRIM(Sheet3!$C11),3)="250",250, IF(RIGHT(TRIM(Sheet3!$C11),2)="02",180,1)) -> 0.060185185 | E11: =SUMIFS(Sheet1!$O9:$O8891,Sheet1!$K9:$K8891,Sheet3!$C11,Sheet1!$G9:$G8891,Sheet3!E$3)/3/2/IF(RIGHT(TRIM(Sheet3!$C11),3)="250",250, IF(RIGHT(TRIM(Sheet3!$C11),2)="02",180,1)) -> 0 | F11: =SUMIFS(Sheet1!$O9:$O8891,Sheet1!$K9:$K8891,Sheet3!$C11,Sheet1!$G9:$G8891,Sheet3!F$3)/3/2/IF(RIGHT(TRIM(Sheet3!$C11),3)="250",250, IF(RIGHT(TRIM(Sheet3!$C11),2)="02",180,1)) -> 0.018518519 | G11: =SUMIFS(Sheet1!$O9:$O8891,Sheet1!$K9:$K8891,Sheet3!$C11,Sheet1!$G9:$G8891,Sheet3!G$3)/3/2/IF(RIGHT(TRIM(Sheet3!$C11),3)="250",250, IF(RIGHT(TRIM(Sheet3!$C11),2)="02",180,1)) -> 0 | H11: =SUMIFS(Sheet1!$O9:$O8891,Sheet1!$K9:$K8891,Sheet3!$C11,Sheet1!$G9:$G8891,Sheet3!H$3)/3/2/IF(RIGHT(TRIM(Sheet3!$C11),3)="250",250, IF(RIGHT(TRIM(Sheet3!$C11),2)="02",180,1)) -> 0.087962963 | I11: =SUMIFS(Sheet1!$O9:$O8891,Sheet1!$K9:$K8891,Sheet3!$C11,Sheet1!$G9:$G8891,Sheet3!I$3)/3/2/IF(RIGHT(TRIM(Sheet3!$C11),3)="250",250, IF(RIGHT(TRIM(Sheet3!$C11),2)="02",180,1)) -> 0 | J11: =SUMIFS(Sheet1!$O9:$O8891,Sheet1!$K9:$K8891,Sheet3!$C11,Sheet1!$G9:$G8891,Sheet3!J$3)/3/2/IF(RIGHT(TRIM(Sheet3!$C11),3)="250",250, IF(RIGHT(TRIM(Sheet3!$C11),2)="02",180,1)) -> 0 | K11: =SUMIFS(Sheet1!$O9:$O8891,Sheet1!$K9:$K8891,Sheet3!$C11,Sheet1!$G9:$G8891,Sheet3!K$3)/3/2/IF(RIGHT(TRIM(Sheet3!$C11),3)="250",250, IF(RIGHT(TRIM(Sheet3!$C11),2)="02",180,1)) -> 0 | ... O11: =SUMIFS(Sheet1!$O9:$O8891,Sheet1!$K9:$K8891,Sheet3!$C11,Sheet1!$G9:$G8891,Sheet3!O$3)/3/2/IF(RIGHT(TRIM(Sheet3!$C11),3)="250",250, IF(RIGHT(TRIM(Sheet3!$C11),2)="02",180,1)) -> 0.023148148
C12: GRO1311619250 | D12: =SUMIFS(Sheet1!$O10:$O8892,Sheet1!$K10:$K8892,Sheet3!$C12,Sheet1!$G10:$G8892,Sheet3!D$3)/3/2/IF(RIGHT(TRIM(Sheet3!$C12),3)="250",250, IF(RIGHT(TRIM(Sheet3!$C12),2)="02",180,1)) -> 0.16666667 | E12: =SUMIFS(Sheet1!$O10:$O8892,Sheet1!$K10:$K8892,Sheet3!$C12,Sheet1!$G10:$G8892,Sheet3!E$3)/3/2/IF(RIGHT(TRIM(Sheet3!$C12),3)="250",250, IF(RIGHT(TRIM(Sheet3!$C12),2)="02",180,1)) -> 2 | F12: =SUMIFS(Sheet1!$O10:$O8892,Sheet1!$K10:$K8892,Sheet3!$C12,Sheet1!$G10:$G8892,Sheet3!F$3)/3/2/IF(RIGHT(TRIM(Sheet3!$C12),3)="250",250, IF(RIGHT(TRIM(Sheet3!$C12),2)="02",180,1)) -> 0.5 | G12: =SUMIFS(Sheet1!$O10:$O8892,Sheet1!$K10:$K8892,Sheet3!$C12,Sheet1!$G10:$G8892,Sheet3!G$3)/3/2/IF(RIGHT(TRIM(Sheet3!$C12),3)="250",250, IF(RIGHT(TRIM(Sheet3!$C12),2)="02",180,1)) -> 2.8333333 | H12: =SUMIFS(Sheet1!$O10:$O8892,Sheet1!$K10:$K8892,Sheet3!$C12,Sheet1!$G10:$G8892,Sheet3!H$3)/3/2/IF(RIGHT(TRIM(Sheet3!$C12),3)="250",250, IF(RIGHT(TRIM(Sheet3!$C12),2)="02",180,1)) -> 4.0333333 | I12: =SUMIFS(Sheet1!$O10:$O8892,Sheet1!$K10:$K8892,Sheet3!$C12,Sheet1!$G10:$G8892,Sheet3!I$3)/3/2/IF(RIGHT(TRIM(Sheet3!$C12),3)="250",250, IF(RIGHT(TRIM(Sheet3!$C12),2)="02",180,1)) -> 3.5333333 | J12: =SUMIFS(Sheet1!$O10:$O8892,Sheet1!$K10:$K8892,Sheet3!$C12,Sheet1!$G10:$G8892,Sheet3!J$3)/3/2/IF(RIGHT(TRIM(Sheet3!$C12),3)="250",250, IF(RIGHT(TRIM(Sheet3!$C12),2)="02",180,1)) -> 5.3333333 | K12: =SUMIFS(Sheet1!$O10:$O8892,Sheet1!$K10:$K8892,Sheet3!$C12,Sheet1!$G10:$G8892,Sheet3!K$3)/3/2/IF(RIGHT(TRIM(Sheet3!$C12),3)="250",250, IF(RIGHT(TRIM(Sheet3!$C12),2)="02",180,1)) -> 4.5 | ... O12: =SUMIFS(Sheet1!$O10:$O8892,Sheet1!$K10:$K8892,Sheet3!$C12,Sheet1!$G10:$G8892,Sheet3!O$3)/3/2/IF(RIGHT(TRIM(Sheet3!$C12),3)="250",250, IF(RIGHT(TRIM(Sheet3!$C12),2)="02",180,1)) -> 0.5
C13: Soar Bloom Spray
C14: SOARBLM250 | D14: =SUMIFS(Sheet1!$O12:$O8894,Sheet1!$K12:$K8894,Sheet3!$C14,Sheet1!$G12:$G8894,Sheet3!D$3)/3/2/IF(RIGHT(TRIM(Sheet3!$C14),3)="250",250, IF(RIGHT(TRIM(Sheet3!$C14),2)="02",180,1)) -> 0 | E14: =SUMIFS(Sheet1!$O12:$O8894,Sheet1!$K12:$K8894,Sheet3!$C14,Sheet1!$G12:$G8894,Sheet3!E$3)/3/2/IF(RIGHT(TRIM(Sheet3!$C14),3)="250",250, IF(RIGHT(TRIM(Sheet3!$C14),2)="02",180,1)) -> 0 | F14: =SUMIFS(Sheet1!$O12:$O8894,Sheet1!$K12:$K8894,Sheet3!$C14,Sheet1!$G12:$G8894,Sheet3!F$3)/3/2/IF(RIGHT(TRIM(Sheet3!$C14),3)="250",250, IF(RIGHT(TRIM(Sheet3!$C14),2)="02",180,1)) -> 0.16666667 | G14: =SUMIFS(Sheet1!$O12:$O8894,Sheet1!$K12:$K8894,Sheet3!$C14,Sheet1!$G12:$G8894,Sheet3!G$3)/3/2/IF(RIGHT(TRIM(Sheet3!$C14),3)="250",250, IF(RIGHT(TRIM(Sheet3!$C14),2)="02",180,1)) -> 3 | H14: =SUMIFS(Sheet1!$O12:$O8894,Sheet1!$K12:$K8894,Sheet3!$C14,Sheet1!$G12:$G8894,Sheet3!H$3)/3/2/IF(RIGHT(TRIM(Sheet3!$C14),3)="250",250, IF(RIGHT(TRIM(Sheet3!$C14),2)="02",180,1)) -> 9.3333333 | I14: =SUMIFS(Sheet1!$O12:$O8894,Sheet1!$K12:$K8894,Sheet3!$C14,Sheet1!$G12:$G8894,Sheet3!I$3)/3/2/IF(RIGHT(TRIM(Sheet3!$C14),3)="250",250, IF(RIGHT(TRIM(Sheet3!$C14),2)="02",180,1)) -> 4.8333333 | J14: =SUMIFS(Sheet1!$O12:$O8894,Sheet1!$K12:$K8894,Sheet3!$C14,Sheet1!$G12:$G8894,Sheet3!J$3)/3/2/IF(RIGHT(TRIM(Sheet3!$C14),3)="250",250, IF(RIGHT(TRIM(Sheet3!$C14),2)="02",180,1)) -> 1.8533333 | K14: =SUMIFS(Sheet1!$O12:$O8894,Sheet1!$K12:$K8894,Sheet3!$C14,Sheet1!$G12:$G8894,Sheet3!K$3)/3/2/IF(RIGHT(TRIM(Sheet3!$C14),3)="250",250, IF(RIGHT(TRIM(Sheet3!$C14),2)="02",180,1)) -> 1 | ... O14: =SUMIFS(Sheet1!$O12:$O8894,Sheet1!$K12:$K8894,Sheet3!$C14,Sheet1!$G12:$G8894,Sheet3!O$3)/3/2/IF(RIGHT(TRIM(Sheet3!$C14),3)="250",250, IF(RIGHT(TRIM(Sheet3!$C14),2)="02",180,1)) -> 0
C15: SOARBLM02 | D15: =SUMIFS(Sheet1!$O13:$O8895,Sheet1!$K13:$K8895,Sheet3!$C15,Sheet1!$G13:$G8895,Sheet3!D$3)/3/2/IF(RIGHT(TRIM(Sheet3!$C15),3)="250",250, IF(RIGHT(TRIM(Sheet3!$C15),2)="02",180,1)) -> 2.1851852 | E15: =SUMIFS(Sheet1!$O13:$O8895,Sheet1!$K13:$K8895,Sheet3!$C15,Sheet1!$G13:$G8895,Sheet3!E$3)/3/2/IF(RIGHT(TRIM(Sheet3!$C15),3)="250",250, IF(RIGHT(TRIM(Sheet3!$C15),2)="02",180,1)) -> 3.462963 | F15: =SUMIFS(Sheet1!$O13:$O8895,Sheet1!$K13:$K8895,Sheet3!$C15,Sheet1!$G13:$G8895,Sheet3!F$3)/3/2/IF(RIGHT(TRIM(Sheet3!$C15),3)="250",250, IF(RIGHT(TRIM(Sheet3!$C15),2)="02",180,1)) -> 5.1527778 | G15: =SUMIFS(Sheet1!$O13:$O8895,Sheet1!$K13:$K8895,Sheet3!$C15,Sheet1!$G13:$G8895,Sheet3!G$3)/3/2/IF(RIGHT(TRIM(Sheet3!$C15),3)="250",250, IF(RIGHT(TRIM(Sheet3!$C15),2)="02",180,1)) -> 8.2152778 | H15: =SUMIFS(Sheet1!$O13:$O8895,Sheet1!$K13:$K8895,Sheet3!$C15,Sheet1!$G13:$G8895,Sheet3!H$3)/3/2/IF(RIGHT(TRIM(Sheet3!$C15),3)="250",250, IF(RIGHT(TRIM(Sheet3!$C15),2)="02",180,1)) -> 9.3564815 | I15: =SUMIFS(Sheet1!$O13:$O8895,Sheet1!$K13:$K8895,Sheet3!$C15,Sheet1!$G13:$G8895,Sheet3!I$3)/3/2/IF(RIGHT(TRIM(Sheet3!$C15),3)="250",250, IF(RIGHT(TRIM(Sheet3!$C15),2)="02",180,1)) -> 9.8888889 | J15: =SUMIFS(Sheet1!$O13:$O8895,Sheet1!$K13:$K8895,Sheet3!$C15,Sheet1!$G13:$G8895,Sheet3!J$3)/3/2/IF(RIGHT(TRIM(Sheet3!$C15),3)="250",250, IF(RIGHT(TRIM(Sheet3!$C15),2)="02",180,1)) -> 9.5509259 | K15: =SUMIFS(Sheet1!$O13:$O8895,Sheet1!$K13:$K8895,Sheet3!$C15,Sheet1!$G13:$G8895,Sheet3!K$3)/3/2/IF(RIGHT(TRIM(Sheet3!$C15),3)="250",250, IF(RIGHT(TRIM(Sheet3!$C15),2)="02",180,1)) -> 1.6967593 | ... O15: =SUMIFS(Sheet1!$O13:$O8895,Sheet1!$K13:$K8895,Sheet3!$C15,Sheet1!$G13:$G8895,Sheet3!O$3)/3/2/IF(RIGHT(TRIM(Sheet3!$C15),3)="250",250, IF(RIGHT(TRIM(Sheet3!$C15),2)="02",180,1)) -> 2.0648148
C16: Soar Citrus Mix
C17: SOARCIT250 | D17: =SUMIFS(Sheet1!$O15:$O8897,Sheet1!$K15:$K8897,Sheet3!$C17,Sheet1!$G15:$G8897,Sheet3!D$3)/3/2/IF(RIGHT(TRIM(Sheet3!$C17),3)="250",250, IF(RIGHT(TRIM(Sheet3!$C17),2)="02",180,1)) -> 0 | E17: =SUMIFS(Sheet1!$O15:$O8897,Sheet1!$K15:$K8897,Sheet3!$C17,Sheet1!$G15:$G8897,Sheet3!E$3)/3/2/IF(RIGHT(TRIM(Sheet3!$C17),3)="250",250, IF(RIGHT(TRIM(Sheet3!$C17),2)="02",180,1)) -> 0 | F17: =SUMIFS(Sheet1!$O15:$O8897,Sheet1!$K15:$K8897,Sheet3!$C17,Sheet1!$G15:$G8897,Sheet3!F$3)/3/2/IF(RIGHT(TRIM(Sheet3!$C17),3)="250",250, IF(RIGHT(TRIM(Sheet3!$C17),2)="02",180,1)) -> 0 | G17: =SUMIFS(Sheet1!$O15:$O8897,Sheet1!$K15:$K8897,Sheet3!$C17,Sheet1!$G15:$G8897,Sheet3!G$3)/3/2/IF(RIGHT(TRIM(Sheet3!$C17),3)="250",250, IF(RIGHT(TRIM(Sheet3!$C17),2)="02",180,1)) -> 0 | H17: =SUMIFS(Sheet1!$O15:$O8897,Sheet1!$K15:$K8897,Sheet3!$C17,Sheet1!$G15:$G8897,Sheet3!H$3)/3/2/IF(RIGHT(TRIM(Sheet3!$C17),3)="250",250, IF(RIGHT(TRIM(Sheet3!$C17),2)="02",180,1)) -> 1 | I17: =SUMIFS(Sheet1!$O15:$O8897,Sheet1!$K15:$K8897,Sheet3!$C17,Sheet1!$G15:$G8897,Sheet3!I$3)/3/2/IF(RIGHT(TRIM(Sheet3!$C17),3)="250",250, IF(RIGHT(TRIM(Sheet3!$C17),2)="02",180,1)) -> 2.3333333 | J17: =SUMIFS(Sheet1!$O15:$O8897,Sheet1!$K15:$K8897,Sheet3!$C17,Sheet1!$G15:$G8897,Sheet3!J$3)/3/2/IF(RIGHT(TRIM(Sheet3!$C17),3)="250",250, IF(RIGHT(TRIM(Sheet3!$C17),2)="02",180,1)) -> 3 | K17: =SUMIFS(Sheet1!$O15:$O8897,Sheet1!$K15:$K8897,Sheet3!$C17,Sheet1!$G15:$G8897,Sheet3!K$3)/3/2/IF(RIGHT(TRIM(Sheet3!$C17),3)="250",250, IF(RIGHT(TRIM(Sheet3!$C17),2)="02",180,1)) -> 3.1666667 | ... O17: =SUMIFS(Sheet1!$O15:$O8897,Sheet1!$K15:$K8897,Sheet3!$C17,Sheet1!$G15:$G8897,Sheet3!O$3)/3/2/IF(RIGHT(TRIM(Sheet3!$C17),3)="250",250, IF(RIGHT(TRIM(Sheet3!$C17),2)="02",180,1)) -> 0.33333333
C18: SOARCIT02 | D18: =SUMIFS(Sheet1!$O16:$O8898,Sheet1!$K16:$K8898,Sheet3!$C18,Sheet1!$G16:$G8898,Sheet3!D$3)/3/2/IF(RIGHT(TRIM(Sheet3!$C18),3)="250",250, IF(RIGHT(TRIM(Sheet3!$C18),2)="02",180,1)) -> 0.33333333 | E18: =SUMIFS(Sheet1!$O16:$O8898,Sheet1!$K16:$K8898,Sheet3!$C18,Sheet1!$G16:$G8898,Sheet3!E$3)/3/2/IF(RIGHT(TRIM(Sheet3!$C18),3)="250",250, IF(RIGHT(TRIM(Sheet3!$C18),2)="02",180,1)) -> 0.027777778 | F18: =SUMIFS(Sheet1!$O16:$O8898,Sheet1!$K16:$K8898,Sheet3!$C18,Sheet1!$G16:$G8898,Sheet3!F$3)/3/2/IF(RIGHT(TRIM(Sheet3!$C18),3)="250",250, IF(RIGHT(TRIM(Sheet3!$C18),2)="02",180,1)) -> 0 | G18: =SUMIFS(Sheet1!$O16:$O8898,Sheet1!$K16:$K8898,Sheet3!$C18,Sheet1!$G16:$G8898,Sheet3!G$3)/3/2/IF(RIGHT(TRIM(Sheet3!$C18),3)="250",250, IF(RIGHT(TRIM(Sheet3!$C18),2)="02",180,1)) -> 0.19444444 | H18: =SUMIFS(Sheet1!$O16:$O8898,Sheet1!$K16:$K8898,Sheet3!$C18,Sheet1!$G16:$G8898,Sheet3!H$3)/3/2/IF(RIGHT(TRIM(Sheet3!$C18),3)="250",250, IF(RIGHT(TRIM(Sheet3!$C18),2)="02",180,1)) -> 0.375 | I18: =SUMIFS(Sheet1!$O16:$O8898,Sheet1!$K16:$K8898,Sheet3!$C18,Sheet1!$G16:$G8898,Sheet3!I$3)/3/2/IF(RIGHT(TRIM(Sheet3!$C18),3)="250",250, IF(RIGHT(TRIM(Sheet3!$C18),2)="02",180,1)) -> 4.2777778 | J18: =SUMIFS(Sheet1!$O16:$O8898,Sheet1!$K16:$K8898,Sheet3!$C18,Sheet1!$G16:$G8898,Sheet3!J$3)/3/2/IF(RIGHT(TRIM(Sheet3!$C18),3)="250",250, IF(RIGHT(TRIM(Sheet3!$C18),2)="02",180,1)) -> 6.3333333 | K18: =SUMIFS(Sheet1!$O16:$O8898,Sheet1!$K16:$K8898,Sheet3!$C18,Sheet1!$G16:$G8898,Sheet3!K$3)/3/2/IF(RIGHT(TRIM(Sheet3!$C18),3)="250",250, IF(RIGHT(TRIM(Sheet3!$C18),2)="02",180,1)) -> 7.212963 | ... O18: =SUMIFS(Sheet1!$O16:$O8898,Sheet1!$K16:$K8898,Sheet3!$C18,Sheet1!$G16:$G8898,Sheet3!O$3)/3/2/IF(RIGHT(TRIM(Sheet3!$C18),3)="250",250, IF(RIGHT(TRIM(Sheet3!$C18),2)="02",180,1)) -> 0.38888889
C19: Dyna Cal 10.25%
C20: SORCA02 | D20: =SUMIFS(Sheet1!$O18:$O8900,Sheet1!$K18:$K8900,Sheet3!$C20,Sheet1!$G18:$G8900,Sheet3!D$3)/3/2/IF(RIGHT(TRIM(Sheet3!$C20),3)="250",250, IF(RIGHT(TRIM(Sheet3!$C20),2)="02",180,1)) -> 0 | E20: =SUMIFS(Sheet1!$O18:$O8900,Sheet1!$K18:$K8900,Sheet3!$C20,Sheet1!$G18:$G8900,Sheet3!E$3)/3/2/IF(RIGHT(TRIM(Sheet3!$C20),3)="250",250, IF(RIGHT(TRIM(Sheet3!$C20),2)="02",180,1)) -> 0 | F20: =SUMIFS(Sheet1!$O18:$O8900,Sheet1!$K18:$K8900,Sheet3!$C20,Sheet1!$G18:$G8900,Sheet3!F$3)/3/2/IF(RIGHT(TRIM(Sheet3!$C20),3)="250",250, IF(RIGHT(TRIM(Sheet3!$C20),2)="02",180,1)) -> 0 | G20: =SUMIFS(Sheet1!$O18:$O8900,Sheet1!$K18:$K8900,Sheet3!$C20,Sheet1!$G18:$G8900,Sheet3!G$3)/3/2/IF(RIGHT(TRIM(Sheet3!$C20),3)="250",250, IF(RIGHT(TRIM(Sheet3!$C20),2)="02",180,1)) -> 0.0046296296 | H20: =SUMIFS(Sheet1!$O18:$O8900,Sheet1!$K18:$K8900,Sheet3!$C20,Sheet1!$G18:$G8900,Sheet3!H$3)/3/2/IF(RIGHT(TRIM(Sheet3!$C20),3)="250",250, IF(RIGHT(TRIM(Sheet3!$C20),2)="02",180,1)) -> 0 | I20: =SUMIFS(Sheet1!$O18:$O8900,Sheet1!$K18:$K8900,Sheet3!$C20,Sheet1!$G18:$G8900,Sheet3!I$3)/3/2/IF(RIGHT(TRIM(Sheet3!$C20),3)="250",250, IF(RIGHT(TRIM(Sheet3!$C20),2)="02",180,1)) -> 0.19444444 | J20: =SUMIFS(Sheet1!$O18:$O8900,Sheet1!$K18:$K8900,Sheet3!$C20,Sheet1!$G18:$G8900,Sheet3!J$3)/3/2/IF(RIGHT(TRIM(Sheet3!$C20),3)="250",250, IF(RIGHT(TRIM(Sheet3!$C20),2)="02",180,1)) -> 0.046296296 | K20: =SUMIFS(Sheet1!$O18:$O8900,Sheet1!$K18:$K8900,Sheet3!$C20,Sheet1!$G18:$G8900,Sheet3!K$3)/3/2/IF(RIGHT(TRIM(Sheet3!$C20),3)="250",250, IF(RIGHT(TRIM(Sheet3!$C20),2)="02",180,1)) -> 0.0046296296 | ... O20: =SUMIFS(Sheet1!$O18:$O8900,Sheet1!$K18:$K8900,Sheet3!$C20,Sheet1!$G18:$G8900,Sheet3!O$3)/3/2/IF(RIGHT(TRIM(Sheet3!$C20),3)="250",250, IF(RIGHT(TRIM(Sheet3!$C20),2)="02",180,1)) -> 0
C21: SORCA250 | D21: =SUMIFS(Sheet1!$O19:$O8901,Sheet1!$K19:$K8901,Sheet3!$C21,Sheet1!$G19:$G8901,Sheet3!D$3)/3/2/IF(RIGHT(TRIM(Sheet3!$C21),3)="250",250, IF(RIGHT(TRIM(Sheet3!$C21),2)="02",180,1)) -> 2 | E21: =SUMIFS(Sheet1!$O19:$O8901,Sheet1!$K19:$K8901,Sheet3!$C21,Sheet1!$G19:$G8901,Sheet3!E$3)/3/2/IF(RIGHT(TRIM(Sheet3!$C21),3)="250",250, IF(RIGHT(TRIM(Sheet3!$C21),2)="02",180,1)) -> 7.5 | F21: =SUMIFS(Sheet1!$O19:$O8901,Sheet1!$K19:$K8901,Sheet3!$C21,Sheet1!$G19:$G8901,Sheet3!F$3)/3/2/IF(RIGHT(TRIM(Sheet3!$C21),3)="250",250, IF(RIGHT(TRIM(Sheet3!$C21),2)="02",180,1)) -> 5.1666667 | G21: =SUMIFS(Sheet1!$O19:$O8901,Sheet1!$K19:$K8901,Sheet3!$C21,Sheet1!$G19:$G8901,Sheet3!G$3)/3/2/IF(RIGHT(TRIM(Sheet3!$C21),3)="250",250, IF(RIGHT(TRIM(Sheet3!$C21),2)="02",180,1)) -> 6.1666667 | H21: =SUMIFS(Sheet1!$O19:$O8901,Sheet1!$K19:$K8901,Sheet3!$C21,Sheet1!$G19:$G8901,Sheet3!H$3)/3/2/IF(RIGHT(TRIM(Sheet3!$C21),3)="250",250, IF(RIGHT(TRIM(Sheet3!$C21),2)="02",180,1)) -> 3.5 | I21: =SUMIFS(Sheet1!$O19:$O8901,Sheet1!$K19:$K8901,Sheet3!$C21,Sheet1!$G19:$G8901,Sheet3!I$3)/3/2/IF(RIGHT(TRIM(Sheet3!$C21),3)="250",250, IF(RIGHT(TRIM(Sheet3!$C21),2)="02",180,1)) -> 1.5 | J21: =SUMIFS(Sheet1!$O19:$O8901,Sheet1!$K19:$K8901,Sheet3!$C21,Sheet1!$G19:$G8901,Sheet3!J$3)/3/2/IF(RIGHT(TRIM(Sheet3!$C21),3)="250",250, IF(RIGHT(TRIM(Sheet3!$C21),2)="02",180,1)) -> 2 | K21: =SUMIFS(Sheet1!$O19:$O8901,Sheet1!$K19:$K8901,Sheet3!$C21,Sheet1!$G19:$G8901,Sheet3!K$3)/3/2/IF(RIGHT(TRIM(Sheet3!$C21),3)="250",250, IF(RIGHT(TRIM(Sheet3!$C21),2)="02",180,1)) -> 0.33333333 | ... O21: =SUMIFS(Sheet1!$O19:$O8901,Sheet1!$K19:$K8901,Sheet3!$C21,Sheet1!$G19:$G8901,Sheet3!O$3)/3/2/IF(RIGHT(TRIM(Sheet3!$C21),3)="250",250, IF(RIGHT(TRIM(Sheet3!$C21),2)="02",180,1)) -> 5.5
C22: Dyna Gold Calcium 8.25%
C23: GOLDCA250 | D23: =SUMIFS(Sheet1!$O21:$O8903,Sheet1!$K21:$K8903,Sheet3!$C23,Sheet1!$G21:$G8903,Sheet3!D$3)/3/2/IF(RIGHT(TRIM(Sheet3!$C23),3)="250",250, IF(RIGHT(TRIM(Sheet3!$C23),2)="02",180,1)) -> 0 | E23: =SUMIFS(Sheet1!$O21:$O8903,Sheet1!$K21:$K8903,Sheet3!$C23,Sheet1!$G21:$G8903,Sheet3!E$3)/3/2/IF(RIGHT(TRIM(Sheet3!$C23),3)="250",250, IF(RIGHT(TRIM(Sheet3!$C23),2)="02",180,1)) -> 0 | F23: =SUMIFS(Sheet1!$O21:$O8903,Sheet1!$K21:$K8903,Sheet3!$C23,Sheet1!$G21:$G8903,Sheet3!F$3)/3/2/IF(RIGHT(TRIM(Sheet3!$C23),3)="250",250, IF(RIGHT(TRIM(Sheet3!$C23),2)="02",180,1)) -> 1 | G23: =SUMIFS(Sheet1!$O21:$O8903,Sheet1!$K21:$K8903,Sheet3!$C23,Sheet1!$G21:$G8903,Sheet3!G$3)/3/2/IF(RIGHT(TRIM(Sheet3!$C23),3)="250",250, IF(RIGHT(TRIM(Sheet3!$C23),2)="02",180,1)) -> 0.5 | H23: =SUMIFS(Sheet1!$O21:$O8903,Sheet1!$K21:$K8903,Sheet3!$C23,Sheet1!$G21:$G8903,Sheet3!H$3)/3/2/IF(RIGHT(TRIM(Sheet3!$C23),3)="250",250, IF(RIGHT(TRIM(Sheet3!$C23),2)="02",180,1)) -> 0.5 | I23: =SUMIFS(Sheet1!$O21:$O8903,Sheet1!$K21:$K8903,Sheet3!$C23,Sheet1!$G21:$G8903,Sheet3!I$3)/3/2/IF(RIGHT(TRIM(Sheet3!$C23),3)="250",250, IF(RIGHT(TRIM(Sheet3!$C23),2)="02",180,1)) -> 0.83333333 | J23: =SUMIFS(Sheet1!$O21:$O8903,Sheet1!$K21:$K8903,Sheet3!$C23,Sheet1!$G21:$G8903,Sheet3!J$3)/3/2/IF(RIGHT(TRIM(Sheet3!$C23),3)="250",250, IF(RIGHT(TRIM(Sheet3!$C23),2)="02",180,1)) -> 0.5 | K23: =SUMIFS(Sheet1!$O21:$O8903,Sheet1!$K21:$K8903,Sheet3!$C23,Sheet1!$G21:$G8903,Sheet3!K$3)/3/2/IF(RIGHT(TRIM(Sheet3!$C23),3)="250",250, IF(RIGHT(TRIM(Sheet3!$C23),2)="02",180,1)) -> 0.16666667 | ... O23: =SUMIFS(Sheet1!$O21:$O8903,Sheet1!$K21:$K8903,Sheet3!$C23,Sheet1!$G21:$G8903,Sheet3!O$3)/3/2/IF(RIGHT(TRIM(Sheet3!$C23),3)="250",250, IF(RIGHT(TRIM(Sheet3!$C23),2)="02",180,1)) -> 0
C24: GOLDCA02 | D24: =SUMIFS(Sheet1!$O22:$O8904,Sheet1!$K22:$K8904,Sheet3!$C24,Sheet1!$G22:$G8904,Sheet3!D$3)/3/2/IF(RIGHT(TRIM(Sheet3!$C24),3)="250",250, IF(RIGHT(TRIM(Sheet3!$C24),2)="02",180,1)) -> 1.9166667 | E24: =SUMIFS(Sheet1!$O22:$O8904,Sheet1!$K22:$K8904,Sheet3!$C24,Sheet1!$G22:$G8904,Sheet3!E$3)/3/2/IF(RIGHT(TRIM(Sheet3!$C24),3)="250",250, IF(RIGHT(TRIM(Sheet3!$C24),2)="02",180,1)) -> 2.0787037 | F24: =SUMIFS(Sheet1!$O22:$O8904,Sheet1!$K22:$K8904,Sheet3!$C24,Sheet1!$G22:$G8904,Sheet3!F$3)/3/2/IF(RIGHT(TRIM(Sheet3!$C24),3)="250",250, IF(RIGHT(TRIM(Sheet3!$C24),2)="02",180,1)) -> 3.6134259 | G24: =SUMIFS(Sheet1!$O22:$O8904,Sheet1!$K22:$K8904,Sheet3!$C24,Sheet1!$G22:$G8904,Sheet3!G$3)/3/2/IF(RIGHT(TRIM(Sheet3!$C24),3)="250",250, IF(RIGHT(TRIM(Sheet3!$C24),2)="02",180,1)) -> 4.5138889 | H24: =SUMIFS(Sheet1!$O22:$O8904,Sheet1!$K22:$K8904,Sheet3!$C24,Sheet1!$G22:$G8904,Sheet3!H$3)/3/2/IF(RIGHT(TRIM(Sheet3!$C24),3)="250",250, IF(RIGHT(TRIM(Sheet3!$C24),2)="02",180,1)) -> 10.833333 | I24: =SUMIFS(Sheet1!$O22:$O8904,Sheet1!$K22:$K8904,Sheet3!$C24,Sheet1!$G22:$G8904,Sheet3!I$3)/3/2/IF(RIGHT(TRIM(Sheet3!$C24),3)="250",250, IF(RIGHT(TRIM(Sheet3!$C24),2)="02",180,1)) -> 4.7337963 | J24: =SUMIFS(Sheet1!$O22:$O8904,Sheet1!$K22:$K8904,Sheet3!$C24,Sheet1!$G22:$G8904,Sheet3!J$3)/3/2/IF(RIGHT(TRIM(Sheet3!$C24),3)="250",250, IF(RIGHT(TRIM(Sheet3!$C24),2)="02",180,1)) -> 4.1111111 | K24: =SUMIFS(Sheet1!$O22:$O8904,Sheet1!$K22:$K8904,Sheet3!$C24,Sheet1!$G22:$G8904,Sheet3!K$3)/3/2/IF(RIGHT(TRIM(Sheet3!$C24),3)="250",250, IF(RIGHT(TRIM(Sheet3!$C24),2)="02",180,1)) -> 1.6759259 | ... O24: =SUMIFS(Sheet1!$O22:$O8904,Sheet1!$K22:$K8904,Sheet3!$C24,Sheet1!$G22:$G8904,Sheet3!O$3)/3/2/IF(RIGHT(TRIM(Sheet3!$C24),3)="250",250, IF(RIGHT(TRIM(Sheet3!$C24),2)="02",180,1)) -> 1.1851852
C25: Dyna Green Potato Mix
C26: GREPOT250 | D26: =SUMIFS(Sheet1!$O27:$O8909,Sheet1!$K27:$K8909,Sheet3!$C26,Sheet1!$G27:$G8909,Sheet3!D$3)/3/2/IF(RIGHT(TRIM(Sheet3!$C26),3)="250",250, IF(RIGHT(TRIM(Sheet3!$C26),2)="02",180,1)) -> 0 | E26: =SUMIFS(Sheet1!$O27:$O8909,Sheet1!$K27:$K8909,Sheet3!$C26,Sheet1!$G27:$G8909,Sheet3!E$3)/3/2/IF(RIGHT(TRIM(Sheet3!$C26),3)="250",250, IF(RIGHT(TRIM(Sheet3!$C26),2)="02",180,1)) -> 0 | F26: =SUMIFS(Sheet1!$O27:$O8909,Sheet1!$K27:$K8909,Sheet3!$C26,Sheet1!$G27:$G8909,Sheet3!F$3)/3/2/IF(RIGHT(TRIM(Sheet3!$C26),3)="250",250, IF(RIGHT(TRIM(Sheet3!$C26),2)="02",180,1)) -> 0 | G26: =SUMIFS(Sheet1!$O27:$O8909,Sheet1!$K27:$K8909,Sheet3!$C26,Sheet1!$G27:$G8909,Sheet3!G$3)/3/2/IF(RIGHT(TRIM(Sheet3!$C26),3)="250",250, IF(RIGHT(TRIM(Sheet3!$C26),2)="02",180,1)) -> 1 | H26: =SUMIFS(Sheet1!$O27:$O8909,Sheet1!$K27:$K8909,Sheet3!$C26,Sheet1!$G27:$G8909,Sheet3!H$3)/3/2/IF(RIGHT(TRIM(Sheet3!$C26),3)="250",250, IF(RIGHT(TRIM(Sheet3!$C26),2)="02",180,1)) -> 2.3333333 | I26: =SUMIFS(Sheet1!$O27:$O8909,Sheet1!$K27:$K8909,Sheet3!$C26,Sheet1!$G27:$G8909,Sheet3!I$3)/3/2/IF(RIGHT(TRIM(Sheet3!$C26),3)="250",250, IF(RIGHT(TRIM(Sheet3!$C26),2)="02",180,1)) -> 6.5 | J26: =SUMIFS(Sheet1!$O27:$O8909,Sheet1!$K27:$K8909,Sheet3!$C26,Sheet1!$G27:$G8909,Sheet3!J$3)/3/2/IF(RIGHT(TRIM(Sheet3!$C26),3)="250",250, IF(RIGHT(TRIM(Sheet3!$C26),2)="02",180,1)) -> 1.1666667 | K26: =SUMIFS(Sheet1!$O27:$O8909,Sheet1!$K27:$K8909,Sheet3!$C26,Sheet1!$G27:$G8909,Sheet3!K$3)/3/2/IF(RIGHT(TRIM(Sheet3!$C26),3)="250",250, IF(RIGHT(TRIM(Sheet3!$C26),2)="02",180,1)) -> 0 | ... O26: =SUMIFS(Sheet1!$O27:$O8909,Sheet1!$K27:$K8909,Sheet3!$C26,Sheet1!$G27:$G8909,Sheet3!O$3)/3/2/IF(RIGHT(TRIM(Sheet3!$C26),3)="250",250, IF(RIGHT(TRIM(Sheet3!$C26),2)="02",180,1)) -> 0
C27: Dyna Flo 0-0-25 17
C28: FLOKTS02 | D28: =SUMIFS(Sheet1!$O35:$O8917,Sheet1!$K35:$K8917,Sheet3!$C28,Sheet1!$G35:$G8917,Sheet3!D$3)/3/2/IF(RIGHT(TRIM(Sheet3!$C28),3)="250",250, IF(RIGHT(TRIM(Sheet3!$C28),2)="02",180,1)) -> 0.62037037 | E28: =SUMIFS(Sheet1!$O35:$O8917,Sheet1!$K35:$K8917,Sheet3!$C28,Sheet1!$G35:$G8917,Sheet3!E$3)/3/2/IF(RIGHT(TRIM(Sheet3!$C28),3)="250",250, IF(RIGHT(TRIM(Sheet3!$C28),2)="02",180,1)) -> 1.0046296 | F28: =SUMIFS(Sheet1!$O35:$O8917,Sheet1!$K35:$K8917,Sheet3!$C28,Sheet1!$G35:$G8917,Sheet3!F$3)/3/2/IF(RIGHT(TRIM(Sheet3!$C28),3)="250",250, IF(RIGHT(TRIM(Sheet3!$C28),2)="02",180,1)) -> 0.63425926 | G28: =SUMIFS(Sheet1!$O35:$O8917,Sheet1!$K35:$K8917,Sheet3!$C28,Sheet1!$G35:$G8917,Sheet3!G$3)/3/2/IF(RIGHT(TRIM(Sheet3!$C28),3)="250",250, IF(RIGHT(TRIM(Sheet3!$C28),2)="02",180,1)) -> 1.4421296 | H28: =SUMIFS(Sheet1!$O35:$O8917,Sheet1!$K35:$K8917,Sheet3!$C28,Sheet1!$G35:$G8917,Sheet3!H$3)/3/2/IF(RIGHT(TRIM(Sheet3!$C28),3)="250",250, IF(RIGHT(TRIM(Sheet3!$C28),2)="02",180,1)) -> 1.3657407 | I28: =SUMIFS(Sheet1!$O35:$O8917,Sheet1!$K35:$K8917,Sheet3!$C28,Sheet1!$G35:$G8917,Sheet3!I$3)/3/2/IF(RIGHT(TRIM(Sheet3!$C28),3)="250",250, IF(RIGHT(TRIM(Sheet3!$C28),2)="02",180,1)) -> 0.75925926 | J28: =SUMIFS(Sheet1!$O35:$O8917,Sheet1!$K35:$K8917,Sheet3!$C28,Sheet1!$G35:$G8917,Sheet3!J$3)/3/2/IF(RIGHT(TRIM(Sheet3!$C28),3)="250",250, IF(RIGHT(TRIM(Sheet3!$C28),2)="02",180,1)) -> 0.57407407 | K28: =SUMIFS(Sheet1!$O35:$O8917,Sheet1!$K35:$K8917,Sheet3!$C28,Sheet1!$G35:$G8917,Sheet3!K$3)/3/2/IF(RIGHT(TRIM(Sheet3!$C28),3)="250",250, IF(RIGHT(TRIM(Sheet3!$C28),2)="02",180,1)) -> 1.2314815 | ... O28: =SUMIFS(Sheet1!$O35:$O8917,Sheet1!$K35:$K8917,Sheet3!$C28,Sheet1!$G35:$G8917,Sheet3!O$3)/3/2/IF(RIGHT(TRIM(Sheet3!$C28),3)="250",250, IF(RIGHT(TRIM(Sheet3!$C28),2)="02",180,1)) -> 0.81018519
C29: FLOKTS250 | D29: =SUMIFS(Sheet1!$O36:$O8918,Sheet1!$K36:$K8918,Sheet3!$C29,Sheet1!$G36:$G8918,Sheet3!D$3)/3/2/IF(RIGHT(TRIM(Sheet3!$C29),3)="250",250, IF(RIGHT(TRIM(Sheet3!$C29),2)="02",180,1)) -> 2.1166667 | E29: =SUMIFS(Sheet1!$O36:$O8918,Sheet1!$K36:$K8918,Sheet3!$C29,Sheet1!$G36:$G8918,Sheet3!E$3)/3/2/IF(RIGHT(TRIM(Sheet3!$C29),3)="250",250, IF(RIGHT(TRIM(Sheet3!$C29),2)="02",180,1)) -> 2.5 | F29: =SUMIFS(Sheet1!$O36:$O8918,Sheet1!$K36:$K8918,Sheet3!$C29,Sheet1!$G36:$G8918,Sheet3!F$3)/3/2/IF(RIGHT(TRIM(Sheet3!$C29),3)="250",250, IF(RIGHT(TRIM(Sheet3!$C29),2)="02",180,1)) -> 1.1666667 | G29: =SUMIFS(Sheet1!$O36:$O8918,Sheet1!$K36:$K8918,Sheet3!$C29,Sheet1!$G36:$G8918,Sheet3!G$3)/3/2/IF(RIGHT(TRIM(Sheet3!$C29),3)="250",250, IF(RIGHT(TRIM(Sheet3!$C29),2)="02",180,1)) -> 0.66666667 | H29: =SUMIFS(Sheet1!$O36:$O8918,Sheet1!$K36:$K8918,Sheet3!$C29,Sheet1!$G36:$G8918,Sheet3!H$3)/3/2/IF(RIGHT(TRIM(Sheet3!$C29),3)="250",250, IF(RIGHT(TRIM(Sheet3!$C29),2)="02",180,1)) -> 1.5786667 | I29: =SUMIFS(Sheet1!$O36:$O8918,Sheet1!$K36:$K8918,Sheet3!$C29,Sheet1!$G36:$G8918,Sheet3!I$3)/3/2/IF(RIGHT(TRIM(Sheet3!$C29),3)="250",250, IF(RIGHT(TRIM(Sheet3!$C29),2)="02",180,1)) -> 0.16666667 | J29: =SUMIFS(Sheet1!$O36:$O8918,Sheet1!$K36:$K8918,Sheet3!$C29,Sheet1!$G36:$G8918,Sheet3!J$3)/3/2/IF(RIGHT(TRIM(Sheet3!$C29),3)="250",250, IF(RIGHT(TRIM(Sheet3!$C29),2)="02",180,1)) -> 0.66666667 | K29: =SUMIFS(Sheet1!$O36:$O8918,Sheet1!$K36:$K8918,Sheet3!$C29,Sheet1!$G36:$G8918,Sheet3!K$3)/3/2/IF(RIGHT(TRIM(Sheet3!$C29),3)="250",250, IF(RIGHT(TRIM(Sheet3!$C29),2)="02",180,1)) -> 3.6666667 | ... O29: =SUMIFS(Sheet1!$O36:$O8918,Sheet1!$K36:$K8918,Sheet3!$C29,Sheet1!$G36:$G8918,Sheet3!O$3)/3/2/IF(RIGHT(TRIM(Sheet3!$C29),3)="250",250, IF(RIGHT(TRIM(Sheet3!$C29),2)="02",180,1)) -> 0.91666667
D30: =D29+D28*180/250 -> 2.5633333 | E30: =E29+E28*180/250 -> 3.2233333 | F30: =F29+F28*180/250 -> 1.6233333 | G30: =G29+G28*180/250 -> 1.705 | H30: =H29+H28*180/250 -> 2.562 | I30: =I29+I28*180/250 -> 0.71333333 | J30: =J29+J28*180/250 -> 1.08 | K30: =K29+K28*180/250 -> 4.5533333 | ... O30: =O29+O28*180/250 -> 1.5
C31: Dyna Flo 3-18-18
C32: FLO3181802 | D32: =SUMIFS(Sheet1!$O40:$O8922,Sheet1!$K40:$K8922,Sheet3!$C32,Sheet1!$G40:$G8922,Sheet3!D$3)/3/2/IF(RIGHT(TRIM(Sheet3!$C32),3)="250",250, IF(RIGHT(TRIM(Sheet3!$C32),2)="02",180,1)) -> 0.16666667 | E32: =SUMIFS(Sheet1!$O40:$O8922,Sheet1!$K40:$K8922,Sheet3!$C32,Sheet1!$G40:$G8922,Sheet3!E$3)/3/2/IF(RIGHT(TRIM(Sheet3!$C32),3)="250",250, IF(RIGHT(TRIM(Sheet3!$C32),2)="02",180,1)) -> 0.23611111 | F32: =SUMIFS(Sheet1!$O40:$O8922,Sheet1!$K40:$K8922,Sheet3!$C32,Sheet1!$G40:$G8922,Sheet3!F$3)/3/2/IF(RIGHT(TRIM(Sheet3!$C32),3)="250",250, IF(RIGHT(TRIM(Sheet3!$C32),2)="02",180,1)) -> 0.2037037 | G32: =SUMIFS(Sheet1!$O40:$O8922,Sheet1!$K40:$K8922,Sheet3!$C32,Sheet1!$G40:$G8922,Sheet3!G$3)/3/2/IF(RIGHT(TRIM(Sheet3!$C32),3)="250",250, IF(RIGHT(TRIM(Sheet3!$C32),2)="02",180,1)) -> 0.083333333 | H32: =SUMIFS(Sheet1!$O40:$O8922,Sheet1!$K40:$K8922,Sheet3!$C32,Sheet1!$G40:$G8922,Sheet3!H$3)/3/2/IF(RIGHT(TRIM(Sheet3!$C32),3)="250",250, IF(RIGHT(TRIM(Sheet3!$C32),2)="02",180,1)) -> 0.30555556 | I32: =SUMIFS(Sheet1!$O40:$O8922,Sheet1!$K40:$K8922,Sheet3!$C32,Sheet1!$G40:$G8922,Sheet3!I$3)/3/2/IF(RIGHT(TRIM(Sheet3!$C32),3)="250",250, IF(RIGHT(TRIM(Sheet3!$C32),2)="02",180,1)) -> 0.19444444 | J32: =SUMIFS(Sheet1!$O40:$O8922,Sheet1!$K40:$K8922,Sheet3!$C32,Sheet1!$G40:$G8922,Sheet3!J$3)/3/2/IF(RIGHT(TRIM(Sheet3!$C32),3)="250",250, IF(RIGHT(TRIM(Sheet3!$C32),2)="02",180,1)) -> 0.13888889 | K32: =SUMIFS(Sheet1!$O40:$O8922,Sheet1!$K40:$K8922,Sheet3!$C32,Sheet1!$G40:$G8922,Sheet3!K$3)/3/2/IF(RIGHT(TRIM(Sheet3!$C32),3)="250",250, IF(RIGHT(TRIM(Sheet3!$C32),2)="02",180,1)) -> 0.16666667 | ... O32: =SUMIFS(Sheet1!$O40:$O8922,Sheet1!$K40:$K8922,Sheet3!$C32,Sheet1!$G40:$G8922,Sheet3!O$3)/3/2/IF(RIGHT(TRIM(Sheet3!$C32),3)="250",250, IF(RIGHT(TRIM(Sheet3!$C32),2)="02",180,1)) -> 0.34722222
C33: FLO31818250 | D33: =SUMIFS(Sheet1!$O41:$O8923,Sheet1!$K41:$K8923,Sheet3!$C33,Sheet1!$G41:$G8923,Sheet3!D$3)/3/2/IF(RIGHT(TRIM(Sheet3!$C33),3)="250",250, IF(RIGHT(TRIM(Sheet3!$C33),2)="02",180,1)) -> 0.33333333 | E33: =SUMIFS(Sheet1!$O41:$O8923,Sheet1!$K41:$K8923,Sheet3!$C33,Sheet1!$G41:$G8923,Sheet3!E$3)/3/2/IF(RIGHT(TRIM(Sheet3!$C33),3)="250",250, IF(RIGHT(TRIM(Sheet3!$C33),2)="02",180,1)) -> 0 | F33: =SUMIFS(Sheet1!$O41:$O8923,Sheet1!$K41:$K8923,Sheet3!$C33,Sheet1!$G41:$G8923,Sheet3!F$3)/3/2/IF(RIGHT(TRIM(Sheet3!$C33),3)="250",250, IF(RIGHT(TRIM(Sheet3!$C33),2)="02",180,1)) -> 0 | G33: =SUMIFS(Sheet1!$O41:$O8923,Sheet1!$K41:$K8923,Sheet3!$C33,Sheet1!$G41:$G8923,Sheet3!G$3)/3/2/IF(RIGHT(TRIM(Sheet3!$C33),3)="250",250, IF(RIGHT(TRIM(Sheet3!$C33),2)="02",180,1)) -> 12.166667 | H33: =SUMIFS(Sheet1!$O41:$O8923,Sheet1!$K41:$K8923,Sheet3!$C33,Sheet1!$G41:$G8923,Sheet3!H$3)/3/2/IF(RIGHT(TRIM(Sheet3!$C33),3)="250",250, IF(RIGHT(TRIM(Sheet3!$C33),2)="02",180,1)) -> 0 | I33: =SUMIFS(Sheet1!$O41:$O8923,Sheet1!$K41:$K8923,Sheet3!$C33,Sheet1!$G41:$G8923,Sheet3!I$3)/3/2/IF(RIGHT(TRIM(Sheet3!$C33),3)="250",250, IF(RIGHT(TRIM(Sheet3!$C33),2)="02",180,1)) -> 1 | J33: =SUMIFS(Sheet1!$O41:$O8923,Sheet1!$K41:$K8923,Sheet3!$C33,Sheet1!$G41:$G8923,Sheet3!J$3)/3/2/IF(RIGHT(TRIM(Sheet3!$C33),3)="250",250, IF(RIGHT(TRIM(Sheet3!$C33),2)="02",180,1)) -> 0.16666667 | K33: =SUMIFS(Sheet1!$O41:$O8923,Sheet1!$K41:$K8923,Sheet3!$C33,Sheet1!$G41:$G8923,Sheet3!K$3)/3/2/IF(RIGHT(TRIM(Sheet3!$C33),3)="250",250, IF(RIGHT(TRIM(Sheet3!$C33),2)="02",180,1)) -> 0 | ... O33: =SUMIFS(Sheet1!$O41:$O8923,Sheet1!$K41:$K8923,Sheet3!$C33,Sheet1!$G41:$G8923,Sheet3!O$3)/3/2/IF(RIGHT(TRIM(Sheet3!$C33),3)="250",250, IF(RIGHT(TRIM(Sheet3!$C33),2)="02",180,1)) -> 0.5
D34: =D33+(D32*180/250) -> 0.45333333 | E34: =E33+(E32*180/250) -> 0.17 | F34: =F33+(F32*180/250) -> 0.14666667 | G34: =G33+(G32*180/250) -> 12.226667 | H34: =H33+(H32*180/250) -> 0.22 | I34: =I33+(I32*180/250) -> 1.14 | J34: =J33+(J32*180/250) -> 0.26666667 | K34: =K33+(K32*180/250) -> 0.12 | ... O34: =O33+(O32*180/250) -> 0.75
C35: Dyna Zone 18-3-6
C36: ZON183602 | D36: =SUMIFS(Sheet1!$O45:$O8927,Sheet1!$K45:$K8927,Sheet3!$C36,Sheet1!$G45:$G8927,Sheet3!D$3)/3/2/IF(RIGHT(TRIM(Sheet3!$C36),3)="250",250, IF(RIGHT(TRIM(Sheet3!$C36),2)="02",180,1)) -> 1.587963 | E36: =SUMIFS(Sheet1!$O45:$O8927,Sheet1!$K45:$K8927,Sheet3!$C36,Sheet1!$G45:$G8927,Sheet3!E$3)/3/2/IF(RIGHT(TRIM(Sheet3!$C36),3)="250",250, IF(RIGHT(TRIM(Sheet3!$C36),2)="02",180,1)) -> 1.3333333 | F36: =SUMIFS(Sheet1!$O45:$O8927,Sheet1!$K45:$K8927,Sheet3!$C36,Sheet1!$G45:$G8927,Sheet3!F$3)/3/2/IF(RIGHT(TRIM(Sheet3!$C36),3)="250",250, IF(RIGHT(TRIM(Sheet3!$C36),2)="02",180,1)) -> 0.59722222 | G36: =SUMIFS(Sheet1!$O45:$O8927,Sheet1!$K45:$K8927,Sheet3!$C36,Sheet1!$G45:$G8927,Sheet3!G$3)/3/2/IF(RIGHT(TRIM(Sheet3!$C36),3)="250",250, IF(RIGHT(TRIM(Sheet3!$C36),2)="02",180,1)) -> 1.287037 | H36: =SUMIFS(Sheet1!$O45:$O8927,Sheet1!$K45:$K8927,Sheet3!$C36,Sheet1!$G45:$G8927,Sheet3!H$3)/3/2/IF(RIGHT(TRIM(Sheet3!$C36),3)="250",250, IF(RIGHT(TRIM(Sheet3!$C36),2)="02",180,1)) -> 2.8796296 | I36: =SUMIFS(Sheet1!$O45:$O8927,Sheet1!$K45:$K8927,Sheet3!$C36,Sheet1!$G45:$G8927,Sheet3!I$3)/3/2/IF(RIGHT(TRIM(Sheet3!$C36),3)="250",250, IF(RIGHT(TRIM(Sheet3!$C36),2)="02",180,1)) -> 2.2662037 | J36: =SUMIFS(Sheet1!$O45:$O8927,Sheet1!$K45:$K8927,Sheet3!$C36,Sheet1!$G45:$G8927,Sheet3!J$3)/3/2/IF(RIGHT(TRIM(Sheet3!$C36),3)="250",250, IF(RIGHT(TRIM(Sheet3!$C36),2)="02",180,1)) -> 0.96759259 | K36: =SUMIFS(Sheet1!$O45:$O8927,Sheet1!$K45:$K8927,Sheet3!$C36,Sheet1!$G45:$G8927,Sheet3!K$3)/3/2/IF(RIGHT(TRIM(Sheet3!$C36),3)="250",250, IF(RIGHT(TRIM(Sheet3!$C36),2)="02",180,1)) -> 0.43981481 | ... O36: =SUMIFS(Sheet1!$O45:$O8927,Sheet1!$K45:$K8927,Sheet3!$C36,Sheet1!$G45:$G8927,Sheet3!O$3)/3/2/IF(RIGHT(TRIM(Sheet3!$C36),3)="250",250, IF(RIGHT(TRIM(Sheet3!$C36),2)="02",180,1)) -> 0.12962963
C37: ZON1836250 | D37: =SUMIFS(Sheet1!$O46:$O8928,Sheet1!$K46:$K8928,Sheet3!$C37,Sheet1!$G46:$G8928,Sheet3!D$3)/3/2/IF(RIGHT(TRIM(Sheet3!$C37),3)="250",250, IF(RIGHT(TRIM(Sheet3!$C37),2)="02",180,1)) -> 1.3166667 | E37: =SUMIFS(Sheet1!$O46:$O8928,Sheet1!$K46:$K8928,Sheet3!$C37,Sheet1!$G46:$G8928,Sheet3!E$3)/3/2/IF(RIGHT(TRIM(Sheet3!$C37),3)="250",250, IF(RIGHT(TRIM(Sheet3!$C37),2)="02",180,1)) -> 0 | F37: =SUMIFS(Sheet1!$O46:$O8928,Sheet1!$K46:$K8928,Sheet3!$C37,Sheet1!$G46:$G8928,Sheet3!F$3)/3/2/IF(RIGHT(TRIM(Sheet3!$C37),3)="250",250, IF(RIGHT(TRIM(Sheet3!$C37),2)="02",180,1)) -> 0 | G37: =SUMIFS(Sheet1!$O46:$O8928,Sheet1!$K46:$K8928,Sheet3!$C37,Sheet1!$G46:$G8928,Sheet3!G$3)/3/2/IF(RIGHT(TRIM(Sheet3!$C37),3)="250",250, IF(RIGHT(TRIM(Sheet3!$C37),2)="02",180,1)) -> 0 | H37: =SUMIFS(Sheet1!$O46:$O8928,Sheet1!$K46:$K8928,Sheet3!$C37,Sheet1!$G46:$G8928,Sheet3!H$3)/3/2/IF(RIGHT(TRIM(Sheet3!$C37),3)="250",250, IF(RIGHT(TRIM(Sheet3!$C37),2)="02",180,1)) -> 0 | I37: =SUMIFS(Sheet1!$O46:$O8928,Sheet1!$K46:$K8928,Sheet3!$C37,Sheet1!$G46:$G8928,Sheet3!I$3)/3/2/IF(RIGHT(TRIM(Sheet3!$C37),3)="250",250, IF(RIGHT(TRIM(Sheet3!$C37),2)="02",180,1)) -> 0.83333333 | J37: =SUMIFS(Sheet1!$O46:$O8928,Sheet1!$K46:$K8928,Sheet3!$C37,Sheet1!$G46:$G8928,Sheet3!J$3)/3/2/IF(RIGHT(TRIM(Sheet3!$C37),3)="250",250, IF(RIGHT(TRIM(Sheet3!$C37),2)="02",180,1)) -> 0.16666667 | K37: =SUMIFS(Sheet1!$O46:$O8928,Sheet1!$K46:$K8928,Sheet3!$C37,Sheet1!$G46:$G8928,Sheet3!K$3)/3/2/IF(RIGHT(TRIM(Sheet3!$C37),3)="250",250, IF(RIGHT(TRIM(Sheet3!$C37),2)="02",180,1)) -> 1.5 | ... O37: =SUMIFS(Sheet1!$O46:$O8928,Sheet1!$K46:$K8928,Sheet3!$C37,Sheet1!$G46:$G8928,Sheet3!O$3)/3/2/IF(RIGHT(TRIM(Sheet3!$C37),3)="250",250, IF(RIGHT(TRIM(Sheet3!$C37),2)="02",180,1)) -> 2.4
C38: ZON1836250 new | D38: =D37 + (D36*180/250) -> 2.46 | E38: =E37 + (E36*180/250) -> 0.96 | F38: =F37 + (F36*180/250) -> 0.43 | G38: =G37 + (G36*180/250) -> 0.92666667 | H38: =H37 + (H36*180/250) -> 2.0733333 | I38: =I37 + (I36*180/250) -> 2.465 | J38: =J37 + (J36*180/250) -> 0.86333333 | K38: =K37 + (K36*180/250) -> 1.8166667 | ... O38: =O37 + (O36*180/250) -> 2.4933333
C39: Nutrient Biofilter
