Workbook

Sheet New Yearly Report
C1: Year | D1: 14 | E1: =D1+1 -> 15 | F1: =E1+1 -> 16 | G1: =F1+1 -> 17 | H1: =G1+1 -> 18 | I1: =H1+1 -> 19 | J1: =I1+1 -> 20 | K1: =J1+1 -> 21 | L1: =K1+1 -> 22 | M1: =L1+1 -> 23
B3: Chemical Dynamics Yearly Product Usage - July to June
B4: As of 6/30/23
D5: 2014 | E5: =D5+1 -> 2015 | F5: =E5+1 -> 2016 | G5: =F5+1 -> 2017 | H5: =G5+1 -> 2018 | I5: =H5+1 -> 2019 | J5: =I5+1 -> 2020 | K5: =J5+1 -> 2021 | L5: =K5+1 -> 2022 | M5: =L5+1 -> 2023
B6: NPK11370 | C6: 11-37-0 | D6: =SUMIFS('FY13-23 Full Data'!$AL5:$FA5,'FY13-23 Full Data'!$AL$2:$FA$2,'New Yearly Report'!D$1) -> 92659.07 | E6: =SUMIFS('FY13-23 Full Data'!$AL5:$FA5,'FY13-23 Full Data'!$AL$2:$FA$2,'New Yearly Report'!E$1) -> 76904.31 | F6: =SUMIFS('FY13-23 Full Data'!$AL5:$FA5,'FY13-23 Full Data'!$AL$2:$FA$2,'New Yearly Report'!F$1) -> 158327.97 | G6: =SUMIFS('FY13-23 Full Data'!$AL5:$FA5,'FY13-23 Full Data'!$AL$2:$FA$2,'New Yearly Report'!G$1) -> 389019.68 | H6: =SUMIFS('FY13-23 Full Data'!$AL5:$FA5,'FY13-23 Full Data'!$AL$2:$FA$2,'New Yearly Report'!H$1) -> 401495.13 | I6: =SUMIFS('FY13-23 Full Data'!$AL5:$FA5,'FY13-23 Full Data'!$AL$2:$FA$2,'New Yearly Report'!I$1) -> 104796.49 | J6: =SUMIFS('FY13-23 Full Data'!$AL5:$FA5,'FY13-23 Full Data'!$AL$2:$FA$2,'New Yearly Report'!J$1) -> 284376.41 | K6: =SUMIFS('FY13-23 Full Data'!$AL5:$FA5,'FY13-23 Full Data'!$AL$2:$FA$2,'New Yearly Report'!K$1) -> 666211.04 | ... M6: =SUMIFS('FY13-23 Full Data'!$AL5:$FA5,'FY13-23 Full Data'!$AL$2:$FA$2,'New Yearly Report'!M$1) -> 461843
B7: NPKAQUA | C7: AQUA AMMONIA | D7: =SUMIFS('FY13-23 Full Data'!$AL6:$FA6,'FY13-23 Full Data'!$AL$2:$FA$2,'New Yearly Report'!D$1) -> 72576.909 | E7: =SUMIFS('FY13-23 Full Data'!$AL6:$FA6,'FY13-23 Full Data'!$AL$2:$FA$2,'New Yearly Report'!E$1) -> 55592.803 | F7: =SUMIFS('FY13-23 Full Data'!$AL6:$FA6,'FY13-23 Full Data'!$AL$2:$FA$2,'New Yearly Report'!F$1) -> 91074.046 | G7: =SUMIFS('FY13-23 Full Data'!$AL6:$FA6,'FY13-23 Full Data'!$AL$2:$FA$2,'New Yearly Report'!G$1) -> 67881.405 | H7: =SUMIFS('FY13-23 Full Data'!$AL6:$FA6,'FY13-23 Full Data'!$AL$2:$FA$2,'New Yearly Report'!H$1) -> 75611.445 | I7: =SUMIFS('FY13-23 Full Data'!$AL6:$FA6,'FY13-23 Full Data'!$AL$2:$FA$2,'New Yearly Report'!I$1) -> 35883.305 | J7: =SUMIFS('FY13-23 Full Data'!$AL6:$FA6,'FY13-23 Full Data'!$AL$2:$FA$2,'New Yearly Report'!J$1) -> 53816.6 | K7: =SUMIFS('FY13-23 Full Data'!$AL6:$FA6,'FY13-23 Full Data'!$AL$2:$FA$2,'New Yearly Report'!K$1) -> 97235.371 | ... M7: =SUMIFS('FY13-23 Full Data'!$AL6:$FA6,'FY13-23 Full Data'!$AL$2:$FA$2,'New Yearly Report'!M$1) -> 54206
B8: SO4BORIC | C8: BORIC ACID | D8: =SUMIFS('FY13-23 Full Data'!$AL7:$FA7,'FY13-23 Full Data'!$AL$2:$FA$2,'New Yearly Report'!D$1) -> -1836.1303 | E8: =SUMIFS('FY13-23 Full Data'!$AL7:$FA7,'FY13-23 Full Data'!$AL$2:$FA$2,'New Yearly Report'!E$1) -> 171724.24 | F8: =SUMIFS('FY13-23 Full Data'!$AL7:$FA7,'FY13-23 Full Data'!$AL$2:$FA$2,'New Yearly Report'!F$1) -> 139590.68 | G8: =SUMIFS('FY13-23 Full Data'!$AL7:$FA7,'FY13-23 Full Data'!$AL$2:$FA$2,'New Yearly Report'!G$1) -> 170758.86 | H8: =SUMIFS('FY13-23 Full Data'!$AL7:$FA7,'FY13-23 Full Data'!$AL$2:$FA$2,'New Yearly Report'!H$1) -> 250223.67 | I8: =SUMIFS('FY13-23 Full Data'!$AL7:$FA7,'FY13-23 Full Data'!$AL$2:$FA$2,'New Yearly Report'!I$1) -> 331849.18 | J8: =SUMIFS('FY13-23 Full Data'!$AL7:$FA7,'FY13-23 Full Data'!$AL$2:$FA$2,'New Yearly Report'!J$1) -> 360876.67 | K8: =SUMIFS('FY13-23 Full Data'!$AL7:$FA7,'FY13-23 Full Data'!$AL$2:$FA$2,'New Yearly Report'!K$1) -> 401241.39 | ... M8: =SUMIFS('FY13-23 Full Data'!$AL7:$FA7,'FY13-23 Full Data'!$AL$2:$FA$2,'New Yearly Report'!M$1) -> 239360
B9: SO4BORON | C9: BORON | D9: =SUMIFS('FY13-23 Full Data'!$AL8:$FA8,'FY13-23 Full Data'!$AL$2:$FA$2,'New Yearly Report'!D$1) -> 86042.359 | E9: =SUMIFS('FY13-23 Full Data'!$AL8:$FA8,'FY13-23 Full Data'!$AL$2:$FA$2,'New Yearly Report'!E$1) -> 61987.828 | F9: =SUMIFS('FY13-23 Full Data'!$AL8:$FA8,'FY13-23 Full Data'!$AL$2:$FA$2,'New Yearly Report'!F$1) -> 72184.506 | G9: =SUMIFS('FY13-23 Full Data'!$AL8:$FA8,'FY13-23 Full Data'!$AL$2:$FA$2,'New Yearly Report'!G$1) -> 66974.604 | H9: =SUMIFS('FY13-23 Full Data'!$AL8:$FA8,'FY13-23 Full Data'!$AL$2:$FA$2,'New Yearly Report'!H$1) -> 55696.43 | I9: =SUMIFS('FY13-23 Full Data'!$AL8:$FA8,'FY13-23 Full Data'!$AL$2:$FA$2,'New Yearly Report'!I$1) -> 58330.507 | J9: =SUMIFS('FY13-23 Full Data'!$AL8:$FA8,'FY13-23 Full Data'!$AL$2:$FA$2,'New Yearly Report'!J$1) -> 49117.988 | K9: =SUMIFS('FY13-23 Full Data'!$AL8:$FA8,'FY13-23 Full Data'!$AL$2:$FA$2,'New Yearly Report'!K$1) -> 53263.927 | ... M9: =SUMIFS('FY13-23 Full Data'!$AL8:$FA8,'FY13-23 Full Data'!$AL$2:$FA$2,'New Yearly Report'!M$1) -> 41476
B10: NO3CA | C10: CALCIUM NITRATE | D10: =SUMIFS('FY13-23 Full Data'!$AL9:$FA9,'FY13-23 Full Data'!$AL$2:$FA$2,'New Yearly Report'!D$1) -> 4919733.8 | E10: =SUMIFS('FY13-23 Full Data'!$AL9:$FA9,'FY13-23 Full Data'!$AL$2:$FA$2,'New Yearly Report'!E$1) -> 3613483.2 | F10: =SUMIFS('FY13-23 Full Data'!$AL9:$FA9,'FY13-23 Full Data'!$AL$2:$FA$2,'New Yearly Report'!F$1) -> 4048321.5 | G10: =SUMIFS('FY13-23 Full Data'!$AL9:$FA9,'FY13-23 Full Data'!$AL$2:$FA$2,'New Yearly Report'!G$1) -> 3389966.9 | H10: =SUMIFS('FY13-23 Full Data'!$AL9:$FA9,'FY13-23 Full Data'!$AL$2:$FA$2,'New Yearly Report'!H$1) -> 3335058.6 | I10: =SUMIFS('FY13-23 Full Data'!$AL9:$FA9,'FY13-23 Full Data'!$AL$2:$FA$2,'New Yearly Report'!I$1) -> 3369745.1 | J10: =SUMIFS('FY13-23 Full Data'!$AL9:$FA9,'FY13-23 Full Data'!$AL$2:$FA$2,'New Yearly Report'!J$1) -> 3656716.6 | K10: =SUMIFS('FY13-23 Full Data'!$AL9:$FA9,'FY13-23 Full Data'!$AL$2:$FA$2,'New Yearly Report'!K$1) -> 3623596.9 | ... M10: =SUMIFS('FY13-23 Full Data'!$AL9:$FA9,'FY13-23 Full Data'!$AL$2:$FA$2,'New Yearly Report'!M$1) -> 2766928
B11: CHECITRIC | C11: CITRIC ACID | D11: =SUMIFS('FY13-23 Full Data'!$AL10:$FA10,'FY13-23 Full Data'!$AL$2:$FA$2,'New Yearly Report'!D$1) -> 144570.62 | E11: =SUMIFS('FY13-23 Full Data'!$AL10:$FA10,'FY13-23 Full Data'!$AL$2:$FA$2,'New Yearly Report'!E$1) -> 92405.868 | F11: =SUMIFS('FY13-23 Full Data'!$AL10:$FA10,'FY13-23 Full Data'!$AL$2:$FA$2,'New Yearly Report'!F$1) -> 97399.913 | G11: =SUMIFS('FY13-23 Full Data'!$AL10:$FA10,'FY13-23 Full Data'!$AL$2:$FA$2,'New Yearly Report'!G$1) -> 71268.473 | H11: =SUMIFS('FY13-23 Full Data'!$AL10:$FA10,'FY13-23 Full Data'!$AL$2:$FA$2,'New Yearly Report'!H$1) -> 73235.148 | I11: =SUMIFS('FY13-23 Full Data'!$AL10:$FA10,'FY13-23 Full Data'!$AL$2:$FA$2,'New Yearly Report'!I$1) -> 56695.769 | J11: =SUMIFS('FY13-23 Full Data'!$AL10:$FA10,'FY13-23 Full Data'!$AL$2:$FA$2,'New Yearly Report'!J$1) -> 61914.664 | K11: =SUMIFS('FY13-23 Full Data'!$AL10:$FA10,'FY13-23 Full Data'!$AL$2:$FA$2,'New Yearly Report'!K$1) -> 67297.112 | ... M11: =SUMIFS('FY13-23 Full Data'!$AL10:$FA10,'FY13-23 Full Data'!$AL$2:$FA$2,'New Yearly Report'!M$1) -> 75863
B12: CHEGLUCO | C12: GLUCOHEPTONATE | D12: =SUMIFS('FY13-23 Full Data'!$AL11:$FA11,'FY13-23 Full Data'!$AL$2:$FA$2,'New Yearly Report'!D$1) -> 916025.43 | E12: =SUMIFS('FY13-23 Full Data'!$AL11:$FA11,'FY13-23 Full Data'!$AL$2:$FA$2,'New Yearly Report'!E$1) -> 798708.94 | F12: =SUMIFS('FY13-23 Full Data'!$AL11:$FA11,'FY13-23 Full Data'!$AL$2:$FA$2,'New Yearly Report'!F$1) -> 922684.74 | G12: =SUMIFS('FY13-23 Full Data'!$AL11:$FA11,'FY13-23 Full Data'!$AL$2:$FA$2,'New Yearly Report'!G$1) -> 695460.94 | H12: =SUMIFS('FY13-23 Full Data'!$AL11:$FA11,'FY13-23 Full Data'!$AL$2:$FA$2,'New Yearly Report'!H$1) -> 611506.48 | I12: =SUMIFS('FY13-23 Full Data'!$AL11:$FA11,'FY13-23 Full Data'!$AL$2:$FA$2,'New Yearly Report'!I$1) -> 613724.47 | J12: =SUMIFS('FY13-23 Full Data'!$AL11:$FA11,'FY13-23 Full Data'!$AL$2:$FA$2,'New Yearly Report'!J$1) -> 622751.95 | K12: =SUMIFS('FY13-23 Full Data'!$AL11:$FA11,'FY13-23 Full Data'!$AL$2:$FA$2,'New Yearly Report'!K$1) -> 607638.8 | ... M12: =SUMIFS('FY13-23 Full Data'!$AL11:$FA11,'FY13-23 Full Data'!$AL$2:$FA$2,'New Yearly Report'!M$1) -> 374581
B13: GRPHUMICLIQ | C13: HUMIC ACID LIQUID | D13: =SUMIFS('FY13-23 Full Data'!$AL12:$FA12,'FY13-23 Full Data'!$AL$2:$FA$2,'New Yearly Report'!D$1) -> 78690.422 | E13: =SUMIFS('FY13-23 Full Data'!$AL12:$FA12,'FY13-23 Full Data'!$AL$2:$FA$2,'New Yearly Report'!E$1) -> 73053.069 | F13: =SUMIFS('FY13-23 Full Data'!$AL12:$FA12,'FY13-23 Full Data'!$AL$2:$FA$2,'New Yearly Report'!F$1) -> 63238.138 | G13: =SUMIFS('FY13-23 Full Data'!$AL12:$FA12,'FY13-23 Full Data'!$AL$2:$FA$2,'New Yearly Report'!G$1) -> 65990.958 | H13: =SUMIFS('FY13-23 Full Data'!$AL12:$FA12,'FY13-23 Full Data'!$AL$2:$FA$2,'New Yearly Report'!H$1) -> 73648.773 | I13: =SUMIFS('FY13-23 Full Data'!$AL12:$FA12,'FY13-23 Full Data'!$AL$2:$FA$2,'New Yearly Report'!I$1) -> 64264.667 | J13: =SUMIFS('FY13-23 Full Data'!$AL12:$FA12,'FY13-23 Full Data'!$AL$2:$FA$2,'New Yearly Report'!J$1) -> 107106.4 | K13: =SUMIFS('FY13-23 Full Data'!$AL12:$FA12,'FY13-23 Full Data'!$AL$2:$FA$2,'New Yearly Report'!K$1) -> 100012.14 | ... M13: =SUMIFS('FY13-23 Full Data'!$AL12:$FA12,'FY13-23 Full Data'!$AL$2:$FA$2,'New Yearly Report'!M$1) -> 63198
B14: NO3FE | C14: IRON NITRATE 10% | D14: =SUMIFS('FY13-23 Full Data'!$AL13:$FA13,'FY13-23 Full Data'!$AL$2:$FA$2,'New Yearly Report'!D$1) -> 140803.43 | E14: =SUMIFS('FY13-23 Full Data'!$AL13:$FA13,'FY13-23 Full Data'!$AL$2:$FA$2,'New Yearly Report'!E$1) -> 152812.47 | F14: =SUMIFS('FY13-23 Full Data'!$AL13:$FA13,'FY13-23 Full Data'!$AL$2:$FA$2,'New Yearly Report'!F$1) -> 270266.22 | G14: =SUMIFS('FY13-23 Full Data'!$AL13:$FA13,'FY13-23 Full Data'!$AL$2:$FA$2,'New Yearly Report'!G$1) -> 893375.4 | H14: =SUMIFS('FY13-23 Full Data'!$AL13:$FA13,'FY13-23 Full Data'!$AL$2:$FA$2,'New Yearly Report'!H$1) -> 1289363.9 | I14: =SUMIFS('FY13-23 Full Data'!$AL13:$FA13,'FY13-23 Full Data'!$AL$2:$FA$2,'New Yearly Report'!I$1) -> 1295287.8 | J14: =SUMIFS('FY13-23 Full Data'!$AL13:$FA13,'FY13-23 Full Data'!$AL$2:$FA$2,'New Yearly Report'!J$1) -> 923762.25 | K14: =SUMIFS('FY13-23 Full Data'!$AL13:$FA13,'FY13-23 Full Data'!$AL$2:$FA$2,'New Yearly Report'!K$1) -> 751025.14 | ... M14: =SUMIFS('FY13-23 Full Data'!$AL13:$FA13,'FY13-23 Full Data'!$AL$2:$FA$2,'New Yearly Report'!M$1) -> 303942
B15: SO4FEDRY19 | C15: IRON SULPHATE (Dry) | D15: =SUMIFS('FY13-23 Full Data'!$AL14:$FA14,'FY13-23 Full Data'!$AL$2:$FA$2,'New Yearly Report'!D$1) -> 153995.56 | E15: =SUMIFS('FY13-23 Full Data'!$AL14:$FA14,'FY13-23 Full Data'!$AL$2:$FA$2,'New Yearly Report'!E$1) -> 113241.2 | F15: =SUMIFS('FY13-23 Full Data'!$AL14:$FA14,'FY13-23 Full Data'!$AL$2:$FA$2,'New Yearly Report'!F$1) -> 109280.95 | G15: =SUMIFS('FY13-23 Full Data'!$AL14:$FA14,'FY13-23 Full Data'!$AL$2:$FA$2,'New Yearly Report'!G$1) -> 67219.379 | H15: =SUMIFS('FY13-23 Full Data'!$AL14:$FA14,'FY13-23 Full Data'!$AL$2:$FA$2,'New Yearly Report'!H$1) -> 84817.651 | I15: =SUMIFS('FY13-23 Full Data'!$AL14:$FA14,'FY13-23 Full Data'!$AL$2:$FA$2,'New Yearly Report'!I$1) -> 81711.578 | J15: =SUMIFS('FY13-23 Full Data'!$AL14:$FA14,'FY13-23 Full Data'!$AL$2:$FA$2,'New Yearly Report'!J$1) -> 64167.182 | K15: =SUMIFS('FY13-23 Full Data'!$AL14:$FA14,'FY13-23 Full Data'!$AL$2:$FA$2,'New Yearly Report'!K$1) -> 76271.903 | ... M15: =SUMIFS('FY13-23 Full Data'!$AL14:$FA14,'FY13-23 Full Data'!$AL$2:$FA$2,'New Yearly Report'!M$1) -> 57229
B16: NPKKOHDRY | C16: KOH DRY | D16: =SUMIFS('FY13-23 Full Data'!$AL15:$FA15,'FY13-23 Full Data'!$AL$2:$FA$2,'New Yearly Report'!D$1) -> 368107.67 | E16: =SUMIFS('FY13-23 Full Data'!$AL15:$FA15,'FY13-23 Full Data'!$AL$2:$FA$2,'New Yearly Report'!E$1) -> 177681.86 | F16: =SUMIFS('FY13-23 Full Data'!$AL15:$FA15,'FY13-23 Full Data'!$AL$2:$FA$2,'New Yearly Report'!F$1) -> 239878.24 | G16: =SUMIFS('FY13-23 Full Data'!$AL15:$FA15,'FY13-23 Full Data'!$AL$2:$FA$2,'New Yearly Report'!G$1) -> 207666.41 | H16: =SUMIFS('FY13-23 Full Data'!$AL15:$FA15,'FY13-23 Full Data'!$AL$2:$FA$2,'New Yearly Report'!H$1) -> 138131.51 | I16: =SUMIFS('FY13-23 Full Data'!$AL15:$FA15,'FY13-23 Full Data'!$AL$2:$FA$2,'New Yearly Report'!I$1) -> 96395.552 | J16: =SUMIFS('FY13-23 Full Data'!$AL15:$FA15,'FY13-23 Full Data'!$AL$2:$FA$2,'New Yearly Report'!J$1) -> 49723.795 | K16: =SUMIFS('FY13-23 Full Data'!$AL15:$FA15,'FY13-23 Full Data'!$AL$2:$FA$2,'New Yearly Report'!K$1) -> 139534.91 | ... M16: =SUMIFS('FY13-23 Full Data'!$AL15:$FA15,'FY13-23 Full Data'!$AL$2:$FA$2,'New Yearly Report'!M$1) -> 127497
B17: NPKKOHLIQ | C17: KOH LIQUID 45% | D17: =SUMIFS('FY13-23 Full Data'!$AL16:$FA16,'FY13-23 Full Data'!$AL$2:$FA$2,'New Yearly Report'!D$1) -> 764206.71 | E17: =SUMIFS('FY13-23 Full Data'!$AL16:$FA16,'FY13-23 Full Data'!$AL$2:$FA$2,'New Yearly Report'!E$1) -> 26682.032 | F17: =SUMIFS('FY13-23 Full Data'!$AL16:$FA16,'FY13-23 Full Data'!$AL$2:$FA$2,'New Yearly Report'!F$1) -> 17138.503 | G17: =SUMIFS('FY13-23 Full Data'!$AL16:$FA16,'FY13-23 Full Data'!$AL$2:$FA$2,'New Yearly Report'!G$1) -> -646.8432 | H17: =SUMIFS('FY13-23 Full Data'!$AL16:$FA16,'FY13-23 Full Data'!$AL$2:$FA$2,'New Yearly Report'!H$1) -> 940.67835 | I17: =SUMIFS('FY13-23 Full Data'!$AL16:$FA16,'FY13-23 Full Data'!$AL$2:$FA$2,'New Yearly Report'!I$1) -> 79.94255 | J17: =SUMIFS('FY13-23 Full Data'!$AL16:$FA16,'FY13-23 Full Data'!$AL$2:$FA$2,'New Yearly Report'!J$1) -> -971.8914 | K17: =SUMIFS('FY13-23 Full Data'!$AL16:$FA16,'FY13-23 Full Data'!$AL$2:$FA$2,'New Yearly Report'!K$1) -> 2190.0294 | ... M17: =SUMIFS('FY13-23 Full Data'!$AL16:$FA16,'FY13-23 Full Data'!$AL$2:$FA$2,'New Yearly Report'!M$1) -> 0
... B37: SO4CU | C37: COPPER SULPHATE 25.2% | D37: =SUMIFS('FY13-23 Full Data'!$AL36:$FA36,'FY13-23 Full Data'!$AL$2:$FA$2,'New Yearly Report'!D$1) -> 0 | E37: =SUMIFS('FY13-23 Full Data'!$AL36:$FA36,'FY13-23 Full Data'!$AL$2:$FA$2,'New Yearly Report'!E$1) -> 0 | F37: =SUMIFS('FY13-23 Full Data'!$AL36:$FA36,'FY13-23 Full Data'!$AL$2:$FA$2,'New Yearly Report'!F$1) -> 0 | G37: =SUMIFS('FY13-23 Full Data'!$AL36:$FA36,'FY13-23 Full Data'!$AL$2:$FA$2,'New Yearly Report'!G$1) -> 0 | H37: =SUMIFS('FY13-23 Full Data'!$AL36:$FA36,'FY13-23 Full Data'!$AL$2:$FA$2,'New Yearly Report'!H$1) -> 0 | I37: =SUMIFS('FY13-23 Full Data'!$AL36:$FA36,'FY13-23 Full Data'!$AL$2:$FA$2,'New Yearly Report'!I$1) -> 0 | J37: =SUMIFS('FY13-23 Full Data'!$AL36:$FA36,'FY13-23 Full Data'!$AL$2:$FA$2,'New Yearly Report'!J$1) -> 0 | K37: =SUMIFS('FY13-23 Full Data'!$AL36:$FA36,'FY13-23 Full Data'!$AL$2:$FA$2,'New Yearly Report'!K$1) -> 0 | ... M37: =SUMIFS('FY13-23 Full Data'!$AL36:$FA36,'FY13-23 Full Data'!$AL$2:$FA$2,'New Yearly Report'!M$1) -> 15168

Sheet New Quarterly Report
C1: Year | D1: 14 | E1: =D1 -> 14 | F1: =E1 -> 14 | G1: =F1 -> 14 | H1: =D1+1 -> 15 | I1: =E1+1 -> 15 | J1: =F1+1 -> 15 | K1: =G1+1 -> 15 | L1: =H1+1 -> 16 | M1: =I1+1 -> 16 | N1: =J1+1 -> 16 | O1: =K1+1 -> 16 | ... AQ1: =AM1+1 -> 23
C2: Quarter | D2: 1 | E2: =D2+1 -> 2 | F2: =E2+1 -> 3 | G2: =F2+1 -> 4 | H2: =D2 -> 1 | I2: =E2 -> 2 | J2: =F2 -> 3 | K2: =G2 -> 4 | L2: =H2 -> 1 | M2: =I2 -> 2 | N2: =J2 -> 3 | O2: =K2 -> 4 | ... AQ2: =AM2 -> 4
B4: Chemical Dynamics Quarterly Product Usage
B5: As of 6/30/23
D6: 2014 | H6: =D6+1 -> 2015 | L6: =H6+1 -> 2016 | P6: =L6+1 -> 2017 | T6: =P6+1 -> 2018 | X6: =T6+1 -> 2019 | AB6: =X6+1 -> 2020 | AF6: =AB6+1 -> 2021 | AJ6: =AF6+1 -> 2022 | AN6: =AJ6+1 -> 2023
D7: Jul-Sep | E7: Oct-Dec | F7: Jan-Mar | G7: Apr-Jun | H7: Jul-Sep | I7: Oct-Dec | J7: Jan-Mar | K7: Apr-Jun | L7: Jul-Sep | M7: Oct-Dec | N7: Jan-Mar | O7: Apr-Jun | P7: Jul-Sep | Q7: Oct-Dec | R7: Jan-Mar | S7: Apr-Jun | T7: Jul-Sep | U7: Oct-Dec | V7: Jan-Mar | W7: Apr-Jun | X7: Jul-Sep | Y7: Oct-Dec | Z7: Jan-Mar | AA7: Apr-Jun | AB7: Jul-Sep | AC7: Oct-Dec | AD7: Jan-Mar | AE7: Apr-Jun | AF7: Jul-Sep | AG7: Oct-Dec | AH7: Jan-Mar | AI7: Apr-Jun | AJ7: Jul-Sep | AK7: Oct-Dec | AL7: Jan-Mar | AM7: Apr-Jun | AN7: Jul-Sep | AO7: Oct-Dec | AP7: Jan-Mar | AQ7: Apr-Jun
B8: NPK11370 | C8: 11-37-0 | D8: =SUMIFS('FY13-23 Full Data'!$AL5:$FA5,'FY13-23 Full Data'!$AL$2:$FA$2,'New Quarterly Report'!D$1,'FY13-23 Full Data'!$AL$3:$FA$3,'New Quarterly Report'!D$2) -> 24890 | E8: =SUMIFS('FY13-23 Full Data'!$AL5:$FA5,'FY13-23 Full Data'!$AL$2:$FA$2,'New Quarterly Report'!E$1,'FY13-23 Full Data'!$AL$3:$FA$3,'New Quarterly Report'!E$2) -> 13911.1 | F8: =SUMIFS('FY13-23 Full Data'!$AL5:$FA5,'FY13-23 Full Data'!$AL$2:$FA$2,'New Quarterly Report'!F$1,'FY13-23 Full Data'!$AL$3:$FA$3,'New Quarterly Report'!F$2) -> 44404.404 | G8: =SUMIFS('FY13-23 Full Data'!$AL5:$FA5,'FY13-23 Full Data'!$AL$2:$FA$2,'New Quarterly Report'!G$1,'FY13-23 Full Data'!$AL$3:$FA$3,'New Quarterly Report'!G$2) -> 9453.5659 | H8: =SUMIFS('FY13-23 Full Data'!$AL5:$FA5,'FY13-23 Full Data'!$AL$2:$FA$2,'New Quarterly Report'!H$1,'FY13-23 Full Data'!$AL$3:$FA$3,'New Quarterly Report'!H$2) -> 9511.5134 | I8: =SUMIFS('FY13-23 Full Data'!$AL5:$FA5,'FY13-23 Full Data'!$AL$2:$FA$2,'New Quarterly Report'!I$1,'FY13-23 Full Data'!$AL$3:$FA$3,'New Quarterly Report'!I$2) -> 16040.223 | J8: =SUMIFS('FY13-23 Full Data'!$AL5:$FA5,'FY13-23 Full Data'!$AL$2:$FA$2,'New Quarterly Report'!J$1,'FY13-23 Full Data'!$AL$3:$FA$3,'New Quarterly Report'!J$2) -> 40039.224 | K8: =SUMIFS('FY13-23 Full Data'!$AL5:$FA5,'FY13-23 Full Data'!$AL$2:$FA$2,'New Quarterly Report'!K$1,'FY13-23 Full Data'!$AL$3:$FA$3,'New Quarterly Report'!K$2) -> 11313.349 | ... AQ8: =SUMIFS('FY13-23 Full Data'!$AL5:$FA5,'FY13-23 Full Data'!$AL$2:$FA$2,'New Quarterly Report'!AQ$1,'FY13-23 Full Data'!$AL$3:$FA$3,'New Quarterly Report'!AQ$2) -> 106413
B9: NPKAQUA | C9: AQUA AMMONIA | D9: =SUMIFS('FY13-23 Full Data'!$AL6:$FA6,'FY13-23 Full Data'!$AL$2:$FA$2,'New Quarterly Report'!D$1,'FY13-23 Full Data'!$AL$3:$FA$3,'New Quarterly Report'!D$2) -> 4024 | E9: =SUMIFS('FY13-23 Full Data'!$AL6:$FA6,'FY13-23 Full Data'!$AL$2:$FA$2,'New Quarterly Report'!E$1,'FY13-23 Full Data'!$AL$3:$FA$3,'New Quarterly Report'!E$2) -> 701.763 | F9: =SUMIFS('FY13-23 Full Data'!$AL6:$FA6,'FY13-23 Full Data'!$AL$2:$FA$2,'New Quarterly Report'!F$1,'FY13-23 Full Data'!$AL$3:$FA$3,'New Quarterly Report'!F$2) -> 59282.365 | G9: =SUMIFS('FY13-23 Full Data'!$AL6:$FA6,'FY13-23 Full Data'!$AL$2:$FA$2,'New Quarterly Report'!G$1,'FY13-23 Full Data'!$AL$3:$FA$3,'New Quarterly Report'!G$2) -> 8568.7813 | H9: =SUMIFS('FY13-23 Full Data'!$AL6:$FA6,'FY13-23 Full Data'!$AL$2:$FA$2,'New Quarterly Report'!H$1,'FY13-23 Full Data'!$AL$3:$FA$3,'New Quarterly Report'!H$2) -> 733.8807 | I9: =SUMIFS('FY13-23 Full Data'!$AL6:$FA6,'FY13-23 Full Data'!$AL$2:$FA$2,'New Quarterly Report'!I$1,'FY13-23 Full Data'!$AL$3:$FA$3,'New Quarterly Report'!I$2) -> 1020.82 | J9: =SUMIFS('FY13-23 Full Data'!$AL6:$FA6,'FY13-23 Full Data'!$AL$2:$FA$2,'New Quarterly Report'!J$1,'FY13-23 Full Data'!$AL$3:$FA$3,'New Quarterly Report'!J$2) -> 50572.701 | K9: =SUMIFS('FY13-23 Full Data'!$AL6:$FA6,'FY13-23 Full Data'!$AL$2:$FA$2,'New Quarterly Report'!K$1,'FY13-23 Full Data'!$AL$3:$FA$3,'New Quarterly Report'!K$2) -> 3265.4012 | ... AQ9: =SUMIFS('FY13-23 Full Data'!$AL6:$FA6,'FY13-23 Full Data'!$AL$2:$FA$2,'New Quarterly Report'!AQ$1,'FY13-23 Full Data'!$AL$3:$FA$3,'New Quarterly Report'!AQ$2) -> 6980
B10: SO4BORIC | C10: BORIC ACID | D10: =SUMIFS('FY13-23 Full Data'!$AL7:$FA7,'FY13-23 Full Data'!$AL$2:$FA$2,'New Quarterly Report'!D$1,'FY13-23 Full Data'!$AL$3:$FA$3,'New Quarterly Report'!D$2) -> -53281 | E10: =SUMIFS('FY13-23 Full Data'!$AL7:$FA7,'FY13-23 Full Data'!$AL$2:$FA$2,'New Quarterly Report'!E$1,'FY13-23 Full Data'!$AL$3:$FA$3,'New Quarterly Report'!E$2) -> -3291.796 | F10: =SUMIFS('FY13-23 Full Data'!$AL7:$FA7,'FY13-23 Full Data'!$AL$2:$FA$2,'New Quarterly Report'!F$1,'FY13-23 Full Data'!$AL$3:$FA$3,'New Quarterly Report'!F$2) -> 1807.9804 | G10: =SUMIFS('FY13-23 Full Data'!$AL7:$FA7,'FY13-23 Full Data'!$AL$2:$FA$2,'New Quarterly Report'!G$1,'FY13-23 Full Data'!$AL$3:$FA$3,'New Quarterly Report'!G$2) -> 52928.685 | H10: =SUMIFS('FY13-23 Full Data'!$AL7:$FA7,'FY13-23 Full Data'!$AL$2:$FA$2,'New Quarterly Report'!H$1,'FY13-23 Full Data'!$AL$3:$FA$3,'New Quarterly Report'!H$2) -> 69041.897 | I10: =SUMIFS('FY13-23 Full Data'!$AL7:$FA7,'FY13-23 Full Data'!$AL$2:$FA$2,'New Quarterly Report'!I$1,'FY13-23 Full Data'!$AL$3:$FA$3,'New Quarterly Report'!I$2) -> 76.0064 | J10: =SUMIFS('FY13-23 Full Data'!$AL7:$FA7,'FY13-23 Full Data'!$AL$2:$FA$2,'New Quarterly Report'!J$1,'FY13-23 Full Data'!$AL$3:$FA$3,'New Quarterly Report'!J$2) -> 2570.8731 | K10: =SUMIFS('FY13-23 Full Data'!$AL7:$FA7,'FY13-23 Full Data'!$AL$2:$FA$2,'New Quarterly Report'!K$1,'FY13-23 Full Data'!$AL$3:$FA$3,'New Quarterly Report'!K$2) -> 100035.47 | ... AQ10: =SUMIFS('FY13-23 Full Data'!$AL7:$FA7,'FY13-23 Full Data'!$AL$2:$FA$2,'New Quarterly Report'!AQ$1,'FY13-23 Full Data'!$AL$3:$FA$3,'New Quarterly Report'!AQ$2) -> 125287
B11: SO4BORON | C11: BORON | D11: =SUMIFS('FY13-23 Full Data'!$AL8:$FA8,'FY13-23 Full Data'!$AL$2:$FA$2,'New Quarterly Report'!D$1,'FY13-23 Full Data'!$AL$3:$FA$3,'New Quarterly Report'!D$2) -> 5629 | E11: =SUMIFS('FY13-23 Full Data'!$AL8:$FA8,'FY13-23 Full Data'!$AL$2:$FA$2,'New Quarterly Report'!E$1,'FY13-23 Full Data'!$AL$3:$FA$3,'New Quarterly Report'!E$2) -> 16732.894 | F11: =SUMIFS('FY13-23 Full Data'!$AL8:$FA8,'FY13-23 Full Data'!$AL$2:$FA$2,'New Quarterly Report'!F$1,'FY13-23 Full Data'!$AL$3:$FA$3,'New Quarterly Report'!F$2) -> 38795.612 | G11: =SUMIFS('FY13-23 Full Data'!$AL8:$FA8,'FY13-23 Full Data'!$AL$2:$FA$2,'New Quarterly Report'!G$1,'FY13-23 Full Data'!$AL$3:$FA$3,'New Quarterly Report'!G$2) -> 24884.854 | H11: =SUMIFS('FY13-23 Full Data'!$AL8:$FA8,'FY13-23 Full Data'!$AL$2:$FA$2,'New Quarterly Report'!H$1,'FY13-23 Full Data'!$AL$3:$FA$3,'New Quarterly Report'!H$2) -> 5165.0771 | I11: =SUMIFS('FY13-23 Full Data'!$AL8:$FA8,'FY13-23 Full Data'!$AL$2:$FA$2,'New Quarterly Report'!I$1,'FY13-23 Full Data'!$AL$3:$FA$3,'New Quarterly Report'!I$2) -> 11175.389 | J11: =SUMIFS('FY13-23 Full Data'!$AL8:$FA8,'FY13-23 Full Data'!$AL$2:$FA$2,'New Quarterly Report'!J$1,'FY13-23 Full Data'!$AL$3:$FA$3,'New Quarterly Report'!J$2) -> 28137.746 | K11: =SUMIFS('FY13-23 Full Data'!$AL8:$FA8,'FY13-23 Full Data'!$AL$2:$FA$2,'New Quarterly Report'!K$1,'FY13-23 Full Data'!$AL$3:$FA$3,'New Quarterly Report'!K$2) -> 17509.617 | ... AQ11: =SUMIFS('FY13-23 Full Data'!$AL8:$FA8,'FY13-23 Full Data'!$AL$2:$FA$2,'New Quarterly Report'!AQ$1,'FY13-23 Full Data'!$AL$3:$FA$3,'New Quarterly Report'!AQ$2) -> 14068
B12: NO3CA | C12: CALCIUM NITRATE | D12: =SUMIFS('FY13-23 Full Data'!$AL9:$FA9,'FY13-23 Full Data'!$AL$2:$FA$2,'New Quarterly Report'!D$1,'FY13-23 Full Data'!$AL$3:$FA$3,'New Quarterly Report'!D$2) -> 149294 | E12: =SUMIFS('FY13-23 Full Data'!$AL9:$FA9,'FY13-23 Full Data'!$AL$2:$FA$2,'New Quarterly Report'!E$1,'FY13-23 Full Data'!$AL$3:$FA$3,'New Quarterly Report'!E$2) -> 2196845.5 | F12: =SUMIFS('FY13-23 Full Data'!$AL9:$FA9,'FY13-23 Full Data'!$AL$2:$FA$2,'New Quarterly Report'!F$1,'FY13-23 Full Data'!$AL$3:$FA$3,'New Quarterly Report'!F$2) -> 1884973.1 | G12: =SUMIFS('FY13-23 Full Data'!$AL9:$FA9,'FY13-23 Full Data'!$AL$2:$FA$2,'New Quarterly Report'!G$1,'FY13-23 Full Data'!$AL$3:$FA$3,'New Quarterly Report'!G$2) -> 688621.2 | H12: =SUMIFS('FY13-23 Full Data'!$AL9:$FA9,'FY13-23 Full Data'!$AL$2:$FA$2,'New Quarterly Report'!H$1,'FY13-23 Full Data'!$AL$3:$FA$3,'New Quarterly Report'!H$2) -> 181107.21 | I12: =SUMIFS('FY13-23 Full Data'!$AL9:$FA9,'FY13-23 Full Data'!$AL$2:$FA$2,'New Quarterly Report'!I$1,'FY13-23 Full Data'!$AL$3:$FA$3,'New Quarterly Report'!I$2) -> 1562763.5 | J12: =SUMIFS('FY13-23 Full Data'!$AL9:$FA9,'FY13-23 Full Data'!$AL$2:$FA$2,'New Quarterly Report'!J$1,'FY13-23 Full Data'!$AL$3:$FA$3,'New Quarterly Report'!J$2) -> 1248943 | K12: =SUMIFS('FY13-23 Full Data'!$AL9:$FA9,'FY13-23 Full Data'!$AL$2:$FA$2,'New Quarterly Report'!K$1,'FY13-23 Full Data'!$AL$3:$FA$3,'New Quarterly Report'!K$2) -> 620669.41 | ... AQ12: =SUMIFS('FY13-23 Full Data'!$AL9:$FA9,'FY13-23 Full Data'!$AL$2:$FA$2,'New Quarterly Report'!AQ$1,'FY13-23 Full Data'!$AL$3:$FA$3,'New Quarterly Report'!AQ$2) -> 441384
B13: CHECITRIC | C13: CITRIC ACID | D13: =SUMIFS('FY13-23 Full Data'!$AL10:$FA10,'FY13-23 Full Data'!$AL$2:$FA$2,'New Quarterly Report'!D$1,'FY13-23 Full Data'!$AL$3:$FA$3,'New Quarterly Report'!D$2) -> 29220 | E13: =SUMIFS('FY13-23 Full Data'!$AL10:$FA10,'FY13-23 Full Data'!$AL$2:$FA$2,'New Quarterly Report'!E$1,'FY13-23 Full Data'!$AL$3:$FA$3,'New Quarterly Report'!E$2) -> 38655.496 | F13: =SUMIFS('FY13-23 Full Data'!$AL10:$FA10,'FY13-23 Full Data'!$AL$2:$FA$2,'New Quarterly Report'!F$1,'FY13-23 Full Data'!$AL$3:$FA$3,'New Quarterly Report'!F$2) -> 38193.259 | G13: =SUMIFS('FY13-23 Full Data'!$AL10:$FA10,'FY13-23 Full Data'!$AL$2:$FA$2,'New Quarterly Report'!G$1,'FY13-23 Full Data'!$AL$3:$FA$3,'New Quarterly Report'!G$2) -> 38501.861 | H13: =SUMIFS('FY13-23 Full Data'!$AL10:$FA10,'FY13-23 Full Data'!$AL$2:$FA$2,'New Quarterly Report'!H$1,'FY13-23 Full Data'!$AL$3:$FA$3,'New Quarterly Report'!H$2) -> 18690.377 | I13: =SUMIFS('FY13-23 Full Data'!$AL10:$FA10,'FY13-23 Full Data'!$AL$2:$FA$2,'New Quarterly Report'!I$1,'FY13-23 Full Data'!$AL$3:$FA$3,'New Quarterly Report'!I$2) -> 16594.294 | J13: =SUMIFS('FY13-23 Full Data'!$AL10:$FA10,'FY13-23 Full Data'!$AL$2:$FA$2,'New Quarterly Report'!J$1,'FY13-23 Full Data'!$AL$3:$FA$3,'New Quarterly Report'!J$2) -> 35330.95 | K13: =SUMIFS('FY13-23 Full Data'!$AL10:$FA10,'FY13-23 Full Data'!$AL$2:$FA$2,'New Quarterly Report'!K$1,'FY13-23 Full Data'!$AL$3:$FA$3,'New Quarterly Report'!K$2) -> 21790.247 | ... AQ13: =SUMIFS('FY13-23 Full Data'!$AL10:$FA10,'FY13-23 Full Data'!$AL$2:$FA$2,'New Quarterly Report'!AQ$1,'FY13-23 Full Data'!$AL$3:$FA$3,'New Quarterly Report'!AQ$2) -> 7466
B14: CHEGLUCO | C14: GLUCOHEPTONATE | D14: =SUMIFS('FY13-23 Full Data'!$AL11:$FA11,'FY13-23 Full Data'!$AL$2:$FA$2,'New Quarterly Report'!D$1,'FY13-23 Full Data'!$AL$3:$FA$3,'New Quarterly Report'!D$2) -> 175738.6 | E14: =SUMIFS('FY13-23 Full Data'!$AL11:$FA11,'FY13-23 Full Data'!$AL$2:$FA$2,'New Quarterly Report'!E$1,'FY13-23 Full Data'!$AL$3:$FA$3,'New Quarterly Report'!E$2) -> 152254.76 | F14: =SUMIFS('FY13-23 Full Data'!$AL11:$FA11,'FY13-23 Full Data'!$AL$2:$FA$2,'New Quarterly Report'!F$1,'FY13-23 Full Data'!$AL$3:$FA$3,'New Quarterly Report'!F$2) -> 261810.15 | G14: =SUMIFS('FY13-23 Full Data'!$AL11:$FA11,'FY13-23 Full Data'!$AL$2:$FA$2,'New Quarterly Report'!G$1,'FY13-23 Full Data'!$AL$3:$FA$3,'New Quarterly Report'!G$2) -> 326221.92 | H14: =SUMIFS('FY13-23 Full Data'!$AL11:$FA11,'FY13-23 Full Data'!$AL$2:$FA$2,'New Quarterly Report'!H$1,'FY13-23 Full Data'!$AL$3:$FA$3,'New Quarterly Report'!H$2) -> 151125.31 | I14: =SUMIFS('FY13-23 Full Data'!$AL11:$FA11,'FY13-23 Full Data'!$AL$2:$FA$2,'New Quarterly Report'!I$1,'FY13-23 Full Data'!$AL$3:$FA$3,'New Quarterly Report'!I$2) -> 99428.8 | J14: =SUMIFS('FY13-23 Full Data'!$AL11:$FA11,'FY13-23 Full Data'!$AL$2:$FA$2,'New Quarterly Report'!J$1,'FY13-23 Full Data'!$AL$3:$FA$3,'New Quarterly Report'!J$2) -> 225710.98 | K14: =SUMIFS('FY13-23 Full Data'!$AL11:$FA11,'FY13-23 Full Data'!$AL$2:$FA$2,'New Quarterly Report'!K$1,'FY13-23 Full Data'!$AL$3:$FA$3,'New Quarterly Report'!K$2) -> 322443.86 | ... AQ14: =SUMIFS('FY13-23 Full Data'!$AL11:$FA11,'FY13-23 Full Data'!$AL$2:$FA$2,'New Quarterly Report'!AQ$1,'FY13-23 Full Data'!$AL$3:$FA$3,'New Quarterly Report'!AQ$2) -> 132566
B15: GRPHUMICLIQ | C15: HUMIC ACID LIQUID | D15: =SUMIFS('FY13-23 Full Data'!$AL12:$FA12,'FY13-23 Full Data'!$AL$2:$FA$2,'New Quarterly Report'!D$1,'FY13-23 Full Data'!$AL$3:$FA$3,'New Quarterly Report'!D$2) -> 16085.5 | E15: =SUMIFS('FY13-23 Full Data'!$AL12:$FA12,'FY13-23 Full Data'!$AL$2:$FA$2,'New Quarterly Report'!E$1,'FY13-23 Full Data'!$AL$3:$FA$3,'New Quarterly Report'!E$2) -> 16843.99 | F15: =SUMIFS('FY13-23 Full Data'!$AL12:$FA12,'FY13-23 Full Data'!$AL$2:$FA$2,'New Quarterly Report'!F$1,'FY13-23 Full Data'!$AL$3:$FA$3,'New Quarterly Report'!F$2) -> 27701.993 | G15: =SUMIFS('FY13-23 Full Data'!$AL12:$FA12,'FY13-23 Full Data'!$AL$2:$FA$2,'New Quarterly Report'!G$1,'FY13-23 Full Data'!$AL$3:$FA$3,'New Quarterly Report'!G$2) -> 18058.94 | H15: =SUMIFS('FY13-23 Full Data'!$AL12:$FA12,'FY13-23 Full Data'!$AL$2:$FA$2,'New Quarterly Report'!H$1,'FY13-23 Full Data'!$AL$3:$FA$3,'New Quarterly Report'!H$2) -> 23594.686 | I15: =SUMIFS('FY13-23 Full Data'!$AL12:$FA12,'FY13-23 Full Data'!$AL$2:$FA$2,'New Quarterly Report'!I$1,'FY13-23 Full Data'!$AL$3:$FA$3,'New Quarterly Report'!I$2) -> 9577.4143 | J15: =SUMIFS('FY13-23 Full Data'!$AL12:$FA12,'FY13-23 Full Data'!$AL$2:$FA$2,'New Quarterly Report'!J$1,'FY13-23 Full Data'!$AL$3:$FA$3,'New Quarterly Report'!J$2) -> 23745.087 | K15: =SUMIFS('FY13-23 Full Data'!$AL12:$FA12,'FY13-23 Full Data'!$AL$2:$FA$2,'New Quarterly Report'!K$1,'FY13-23 Full Data'!$AL$3:$FA$3,'New Quarterly Report'!K$2) -> 16135.881 | ... AQ15: =SUMIFS('FY13-23 Full Data'!$AL12:$FA12,'FY13-23 Full Data'!$AL$2:$FA$2,'New Quarterly Report'!AQ$1,'FY13-23 Full Data'!$AL$3:$FA$3,'New Quarterly Report'!AQ$2) -> 24621
B16: NO3FE | C16: IRON NITRATE 10% | D16: =SUMIFS('FY13-23 Full Data'!$AL13:$FA13,'FY13-23 Full Data'!$AL$2:$FA$2,'New Quarterly Report'!D$1,'FY13-23 Full Data'!$AL$3:$FA$3,'New Quarterly Report'!D$2) -> 22000 | E16: =SUMIFS('FY13-23 Full Data'!$AL13:$FA13,'FY13-23 Full Data'!$AL$2:$FA$2,'New Quarterly Report'!E$1,'FY13-23 Full Data'!$AL$3:$FA$3,'New Quarterly Report'!E$2) -> 17973.06 | F16: =SUMIFS('FY13-23 Full Data'!$AL13:$FA13,'FY13-23 Full Data'!$AL$2:$FA$2,'New Quarterly Report'!F$1,'FY13-23 Full Data'!$AL$3:$FA$3,'New Quarterly Report'!F$2) -> 42313.952 | G16: =SUMIFS('FY13-23 Full Data'!$AL13:$FA13,'FY13-23 Full Data'!$AL$2:$FA$2,'New Quarterly Report'!G$1,'FY13-23 Full Data'!$AL$3:$FA$3,'New Quarterly Report'!G$2) -> 58516.417 | H16: =SUMIFS('FY13-23 Full Data'!$AL13:$FA13,'FY13-23 Full Data'!$AL$2:$FA$2,'New Quarterly Report'!H$1,'FY13-23 Full Data'!$AL$3:$FA$3,'New Quarterly Report'!H$2) -> 32735.935 | I16: =SUMIFS('FY13-23 Full Data'!$AL13:$FA13,'FY13-23 Full Data'!$AL$2:$FA$2,'New Quarterly Report'!I$1,'FY13-23 Full Data'!$AL$3:$FA$3,'New Quarterly Report'!I$2) -> 18190.365 | J16: =SUMIFS('FY13-23 Full Data'!$AL13:$FA13,'FY13-23 Full Data'!$AL$2:$FA$2,'New Quarterly Report'!J$1,'FY13-23 Full Data'!$AL$3:$FA$3,'New Quarterly Report'!J$2) -> 54098.279 | K16: =SUMIFS('FY13-23 Full Data'!$AL13:$FA13,'FY13-23 Full Data'!$AL$2:$FA$2,'New Quarterly Report'!K$1,'FY13-23 Full Data'!$AL$3:$FA$3,'New Quarterly Report'!K$2) -> 47787.886 | ... AQ16: =SUMIFS('FY13-23 Full Data'!$AL13:$FA13,'FY13-23 Full Data'!$AL$2:$FA$2,'New Quarterly Report'!AQ$1,'FY13-23 Full Data'!$AL$3:$FA$3,'New Quarterly Report'!AQ$2) -> 84617
B17: SO4FEDRY19 | C17: IRON SULPHATE (Dry) | D17: =SUMIFS('FY13-23 Full Data'!$AL14:$FA14,'FY13-23 Full Data'!$AL$2:$FA$2,'New Quarterly Report'!D$1,'FY13-23 Full Data'!$AL$3:$FA$3,'New Quarterly Report'!D$2) -> 33087 | E17: =SUMIFS('FY13-23 Full Data'!$AL14:$FA14,'FY13-23 Full Data'!$AL$2:$FA$2,'New Quarterly Report'!E$1,'FY13-23 Full Data'!$AL$3:$FA$3,'New Quarterly Report'!E$2) -> 28551.785 | F17: =SUMIFS('FY13-23 Full Data'!$AL14:$FA14,'FY13-23 Full Data'!$AL$2:$FA$2,'New Quarterly Report'!F$1,'FY13-23 Full Data'!$AL$3:$FA$3,'New Quarterly Report'!F$2) -> 36562.595 | G17: =SUMIFS('FY13-23 Full Data'!$AL14:$FA14,'FY13-23 Full Data'!$AL$2:$FA$2,'New Quarterly Report'!G$1,'FY13-23 Full Data'!$AL$3:$FA$3,'New Quarterly Report'!G$2) -> 55794.184 | H17: =SUMIFS('FY13-23 Full Data'!$AL14:$FA14,'FY13-23 Full Data'!$AL$2:$FA$2,'New Quarterly Report'!H$1,'FY13-23 Full Data'!$AL$3:$FA$3,'New Quarterly Report'!H$2) -> 24368.114 | I17: =SUMIFS('FY13-23 Full Data'!$AL14:$FA14,'FY13-23 Full Data'!$AL$2:$FA$2,'New Quarterly Report'!I$1,'FY13-23 Full Data'!$AL$3:$FA$3,'New Quarterly Report'!I$2) -> 16904.176 | J17: =SUMIFS('FY13-23 Full Data'!$AL14:$FA14,'FY13-23 Full Data'!$AL$2:$FA$2,'New Quarterly Report'!J$1,'FY13-23 Full Data'!$AL$3:$FA$3,'New Quarterly Report'!J$2) -> 28719.766 | K17: =SUMIFS('FY13-23 Full Data'!$AL14:$FA14,'FY13-23 Full Data'!$AL$2:$FA$2,'New Quarterly Report'!K$1,'FY13-23 Full Data'!$AL$3:$FA$3,'New Quarterly Report'!K$2) -> 43249.146 | ... AQ17: =SUMIFS('FY13-23 Full Data'!$AL14:$FA14,'FY13-23 Full Data'!$AL$2:$FA$2,'New Quarterly Report'!AQ$1,'FY13-23 Full Data'!$AL$3:$FA$3,'New Quarterly Report'!AQ$2) -> 20819
B18: NPKKOHDRY | C18: KOH DRY | D18: =SUMIFS('FY13-23 Full Data'!$AL15:$FA15,'FY13-23 Full Data'!$AL$2:$FA$2,'New Quarterly Report'!D$1,'FY13-23 Full Data'!$AL$3:$FA$3,'New Quarterly Report'!D$2) -> 113829 | E18: =SUMIFS('FY13-23 Full Data'!$AL15:$FA15,'FY13-23 Full Data'!$AL$2:$FA$2,'New Quarterly Report'!E$1,'FY13-23 Full Data'!$AL$3:$FA$3,'New Quarterly Report'!E$2) -> 96129.34 | F18: =SUMIFS('FY13-23 Full Data'!$AL15:$FA15,'FY13-23 Full Data'!$AL$2:$FA$2,'New Quarterly Report'!F$1,'FY13-23 Full Data'!$AL$3:$FA$3,'New Quarterly Report'!F$2) -> 65995.226 | G18: =SUMIFS('FY13-23 Full Data'!$AL15:$FA15,'FY13-23 Full Data'!$AL$2:$FA$2,'New Quarterly Report'!G$1,'FY13-23 Full Data'!$AL$3:$FA$3,'New Quarterly Report'!G$2) -> 92154.106 | H18: =SUMIFS('FY13-23 Full Data'!$AL15:$FA15,'FY13-23 Full Data'!$AL$2:$FA$2,'New Quarterly Report'!H$1,'FY13-23 Full Data'!$AL$3:$FA$3,'New Quarterly Report'!H$2) -> 13341.183 | I18: =SUMIFS('FY13-23 Full Data'!$AL15:$FA15,'FY13-23 Full Data'!$AL$2:$FA$2,'New Quarterly Report'!I$1,'FY13-23 Full Data'!$AL$3:$FA$3,'New Quarterly Report'!I$2) -> 67804.859 | J18: =SUMIFS('FY13-23 Full Data'!$AL15:$FA15,'FY13-23 Full Data'!$AL$2:$FA$2,'New Quarterly Report'!J$1,'FY13-23 Full Data'!$AL$3:$FA$3,'New Quarterly Report'!J$2) -> 14083.999 | K18: =SUMIFS('FY13-23 Full Data'!$AL15:$FA15,'FY13-23 Full Data'!$AL$2:$FA$2,'New Quarterly Report'!K$1,'FY13-23 Full Data'!$AL$3:$FA$3,'New Quarterly Report'!K$2) -> 82451.821 | ... AQ18: =SUMIFS('FY13-23 Full Data'!$AL15:$FA15,'FY13-23 Full Data'!$AL$2:$FA$2,'New Quarterly Report'!AQ$1,'FY13-23 Full Data'!$AL$3:$FA$3,'New Quarterly Report'!AQ$2) -> 572
B19: NPKKOHLIQ | C19: KOH LIQUID 45% | D19: =SUMIFS('FY13-23 Full Data'!$AL16:$FA16,'FY13-23 Full Data'!$AL$2:$FA$2,'New Quarterly Report'!D$1,'FY13-23 Full Data'!$AL$3:$FA$3,'New Quarterly Report'!D$2) -> 244584 | E19: =SUMIFS('FY13-23 Full Data'!$AL16:$FA16,'FY13-23 Full Data'!$AL$2:$FA$2,'New Quarterly Report'!E$1,'FY13-23 Full Data'!$AL$3:$FA$3,'New Quarterly Report'!E$2) -> 238041.69 | F19: =SUMIFS('FY13-23 Full Data'!$AL16:$FA16,'FY13-23 Full Data'!$AL$2:$FA$2,'New Quarterly Report'!F$1,'FY13-23 Full Data'!$AL$3:$FA$3,'New Quarterly Report'!F$2) -> 142566.92 | G19: =SUMIFS('FY13-23 Full Data'!$AL16:$FA16,'FY13-23 Full Data'!$AL$2:$FA$2,'New Quarterly Report'!G$1,'FY13-23 Full Data'!$AL$3:$FA$3,'New Quarterly Report'!G$2) -> 139014.11 | H19: =SUMIFS('FY13-23 Full Data'!$AL16:$FA16,'FY13-23 Full Data'!$AL$2:$FA$2,'New Quarterly Report'!H$1,'FY13-23 Full Data'!$AL$3:$FA$3,'New Quarterly Report'!H$2) -> 5614.53 | I19: =SUMIFS('FY13-23 Full Data'!$AL16:$FA16,'FY13-23 Full Data'!$AL$2:$FA$2,'New Quarterly Report'!I$1,'FY13-23 Full Data'!$AL$3:$FA$3,'New Quarterly Report'!I$2) -> 12219.928 | J19: =SUMIFS('FY13-23 Full Data'!$AL16:$FA16,'FY13-23 Full Data'!$AL$2:$FA$2,'New Quarterly Report'!J$1,'FY13-23 Full Data'!$AL$3:$FA$3,'New Quarterly Report'!J$2) -> 1985.001 | K19: =SUMIFS('FY13-23 Full Data'!$AL16:$FA16,'FY13-23 Full Data'!$AL$2:$FA$2,'New Quarterly Report'!K$1,'FY13-23 Full Data'!$AL$3:$FA$3,'New Quarterly Report'!K$2) -> 6862.5724 | ... AQ19: =SUMIFS('FY13-23 Full Data'!$AL16:$FA16,'FY13-23 Full Data'!$AL$2:$FA$2,'New Quarterly Report'!AQ$1,'FY13-23 Full Data'!$AL$3:$FA$3,'New Quarterly Report'!AQ$2) -> 0
... B39: SO4CU | C39: COPPER SULPHATE 25.2% | D39: =SUMIFS('FY13-23 Full Data'!$AL36:$FA36,'FY13-23 Full Data'!$AL$2:$FA$2,'New Quarterly Report'!D$1,'FY13-23 Full Data'!$AL$3:$FA$3,'New Quarterly Report'!D$2) -> 0 | E39: =SUMIFS('FY13-23 Full Data'!$AL36:$FA36,'FY13-23 Full Data'!$AL$2:$FA$2,'New Quarterly Report'!E$1,'FY13-23 Full Data'!$AL$3:$FA$3,'New Quarterly Report'!E$2) -> 0 | F39: =SUMIFS('FY13-23 Full Data'!$AL36:$FA36,'FY13-23 Full Data'!$AL$2:$FA$2,'New Quarterly Report'!F$1,'FY13-23 Full Data'!$AL$3:$FA$3,'New Quarterly Report'!F$2) -> 0 | G39: =SUMIFS('FY13-23 Full Data'!$AL36:$FA36,'FY13-23 Full Data'!$AL$2:$FA$2,'New Quarterly Report'!G$1,'FY13-23 Full Data'!$AL$3:$FA$3,'New Quarterly Report'!G$2) -> 0 | H39: =SUMIFS('FY13-23 Full Data'!$AL36:$FA36,'FY13-23 Full Data'!$AL$2:$FA$2,'New Quarterly Report'!H$1,'FY13-23 Full Data'!$AL$3:$FA$3,'New Quarterly Report'!H$2) -> 0 | I39: =SUMIFS('FY13-23 Full Data'!$AL36:$FA36,'FY13-23 Full Data'!$AL$2:$FA$2,'New Quarterly Report'!I$1,'FY13-23 Full Data'!$AL$3:$FA$3,'New Quarterly Report'!I$2) -> 0 | J39: =SUMIFS('FY13-23 Full Data'!$AL36:$FA36,'FY13-23 Full Data'!$AL$2:$FA$2,'New Quarterly Report'!J$1,'FY13-23 Full Data'!$AL$3:$FA$3,'New Quarterly Report'!J$2) -> 0 | K39: =SUMIFS('FY13-23 Full Data'!$AL36:$FA36,'FY13-23 Full Data'!$AL$2:$FA$2,'New Quarterly Report'!K$1,'FY13-23 Full Data'!$AL$3:$FA$3,'New Quarterly Report'!K$2) -> 0 | ... AQ39: =SUMIFS('FY13-23 Full Data'!$AL36:$FA36,'FY13-23 Full Data'!$AL$2:$FA$2,'New Quarterly Report'!AQ$1,'FY13-23 Full Data'!$AL$3:$FA$3,'New Quarterly Report'!AQ$2) -> 5595

Sheet FY13-23 Full Data
AK2: Year | AL2: 14 | AM2: =AL2 -> 14 | AN2: =AM2 -> 14 | AO2: =AN2 -> 14 | AP2: =AO2 -> 14 | AQ2: =AP2 -> 14 | AR2: =AQ2 -> 14 | AS2: =AR2 -> 14 | AT2: =AS2 -> 14 | ... AW2: =AV2 -> 14 | AX2: =AL2+1 -> 15 | AY2: =AM2+1 -> 15 | AZ2: =AN2+1 -> 15 | BA2: =AO2+1 -> 15 | BB2: =AP2+1 -> 15 | BC2: =AQ2+1 -> 15 | BD2: =AR2+1 -> 15 | BE2: =AS2+1 -> 15 | ... FA2: =EO2+1 -> 23
AK3: Quarter | AL3: 1 | AM3: =AL3 -> 1 | AN3: =AM3 -> 1 | AO3: =AL3+1 -> 2 | AP3: =AM3+1 -> 2 | AQ3: =AN3+1 -> 2 | AR3: =AO3+1 -> 3 | AS3: =AP3+1 -> 3 | AT3: =AQ3+1 -> 3 | AU3: =AR3+1 -> 4 | AV3: =AS3+1 -> 4 | AW3: =AT3+1 -> 4 | AX3: =AL3 -> 1 | AY3: =AM3 -> 1 | AZ3: =AN3 -> 1 | BA3: =AO3 -> 2 | BB3: =AP3 -> 2 | BC3: =AQ3 -> 2 | BD3: =AR3 -> 3 | BE3: =AS3 -> 3 | ... FA3: =EO3 -> 4
B4: Month | C4: NPK11370 | D4: NPKAQUA | E4: SO4BORIC | F4: SO4BORON | G4: NO3CA | H4: CHECITRIC | I4: CHEGLUCO | J4: GRPHUMICLIQ | K4: NO3FE | L4: SO4FEDRY19 | M4: NPKKOHDRY | N4: NPKKOHLIQ | O4: NPKKTS | P4: CHELIGLIQ | Q4: CHELIGDRY | R4: SO4MG | S4: NO3MG60 | T4: NO3MG63 | U4: NO3MN | V4: SO4MN32 | W4: NPK2800 | X4: NPKNPHURCDI | Y4: NPKPHOS75 | Z4: NPKKCL62 | AA4: NPKKNO3 | AB4: NPKU32 | AC4: NPKUREA | AD4: NO3ZN | AE4: SO4ZNSTD | AF4: EDTAFEHE | AG4: EDTAACID | AH4: EDTAZN | AI4: SO4CU | AK4: {=TRANSPOSE(B4:AI124)} -> Month | AL4: 41456 | AM4: 41517 | AN4: 41547 | AO4: 41578 | AP4: 41608 | AQ4: 41639 | AR4: 41670 | AS4: 41698 | AT4: 41729 | AU4: 41759 | AV4: 41790 | AW4: 41820 | AX4: 41851 | AY4: 41882 | AZ4: 41912 | BA4: 41943 | BB4: 41973 | BC4: 42004 | BD4: 42035 | BE4: 42063 | BF4: 42094 | BG4: 42124 | BH4: 42155 | BI4: 42185 | BJ4: 42216 | BK4: 42247 | BL4: 42277 | BM4: 42308 | BN4: 42338 | BO4: 42369 | BP4: 42400 | BQ4: 42429 | BR4: 42460 | BS4: 42490 | BT4: 42521 | BU4: 42551 | BV4: 42582 | BW4: 42613 | BX4: 42643 | BY4: 42674 | BZ4: 42704 | CA4: 42735 | CB4: 42766 | CC4: 42794 | CD4: 42825 | CE4: 42855 | CF4: 42886 | CG4: 42916 | CH4: 42947 | CI4: 42978 | CJ4: 43008 | CK4: 43039 | CL4: 43069 | CM4: 43100 | CN4: 43131 | CO4: 43159 | CP4: 43190 | CQ4: 43220 | CR4: 43251 | CS4: 43281 | CT4: 43312 | CU4: 43343 | CV4: 43373 | CW4: 43404 | CX4: 43434 | CY4: 43465 | CZ4: 43496 | DA4: 43524 | DB4: 43555 | DC4: 43585 | DD4: 43616 | DE4: 43646 | DF4: 43677 | DG4: 43708 | DH4: 43738 | DI4: 43769 | DJ4: 43799 | DK4: 43830 | DL4: 43861 | DM4: 43890 | DN4: 43921 | DO4: 43951 | DP4: 43982 | DQ4: 44012 | DR4: 44043 | DS4: 44074 | DT4: 44104 | DU4: 44135 | DV4: 44165 | DW4: 44196 | DX4: 44227 | DY4: 44255 | DZ4: 44286 | EA4: 44316 | EB4: 44347 | EC4: 44377 | ED4: 44408 | EE4: 44439 | EF4: 44469 | EG4: 44500 | EH4: 44530 | EI4: 44561 | EJ4: 44592 | EK4: 44620 | EL4: 44651 | EM4: 44681 | EN4: 44712 | EO4: 44742 | EP4: 44773 | EQ4: 44804 | ER4: 44834 | ES4: 44865 | ET4: 44895 | EU4: 44926 | EV4: 44957 | EW4: 44985 | EX4: 45016 | EY4: 45046 | EZ4: 45077 | FA4: 45107
B5: 41456 | C5: 4104 | D5: 1741 | E5: -46106 | F5: 2846 | G5: 18527 | H5: 9693 | I5: 88526 | J5: 6805.1 | K5: 10208 | L5: 21153 | M5: 42186 | N5: 26828 | O5: 0 | P5: 775 | Q5: N/A | R5: 6481 | S5: 13224 | T5: 19366.1 | U5: 26788 | V5: 20020 | W5: 17314 | X5: 1549 | Y5: 53517.5 | Z5: 9950 | AA5: 157 | AB5: 37593 | AC5: 14146 | AD5: 43798 | AE5: 3386 | AF5: 547 | AG5: 0 | AK5: NPK11370 | AL5: 4104 | AM5: 8462 | AN5: 12324 | AO5: 4266.944 | AP5: 1645.2972 | AQ5: 7998.8588 | AR5: 11122.18 | AS5: 5730.8016 | AT5: 27551.422 | AU5: 6460.9149 | AV5: 1801.5661 | AW5: 1191.0849 | AX5: 359.046 | AY5: 4113.5851 | AZ5: 5038.8822 | BA5: 5846.6863 | BB5: 4225.3614 | BC5: 5968.1757 | BD5: 7114.4306 | BE5: 2009.5335 | BF5: 30915.26 | BG5: 8811.466 | BH5: 443.6364 | BI5: 2058.2469 | BJ5: 879.3361 | BK5: 4200.4375 | BL5: 6430.5979 | BM5: -3079.9092 | BN5: 516.8693 | BO5: 84308.678 | BP5: 232.4764 | BQ5: 2460.1393 | BR5: 1910.1506 | BS5: 6778.9494 | BT5: 40641.547 | BU5: 13048.696 | BV5: 8497.7192 | BW5: 2737.3336 | BX5: 1259.615 | BY5: 2476.8697 | BZ5: 121902.66 | CA5: 30265.598 | CB5: 34563.312 | CC5: 151.809 | CD5: 2647.5904 | CE5: 31000.041 | CF5: 84513.757 | CG5: 69003.374 | CH5: 39351.398 | CI5: 3298.618 | CJ5: 703.1115 | CK5: 205299.24 | CL5: 54.9616 | CM5: 1025.2542 | CN5: 4481.7387 | CO5: 59476.542 | CP5: 50579.286 | CQ5: 4993.6291 | CR5: 692.7191 | CS5: 31538.635 | CT5: 8736.5953 | CU5: 6563.2491 | CV5: 12050.906 | CW5: 482.446 | CX5: 0 | CY5: 155.0315 | CZ5: 677.449 | DA5: 3007.2725 | DB5: 7689.4693 | DC5: 31339.6 | DD5: 24559 | DE5: 9535.4692 | DF5: 5808.7559 | DG5: 631.5371 | DH5: 376.2955 | DI5: 925.6641 | DJ5: 59564.077 | DK5: 61746.543 | DL5: 1201.3031 | DM5: 63416.682 | DN5: 84349.21 | DO5: 0 | DP5: 5103.0418 | DQ5: 1253.3031 | DR5: 880.2311 | DS5: 31800.656 | DT5: 1287.2569 | DU5: 658.14195 | DV5: 1067.2328 | DW5: 93229.685 | DX5: 691.8111 | DY5: 163546.77 | DZ5: 238681.86 | EA5: 18739.526 | EB5: 50263.211 | EC5: 65364.658 | ED5: 78694.83 | EE5: 70312.48 | EF5: 760.54 | EG5: 70410.77 | EH5: 48489.884 | EI5: 21650.16 | EJ5: 89004.26 | EK5: 26821.91 | EL5: 151415.95 | EM5: 39765.61 | EN5: 3995.95 | EO5: 89833.47 | EP5: 743 | EQ5: 308 | ER5: 272 | ES5: 8588 | ET5: 81206 | EU5: 127561 | EV5: 71564 | EW5: 1160 | EX5: 64028 | EY5: 41914 | EZ5: 63318 | FA5: 1181
B6: =EOMONTH(B5,1) -> 41517 | C6: 8462 | D6: 1225 | E6: -7154 | F6: 1067 | G6: 54107 | H6: 9010 | I6: 52356 | J6: 6759.8 | K6: 2753 | L6: 5978 | M6: 48939 | N6: 173074 | O6: 6232.2 | P6: 511 | Q6: N/A | R6: 1767 | S6: 16840 | T6: 13108.7 | U6: 41745 | V6: 19573 | W6: 8019 | X6: 8820 | Y6: 163243.3 | Z6: 15558 | AA6: 35774 | AB6: 41107 | AC6: 5424 | AD6: 35629 | AE6: 3281 | AF6: 495 | AG6: 31 | AK6: NPKAQUA | AL6: 1741 | AM6: 1225 | AN6: 1058 | AO6: 414.628 | AP6: 249.775 | AQ6: 37.36 | AR6: 16730.427 | AS6: 24330.284 | AT6: 18221.654 | AU6: 3776.7683 | AV6: 3886.5319 | AW6: 905.4812 | AX6: 397.44485 | AY6: 190.6516 | AZ6: 145.78425 | BA6: 456.87593 | BB6: 69.1647 | BC6: 494.7794 | BD6: 105.6864 | BE6: 19078.295 | BF6: 31388.72 | BH6: 2797.6785 | BI6: 467.7227 | BJ6: 2395.2209 | BK6: 587.18518 | BL6: 2787.9255 | BM6: -1486.7393 | BN6: 254.1755 | BO6: 91.5357 | BP6: 788.38925 | BQ6: 26808.287 | BR6: 40093.429 | BS6: 15714.627 | BT6: 1755.0705 | BU6: 1284.9398 | BV6: 1148.4403 | BW6: 462.4871 | BX6: 709.068 | BY6: 313.89975 | BZ6: 111.99978 | CA6: 192.9132 | CB6: 1084.6793 | CC6: 28679.305 | CD6: 21163.167 | CE6: 10007.901 | CF6: 1661.588 | CG6: 2345.9561 | CH6: 919.34045 | CI6: 637.59858 | CJ6: 103.46275 | CK6: 353.2425 | CL6: 115.61275 | CM6: 22176.352 | CN6: 569.5759 | CO6: 17182.995 | CP6: 24310.732 | CQ6: 929.26145 | CR6: 7510.0019 | CS6: 803.27016 | CT6: 745.13858 | CU6: 245.85 | CV6: 186.5985 | CW6: 244.764 | CX6: 245.7796 | CY6: 87.9 | CZ6: 2562.9584 | DA6: 16620.627 | DB6: 9566.19 | DC6: 540.78157 | DD6: 3555.0916 | DE6: 1281.6257 | DF6: 477.93825 | DG6: 1215.5643 | DH6: 228.09006 | DI6: 839.81466 | DJ6: 15.92 | DK6: 234.8 | DL6: 3301.4189 | DM6: 34742.395 | DN6: 7225.7728 | DO6: 1348.5965 | DP6: 2353.6758 | DQ6: 1832.6133 | DR6: 2532.7597 | DS6: 1612.2305 | DT6: 2721.4486 | DU6: 2168.5922 | DV6: 2678.845 | DW6: 1737.0928 | DX6: 4528.6695 | DY6: 37039.242 | DZ6: 30189.002 | EA6: 4758.7762 | EB6: 4426.0489 | EC6: 2842.6635 | ED6: 1556.73 | EE6: 1478.1385 | EF6: 995.21 | EG6: 850.46 | EH6: 8346.19 | EI6: 834.28 | EJ6: 11369.08 | EK6: 25405.73 | EL6: 12224.39 | EM6: 2335.89 | EN6: 1907.53 | EO6: 1112.79 | EP6: 345 | EQ6: 77 | ER6: 142 | ES6: 1379 | ET6: 1679 | EU6: 2415 | EV6: 7301 | EW6: 21179 | EX6: 12709 | EY6: 515 | EZ6: 6224 | FA6: 241
B7: =EOMONTH(B6,1) -> 41547 | C7: 12324 | D7: 1058 | E7: -21 | F7: 1716 | G7: 76660 | H7: 10517 | I7: 34856.6 | J7: 2520.6 | K7: 9039 | L7: 5956 | M7: 22704 | N7: 44682 | O7: 5682.6 | P7: 359 | Q7: N/A | R7: 2894 | S7: 40108 | T7: 4722.4 | U7: 4011.4 | V7: 12131 | W7: 4611.2 | X7: 13749 | Y7: 79144 | Z7: 47207 | AA7: 50532 | AB7: 87444 | AC7: 666 | AD7: 4643 | AE7: 4488 | AF7: 1321.4 | AG7: 119 | AK7: SO4BORIC | AL7: -46106 | AM7: -7154 | AN7: -21 | AO7: -60 | AP7: -20 | AQ7: -3211.796 | AR7: 3.6844 | AS7: 1627.296 | AT7: 177 | AU7: 13703.218 | AV7: 27997.003 | AW7: 11228.465 | AX7: 68914.192 | AY7: 91.7044 | AZ7: 36 | BA7: 60 | BB7: 2 | BC7: 14.0064 | BD7: 17 | BE7: 1.41705 | BF7: 2552.4561 | BG7: 45489.819 | BH7: 115 | BI7: 54430.647 | BJ7: 48740.303 | BK7: 75 | BL7: 28.3824 | BM7: 61.7044 | BN7: 5 | BO7: 10 | BP7: 657.596 | BQ7: 281.2276 | BR7: 36495.108 | BS7: 85 | BT7: 25602.346 | BU7: 27549.01 | BV7: 71067.523 | BW7: 75 | BX7: 25 | BY7: 75 | BZ7: 1632.296 | CA7: 1636.49 | CB7: 1612.296 | CC7: 30 | CD7: 384.94 | CE7: 14113.465 | CF7: 53538.558 | CG7: 26568.289 | CH7: 79243.593 | CI7: 30538.441 | CJ7: 75 | CK7: 50 | CL7: 25 | CM7: 0 | CN7: 1612.296 | CO7: 1706.5 | CP7: 15011.54 | CQ7: 16733.966 | CR7: 34398.375 | CS7: 70828.963 | CT7: 110898.47 | CU7: 90 | CV7: 28 | CW7: 50 | CX7: 0 | CY7: 1612.296 | CZ7: 205 | DA7: 150 | DB7: 27990.76 | DC7: 45408.763 | DD7: 47840.142 | DE7: 97575.747 | DF7: 97575.747 | DG7: 9907.3366 | DH7: 0.2838 | DI7: 46 | DJ7: 16.398 | DK7: 0 | DL7: 68449.536 | DM7: 4914.092 | DN7: 32336.903 | DO7: 18650.17 | DP7: 54491.366 | DQ7: 74488.835 | DR7: 84909.831 | DS7: 10972.996 | DT7: 0 | DU7: 0.7095 | DV7: 0 | DW7: 0 | DX7: 0 | DY7: 170.17028 | DZ7: 35582.215 | EA7: 132842.6 | EB7: 91905.956 | EC7: 44856.91 | ED7: 59903.77 | EE7: 10334.77 | EF7: 0 | EG7: 0 | EH7: 0 | EI7: 3211.79 | EJ7: 21085.4 | EK7: 14107.6 | EL7: 115260.55 | EM7: 28549.38 | EN7: 25034.99 | EO7: 28118.42 | EP7: 19425 | EQ7: 13275 | ER7: 0 | ES7: 19495 | ET7: 9597 | EU7: 0 | EV7: 5976 | EW7: 14303 | EX7: 32002 | EY7: 28185 | EZ7: 87505 | FA7: 9597
B8: =EOMONTH(B7,1) -> 41578 | C8: 4266.944 | D8: 414.628 | E8: -60 | F8: 6867.1134 | G8: 564655.16 | H8: 15356.268 | I8: 70175.24 | J8: 4112.0495 | K8: 10720.586 | L8: 10746.101 | M8: 31243.343 | N8: 94386.027 | O8: 14436.866 | P8: 844.98 | Q8: N/A | R8: 5083.0624 | S8: 155559 | T8: 14023.18 | U8: 31475.722 | V8: 17838.136 | W8: 6919.0344 | X8: 90194.108 | Y8: 225649.47 | Z8: 199211 | AA8: 211755.86 | AB8: 392396.69 | AC8: 6466.8418 | AD8: 44911.92 | AE8: 4545.9084 | AF8: 550.9644 | AG8: 31 | AK8: SO4BORON | AL8: 2846 | AM8: 1067 | AN8: 1716 | AO8: 6867.1134 | AP8: 5187.9486 | AQ8: 4677.8315 | AR8: 8864.9189 | AS8: 15122.85 | AT8: 14807.843 | AU8: 10637.225 | AV8: 7189.9138 | AW8: 7057.7146 | AX8: 2148.8647 | AY8: 1690.1836 | AZ8: 1326.0288 | BA8: 4814.8627 | BB8: 2818.5473 | BC8: 3541.9788 | BD8: 6637.9951 | BE8: 11012.017 | BF8: 10487.734 | BG8: 10299.196 | BH8: 4569.6325 | BI8: 2640.788 | BJ8: 4600.0756 | BK8: 1083.107 | BL8: 2248.4662 | BM8: 3888.1289 | BN8: 3505.0152 | BO8: 4415.1206 | BP8: 6115.3106 | BQ8: 13002.216 | BR8: 15007.499 | BS8: 9075.6718 | BT8: 5172.3798 | BU8: 4071.5158 | BV8: 2462.1033 | BW8: 3586.0253 | BX8: 1452.0333 | BY8: 3592.566 | BZ8: 3869.1429 | CA8: 4564.0862 | CB8: 7361.1282 | CC8: 11960.71 | CD8: 8424.0295 | CE8: 6000.9547 | CF8: 7656.9315 | CG8: 6044.8925 | CH8: 4191.8755 | CI8: 159.51732 | CJ8: 842.02482 | CK8: 2913.0252 | CL8: 3118.9327 | CM8: 2502.7434 | CN8: 3371.9773 | CO8: 15489.121 | CP8: 4787.3248 | CQ8: 7169.9689 | CR8: 6158.0225 | CS8: 4991.8966 | CT8: 1500.443 | CU8: 636.37407 | CV8: 343.8676 | CW8: 3008.0087 | CX8: 1914.4435 | CY8: 2070.9831 | CZ8: 6997.9599 | DA8: 19864.941 | DB8: 7380.1794 | DC8: 6475.1044 | DD8: 5004.1301 | DE8: 3134.0723 | DF8: 1035.6074 | DG8: 185.56875 | DH8: 336.55378 | DI8: 3035.0983 | DJ8: 1589.5899 | DK8: 2472.9131 | DL8: 8725.0224 | DM8: 13746.388 | DN8: 8906.5989 | DO8: 4400.5804 | DP8: 2562.7935 | DQ8: 2121.2731 | DR8: 2087.3395 | DS8: 543.3748 | DT8: 305.59074 | DU8: 3488.913 | DV8: 2650.4495 | DW8: 3547.9208 | DX8: 4984.6961 | DY8: 12896.079 | DZ8: 8498.3143 | EA8: 6196.4935 | EB8: 2956.7158 | EC8: 5108.0396 | ED8: 579.25 | EE8: 176.42 | EF8: 1133.55 | EG8: 1672.55 | EH8: 2252.88 | EI8: 2353.8 | EJ8: 6127 | EK8: 9209.65 | EL8: 7984.14 | EM8: 6343.68 | EN8: 4041.27 | EO8: 2716.74 | EP8: 7 | EQ8: 516 | ER8: 600 | ES8: 1458 | ET8: 3224 | EU8: 3294 | EV8: 4157 | EW8: 8168 | EX8: 5984 | EY8: 5739 | EZ8: 5683 | FA8: 2646
B9: =EOMONTH(B8,1) -> 41608 | C9: 1645.2972 | D9: 249.775 | E9: -20 | F9: 5187.9486 | G9: 780940.33 | H9: 8867.706 | I9: 38209.317 | J9: 8621.4441 | K9: 1152.4742 | L9: 5379.2845 | M9: 12311.729 | N9: 37263.18 | O9: 13833.636 | P9: 739.35875 | Q9: N/A | R9: 2148.5151 | S9: 194801 | T9: 5567.7334 | U9: 16947.413 | V9: 4098.7576 | W9: 8268.3322 | X9: 90746.535 | Y9: 159391.36 | Z9: 244445.92 | AA9: 269839.69 | AB9: 393754 | AC9: 5446.9238 | AD9: 8292.4718 | AE9: 2139.2683 | AF9: 598.3177 | AG9: 109.18 | AK9: NO3CA | AL9: 18527 | AM9: 54107 | AN9: 76660 | AO9: 564655.16 | AP9: 780940.33 | AQ9: 851250.04 | AR9: 719713.34 | AS9: 736100.17 | AT9: 429159.59 | AU9: 403700.06 | AV9: 244918.38 | AW9: 40002.763 | AX9: 20090.551 | AY9: 46720.222 | AZ9: 114296.44 | BA9: 421414.03 | BB9: 529184.13 | BC9: 612165.38 | BD9: 445276.92 | BE9: 439520.5 | BF9: 364145.62 | BG9: 376340.38 | BH9: 189041 | BI9: 55288.029 | BJ9: 19165.729 | BK9: 21093.328 | BL9: 116469.21 | BM9: 485642.17 | BN9: 583082.94 | BO9: 563193.47 | BP9: 389748.43 | BQ9: 635320.24 | BR9: 426964.23 | BS9: 405210.86 | BT9: 303268.8 | BU9: 99162.109 | BV9: 113175.28 | BW9: 52782.053 | BX9: 147012.9 | BY9: 610473.9 | BZ9: 495397.24 | CA9: 381707.27 | CB9: 418635.94 | CC9: 390019.41 | CD9: 275180.83 | CE9: 237345.89 | CF9: 211540.39 | CG9: 56695.774 | CH9: 30453.853 | CI9: 27108.573 | CJ9: 41373.334 | CK9: 449744.87 | CL9: 541083.85 | CM9: 472773.99 | CN9: 438040.68 | CO9: 454189.6 | CP9: 287066.51 | CQ9: 349139.53 | CR9: 212200.3 | CS9: 31883.481 | CT9: 15230.048 | CU9: 4758 | CV9: 85676.59 | CW9: 485105.24 | CX9: 538928.59 | CY9: 446121.89 | CZ9: 496243.4 | DA9: 479826.85 | DB9: 281586.77 | DC9: 330245.67 | DD9: 153354.45 | DE9: 52667.628 | DF9: 19855.62 | DG9: 26612.555 | DH9: 92294.97 | DI9: 455093.32 | DJ9: 553041.9 | DK9: 425503.75 | DL9: 557460.12 | DM9: 463740.54 | DN9: 407093.62 | DO9: 391234.28 | DP9: 240174.97 | DQ9: 24610.977 | DR9: 65942.406 | DS9: 13548.654 | DT9: 91329.132 | DU9: 392934.94 | DV9: 529469.74 | DW9: 501040.84 | DX9: 498501.28 | DY9: 512257.18 | DZ9: 351899.15 | EA9: 389110.24 | EB9: 200399.8 | EC9: 77163.493 | ED9: 28478.64 | EE9: 23329.27 | EF9: 102174.34 | EG9: 272399.57 | EH9: 468267.69 | EI9: 470441.2 | EJ9: 452766.92 | EK9: 454712.91 | EL9: 379058.19 | EM9: 341096.98 | EN9: 197837.55 | EO9: 27722.32 | EP9: 14060 | EQ9: 22208 | ER9: 70388 | ES9: 234857 | ET9: 471679 | EU9: 430067 | EV9: 397825 | EW9: 398147 | EX9: 286313 | EY9: 227375 | EZ9: 182145 | FA9: 31864
B10: =EOMONTH(B9,1) -> 41639 | C10: 7998.8588 | D10: 37.36 | E10: -3211.796 | F10: 4677.8315 | G10: 851250.04 | H10: 14431.522 | I10: 43870.201 | J10: 4110.496 | K10: 6100 | L10: 12426.4 | M10: 52574.268 | N10: 106392.48 | O10: 14713.596 | P10: 2957.355 | Q10: N/A | R10: 6727.4052 | S10: 200674.63 | T10: 11547.69 | U10: 17397 | V10: 5569.5831 | W10: 6975.8342 | X10: 85441.767 | Y10: 170246.44 | Z10: 213673.07 | AA10: 215438.87 | AB10: 294890.3 | AC10: 3152.7747 | AD10: 3800 | AE10: 4053.8232 | AF10: 436.70715 | AG10: 50.65 | AK10: CHECITRIC | AL10: 9693 | AM10: 9010 | AN10: 10517 | AO10: 15356.268 | AP10: 8867.706 | AQ10: 14431.522 | AR10: 7990.495 | AS10: 20080.601 | AT10: 10122.163 | AU10: 20687.637 | AV10: 11942.559 | AW10: 5871.6646 | AX10: 12584.784 | AY10: 1589.0164 | AZ10: 4516.577 | BA10: 5731.8933 | BB10: 3089.2187 | BC10: 7773.1816 | BD10: 13283.767 | BE10: 11129.164 | BF10: 10918.019 | BG10: 10221.484 | BH10: 4945.5351 | BI10: 6623.2278 | BJ10: 6730.6342 | BK10: 7124.7808 | BL10: 10016.242 | BM10: 3812.8856 | BN10: 8457.9822 | BO10: 7928.1654 | BP10: 3358.8182 | BQ10: 14785.384 | BR10: 16365.508 | BS10: 11332.528 | BT10: 4310 | BU10: 3176.986 | BV10: 2623.3118 | BW10: 4196.7423 | BX10: 3389.6932 | BY10: 10442.521 | BZ10: 4228.4624 | CA10: 8980.8931 | CB10: 2261.9622 | CC10: 11234.501 | CD10: 7843.1705 | CE10: 7192.2697 | CF10: 4238.1542 | CG10: 4636.7918 | CH10: 7414.9646 | CI10: 2496.7219 | CJ10: 3368.163 | CK10: 2229.8875 | CL10: 4738.7876 | CM10: 10661.858 | CN10: 5986.7634 | CO10: 7376.0789 | CP10: 8946.1154 | CQ10: 7053.1778 | CR10: 10452.402 | CS10: 2510.2282 | CT10: 2791.5538 | CU10: 383.43 | CV10: 332 | CW10: 5948.24 | CX10: 4322.55 | CY10: 3208.3201 | CZ10: 7148.4225 | DA10: 9538.7642 | DB10: 8791.365 | DC10: 8963.9045 | DD10: 3186.3788 | DE10: 2080.84 | DF10: 2497.8975 | DG10: 3696.1641 | DH10: 2669.0456 | DI10: 3693.0271 | DJ10: 3040.8138 | DK10: 907.5312 | DL10: 6546.913 | DM10: 16196.924 | DN10: 7573.1125 | DO10: 5320.0535 | DP10: 2328.8173 | DQ10: 7444.3653 | DR10: 2428.3952 | DS10: 1259.5119 | DT10: 5644.3061 | DU10: 4618.8696 | DV10: 3690.4746 | DW10: 1895.4638 | DX10: 5427.9764 | DY10: 18861.148 | DZ10: 11778.716 | EA10: 3765.2505 | EB10: 5834 | EC10: 2093 | ED10: 2612.17 | EE10: 4140.36 | EF10: 1054.79 | EG10: 2735.83 | EH10: 5730.52 | EI10: 3876.66 | EJ10: 7320.86 | EK10: 21353.54 | EL10: 8784 | EM10: 4967.52 | EN10: 4801.78 | EO10: 25468.14 | EP10: 4393 | EQ10: 1084 | ER10: 19221 | ES10: 784 | ET10: 3765 | EU10: 6946 | EV10: 8865 | EW10: 18349 | EX10: 4990 | EY10: 2892 | EZ10: 4259 | FA10: 315
B11: =EOMONTH(B10,1) -> 41670 | C11: 11122.18 | D11: 16730.427 | E11: 3.6844 | F11: 8864.9189 | G11: 719713.34 | H11: 7990.495 | I11: 68949.431 | J11: 7597.7216 | K11: 14685.025 | L11: 10311.278 | M11: 46864.561 | N11: 81441.629 | O11: 4956.2964 | P11: 3934.313 | Q11: N/A | R11: 9764.7391 | S11: 158161 | T11: 19584.151 | U11: 24871.952 | V11: 19339.223 | W11: 11324.35 | X11: 153130.92 | Y11: 238923.7 | Z11: 189651.99 | AA11: 260118.32 | AB11: 219008.3 | AC11: 11414.671 | AD11: 8996.6255 | AE11: 8488.0069 | AF11: 1423.3698 | AG11: 375.87 | AK11: CHEGLUCO | AL11: 88526 | AM11: 52356 | AN11: 34856.6 | AO11: 70175.24 | AP11: 38209.317 | AQ11: 43870.201 | AR11: 68949.431 | AS11: 97122.573 | AT11: 95738.141 | AU11: 150580.22 | AV11: 55797.157 | AW11: 119844.54 | AX11: 84416.623 | AY11: 76834.471 | AZ11: -10125.788 | BA11: 50315.293 | BB11: 20538.982 | BC11: 28574.525 | BD11: 60946.992 | BE11: 71036.97 | BF11: 93727.02 | BG11: 157295.12 | BH11: 96082.073 | BI11: 69066.66 | BJ11: 87446.863 | BK11: 47509.562 | BL11: 80389.884 | BM11: 35481.96 | BN11: 40022.562 | BO11: 36275.739 | BP11: 46831.67 | BQ11: 77502.322 | BR11: 88694.426 | BS11: 162499.46 | BT11: 88167.161 | BU11: 131863.13 | BV11: 55435.368 | BW11: 68187.354 | BX11: 49868.662 | BY11: 27883.87 | BZ11: 27157.039 | CA11: 25642.008 | CB11: 60858.83 | CC11: 87400.09 | CD11: 56674.661 | CE11: 79692.389 | CF11: 81249.655 | CG11: 75411.016 | CH11: 71955.591 | CI11: 25893.263 | CJ11: 11167.892 | CK11: 32663.982 | CL11: 30456.46 | CM11: 10689.378 | CN11: 43955.296 | CO11: 75088.024 | CP11: 96401.69 | CQ11: 68719.636 | CR11: 86488.463 | CS11: 58026.807 | CT11: 52585.131 | CU11: 23882.944 | CV11: 31813.268 | CW11: 26366.281 | CX11: 20841.926 | CY11: 22688.82 | CZ11: 46921.452 | DA11: 97343.052 | DB11: 68416.039 | DC11: 97038.442 | DD11: 67670.78 | DE11: 58156.339 | DF11: 60867.503 | DG11: 27283.697 | DH11: 22079.534 | DI11: 20304.283 | DJ11: 13203.185 | DK11: 39352.511 | DL11: 73756.143 | DM11: 87434.748 | DN11: 116187.39 | DO11: 61998.556 | DP11: 28227.906 | DQ11: 72056.498 | DR11: 34848.238 | DS11: 49457.688 | DT11: 23935.486 | DU11: 42942.365 | DV11: 21154.819 | DW11: 50102.763 | DX11: 36907.286 | DY11: 85478.481 | DZ11: 83365.814 | EA11: 78113.904 | EB11: 64721.725 | EC11: 36610.232 | ED11: 45990.85 | EE11: 5061.41 | EF11: 38321.62 | EG11: 13610.98 | EH11: 18625.74 | EI11: 50029.27 | EJ11: 79249.06 | EK11: 72535.53 | EL11: 62116 | EM11: 62735.7 | EN11: 43932.62 | EO11: 31128.4 | EP11: 28295 | EQ11: 20279 | ER11: 11225 | ES11: 13771 | ET11: 21191 | EU11: 27936 | EV11: 25614 | EW11: 60362 | EX11: 33342 | EY11: 52057 | EZ11: 54671 | FA11: 25838
B12: =EOMONTH(B11,1) -> 41698 | C12: 5730.8016 | D12: 24330.284 | E12: 1627.296 | F12: 15122.85 | G12: 736100.17 | H12: 20080.601 | I12: 97122.573 | J12: 8401.0323 | K12: 7397.4956 | L12: 13285.398 | M12: 8256.7885 | N12: 34316.494 | O12: 5051.5515 | P12: 3241.71 | Q12: N/A | R12: 2977.0084 | S12: 151435 | T12: 41658.177 | U12: 13154.546 | V12: 17035.224 | W12: 6772.0315 | X12: 96290.16 | Y12: 146164.72 | Z12: 169524.8 | AA12: 182641.56 | AB12: 226647 | AC12: 11850.042 | AD12: 9804.1362 | AE12: 15137.246 | AF12: 1492.7883 | AG12: 0 | AK12: GRPHUMICLIQ | AL12: 6805.1 | AM12: 6759.8 | AN12: 2520.6 | AO12: 4112.0495 | AP12: 8621.4441 | AQ12: 4110.496 | AR12: 7597.7216 | AS12: 8401.0323 | AT12: 11703.239 | AU12: 6870.7954 | AV12: 5741.983 | AW12: 5446.1614 | AX12: 12986.909 | AY12: 8046.8694 | AZ12: 2560.9074 | BA12: 3606.1658 | BB12: 1954.0536 | BC12: 4017.1949 | BD12: 4048.9937 | BE12: 6645.2085 | BF12: 13050.885 | BG12: 9016.2242 | BH12: 2814.6059 | BI12: 4305.051 | BJ12: 2255.6361 | BK12: 1597.7964 | BL12: 2930.4992 | BM12: 3785.8808 | BN12: 203.63265 | BO12: 2738.5464 | BP12: 2491.2 | BQ12: 10284.801 | BR12: 9407.7864 | BS12: 6808.5284 | BT12: 7603.8871 | BU12: 13129.944 | BV12: 4994.3539 | BW12: 2674.2319 | BX12: 4616.3566 | BY12: 4450.72 | BZ12: 1862.6521 | CA12: 2494.6753 | CB12: 4733.4612 | CC12: 6289.3673 | CD12: 6721.4284 | CE12: 6966.6566 | CF12: 10093.377 | CG12: 10093.678 | CH12: 6771.893 | CI12: 1830.697 | CJ12: 1901.3123 | CK12: 4801.1736 | CL12: 1174.9598 | CM12: 3076.8867 | CN12: 5233.893 | CO12: 12662.6 | CP12: 10478.526 | CQ12: 6611.1977 | CR12: 12608.294 | CS12: 6497.3402 | CT12: 3044.6793 | CU12: 2260.702 | CV12: 3254.16 | CW12: 11922.386 | CX12: 1518.4126 | CY12: 1696.525 | CZ12: 5543.4952 | DA12: 14672.652 | DB12: 4984.6022 | DC12: 5403.2865 | DD12: 3052.1196 | DE12: 6911.6467 | DF12: 3220.1041 | DG12: 2647.7567 | DH12: 2130.2613 | DI12: 3871.9372 | DJ12: 1963.7497 | DK12: 2911.001 | DL12: 5764.4082 | DM12: 8072.8755 | DN12: 16775.739 | DO12: 46530.477 | DP12: 7065.8073 | DQ12: 6152.2873 | DR12: 3727.9338 | DS12: 5080.3428 | DT12: 2486.2382 | DU12: 1505.4456 | DV12: 1703.708 | DW12: 3144.1634 | DX12: 5008.4482 | DY12: 16661.617 | DZ12: 33915.406 | EA12: 10880.803 | EB12: 7444.6753 | EC12: 8453.3545 | ED12: 12727.96 | EE12: 1571.42 | EF12: 2781.48 | EG12: 4235.81 | EH12: 45952.96 | EI12: 3845.96 | EJ12: 14270.72 | EK12: 6461.51 | EL12: 7893.2 | EM12: 9928.44 | EN12: 5986.19 | EO12: 9243.51 | EP12: 2133 | EQ12: 1285 | ER12: 695 | ES12: 4539 | ET12: 5614 | EU12: 7818 | EV12: 4692 | EW12: 4895 | EX12: 6906 | EY12: 11291 | EZ12: 7838 | FA12: 5492
